Workbook

Sheet PORTADA_VISTOSA
A1: REGISTRODOC MULTIGRADO
A2: PORTADA ACADEMICA
A3: Control de notas y asistencia
B7: INFORMACION INSTITUCIONAL
B9: Escuela | C9: Escuela Cerro Cacicon
B10: Docente | C10: Elmer Tugri
B11: Ano lectivo | C11: 2026
B12: Grados | C12: 7°, 8° y 9°
B13: Materias | C13: Ingles, Agropecuaria, Comercio, Hogar y Desarrollo, Artistica
B18: HOJAS CLAVE DEL LIBRO
B20: MAESTRO | C20: Lista base de estudiantes por grado
B21: DASHBOARD | C21: Resumen visual con graficas
B22: Asistencia 7/8/9 | C22: Registro directo por hoja de grado
B23: PROM y PLANILLAS | C23: Calificaciones por materia y grado

Sheet Caratula
A15: Registro de Asistencia
A16: y Evaluación
A17: para Docentes de Centros
A18: Educativos Oficiales
Q23: Prof. Elmer Tugri
Q24: Insturctor Vocacional Pre-Media
Q25: Grupo:

Sheet Portada
A4: REGISTRO DE ASISTENCIA Y EVALUACIÓN
A5: PARA PROFESORES DE LOS CENTROS
A6: EDUCATIVOS OFICIALES
A8: Año lectivo: | P8: 2026
A10: Grado:
A12: Área Curricular: | O12: PREMEDIA MULTIGRADO
A14: Nombre del Docente: | P14: Elmer Tugri
A16: N° de Cédula: | H16: 4-785-823 | V16: N° S. S. | AI16: N° de Pos.:
A18: Condición de Nombramiento: | U18: Instructor Vocacional
A20: Jornada: | H20: Matutina | X20: Asignatura: | AD20: Tecnología - Expresiones Artísticas - Ingles
A22: Nombre del Director(ar): | S22: Mardel Camarena
A24: Nombre del Subdirector(ar): | T24: Jairo Marciaga
A26: Nombre del Coordinador:
A28: Centro Educativo: | Q28: Escuela Cerro Cacicon
A30: Teléfono: | F30: 64185780 | U30: Correo Electrónico: | AF30: elmer.tugri7@meduca.edu.pa
A32: Regional: | M32: Comarca Ngabe Bugle
A34: Distrito de: | L34: MÜNA
A36: Corregimiento de: | Q36: MARACA
A38: Zona Escolar: | O38: 31

Sheet Horarios
I2: Profesor: | O2: Elmer Tugri
C4: Jornada: | H4: MATUTINA
C6: Asignatura: | I6: Tecnología (7° a 9°) - Expresiones Artísticas (9°) - Ingles (7° a 9°)
C8: Grados:
D10: PERIODO | J10: HORAS | O10: LUNES | P10: MARTES | Q10: MIERCOLES | R10: JUEVES | S10: VIERNES
D11: I | J11: 8:00 -8:35 | O11: ACTO CIVO | P11: TECNOLOGIA 9° | Q11: TECNOLOGIA 9°
D12: II | J12: 8:35 - 9:10 | O12: TECNOLOGIA 7° | P12: INGLES 9° | Q12: INGLES 8°
D13: III | J13: 9:10 - 9:45 | R13: INGLES 7°
D14: IV | J14: 9:45 - 10:20 | O14: TECNOLOGIA 8° | Q14: INGLES 7° | S14: Artística 9°
D15: RECESO ACADÉMICO
D16: V | J16: 10:40 - 11:15 | O16: TECNOLOGIA 8° | Q16: INGLES 7° | R16: Artística 9° | S16: Artística 9°
D17: VI | J17: 11:15 - 11:50 | O17: INGLES 8° | Q17: TECNOLOGIA 8° | S17: TECNOLOGIA 9°
D18: VII | J18: 11:50 - 12:25 | P18: TECNOLOGIA 7° | R18: INGLES 9° | S18: PROYECTOS
D19: VIII | J19: 12:25 - 1:00 | Q19: TECNOLOGIA 9°

Sheet Guía del Registro
A1: GUÍA PARA EL CORRECTO MANEJO DEL REGISTRO ESCOLAR | C1: . Debe anotarse toda la información relacionada con el nombre y apellido.
C2: . En caso de retiros, no se debe tachar el nombre, sino hacer la correspondiente anotación en el espacio previsto para ello al final de cada grupo.
A3: La libreta de Registro Escolar es propiedad del Estado. Sin embargo, la docente y el docente la utilizan durante el periodo lectivo para llevar un control de las actividades que realiza con sus estudiantes. Este documento recoge toda la información sobre la asistencia, rendimiento académico, comportamiento, etc., de los estudiantes.
C5: . En la sección para observaciones, debe aparecer el nombre de la profesora o del profesor consejero así como el grupo de consejería a que pertenece la estudiante o el estudiante.
C7: SIMBOLOGÍA RECOMENDADA
C9: El registro o control de la asistencia tiene una trascendental importancia con los diferentes aspectos que debe manejar el docente para dar respuesta a las solicitudes que se formulen en torno a sus estudiantes. El profesor y la profesora deberán:
A10: Para asegurar el correcto reistro, tanto de la asistencia como las calificaciones, el docente debe guiarse por el nombre del estudiante como por el número de casilla que le corresponde.
A15: Al finalizar el año lectivo, todos los docentes deben devolver el Registro Escolar a la Dirección del Plantel. | C15: 1. Registrar la asistencia diariamente, anotando la fecha correspondiente (día: número arábigo; mes: número arabigo). Utilizar la siguiente simbología:
A18: Esperamos que los señalamientos aquí presentados sean considerados por los docentes quienes oportunamente deberán presentar opiniones o nuevas ideas relacionadas con el manejo del Registro Escolar. | C18: a. Asistencia: un punto (.)
C19: b. Ausencia: una raya horizontal (-)
C20: c. Ausencia justificada (excusa): la letra mayúscula €
C21: d. Tardanza: La letra mayúscula (T)
C22: e. Fuga: la letra (F)
A23: PRESENTACIÓN | C23: f. Sin nota: las letras (S/N)
C24: g. Sin profesor: las letras (S/P)
A25: El Registro Escolar refleja la personalidad de la docente o del docente, por lo tanto, se debe tener especial cuidado con su aspecto físico. | C25: h. Alumno retirado: La letra (R) mayúscula.
C27: CONSIDERACIONES FINALES
A29: En cuanto a su presentación se tendrá en cuenta lo siguiente:
C30: El registro de notas o calificaciones es importante por su trascendencia en la determinación cuantitativa y cualitativa del aprovechamiento escolar. Por eso debemos:
A32: 1. Debe estar forrado con sobriedad; si es posible, encuadernado o empastado.
A34: 2. La información se anotará con tinta sin exagerar el uso de los colores.
C35: . Utilizar la escala numérica de 1 a 5 (incluye decimales con números arábigos).
A36: 3. Al escribir en él puede usar la letra de imprenta o cursiva legible.
C37: . Recordar que el cero (0) no existe dentro de esta escala.
A38: 4. Debe conservarse en forma nítida, sin manchas, sin borrones y sin tachaduras.
C39: . No utilizar ganchos, equis ni otros símbolos.
A40: 5. La libreta no debe contener información ajena a sus propósitos. | C40: . Registrar las notas con tinta, sin borrones ni tachaduras. Evitar escribir un número sobre otro.
C42: . Se debe registrar según la carga horaria, un mínimo de pruebas y actividades.
A43: CONFECCIÓN DEL LISTADO DE LAS ESTUDIANTES Y LOS ESTUDIANTES.
C44: . Debemos recordar que el trabajo en la libreta debe ser exacto, completo, claro y legible.
A46: . El listado debe hacerse por apellidos, en orden alfabético, sin distinción de género.
A47: Según el Resuelto No.1840 de 1 de noviembre de 2000.

Sheet Observaciones
A4: OBSERVACIONES

Sheet MAESTRO
A1: HOJA MAESTRO — ESCUELA CERRO CACICÓN · AÑO LECTIVO 2026
A2: Ingresa aquí los nombres de cada grado. Se copiarán automáticamente a TODAS las hojas.
A3: 7° GRADO | C3: 8° GRADO | E3: 9° GRADO
A4: No. | B4: APELLIDO, NOMBRE | C4: No. | D4: APELLIDO, NOMBRE | E4: No. | F4: APELLIDO, NOMBRE
A5: 1 | B5: Abrigo Yuleika | C5: 1 | D5: Bejerano Yeika | E5: 1 | F5: Abrego Yosselih
A6: 2 | B6: Bejerano Yohana | C6: 2 | D6: Camarena Khathia | E6: 2 | F6: Abrigo Sheldry
A7: 3 | B7: Cedeño Carol | C7: 3 | D7: Case Yarixell | E7: 3 | F7: Caballero Edimael
A8: 4 | B8: Gallardo Ivan | C8: 4 | D8: Gallardo Alvaro | E8: 4 | F8: Carrera Meliza
A9: 5 | B9: Gallardo Maritzenia | C9: 5 | D9: Gallardo Cornelio | E9: 5 | F9: Case Noriel
A10: 6 | B10: Guerra Maria | C10: 6 | D10: Gallardo Doritza | E10: 6 | F10: Cire Marina
A11: 7 | B11: Guerra Yanelis | C11: 7 | D11: Gallardo Henry | E11: 7 | F11: Cire Saul
A12: 8 | B12: Javilla Manuel | C12: 8 | D12: Gallardo Yaquelin | E12: 8 | F12: Fuentes Isabela
A13: 9 | B13: Jiménez Hernan | C13: 9 | D13: Jimenez Abner | E13: 9 | F13: Garcia Kimberly
A14: 10 | B14: Montero Rebeca | C14: 10 | D14: Jimenez Jancarlo | E14: 10 | F14: Guerra Yeni
A15: 11 | B15: Pinto Arasely | C15: 11 | D15: Mariano Herenia | E15: 11 | F15: Jimenez Orlando
A16: 12 | B16: Pinto Elodia | C16: 12 | D16: Montezuma Edison | E16: 12 | F16: Jimenez YanCarlos
... A29: 25 | B29: Zurdo Luz Dairis | C29: 25 | D29: Santo Roxana | E29: 25 | F29: Santo Yuliana
A30: 26 | C30: 26 | D30: Santo Yuliana | E30: 26 | F30: Santos Camila
A31: 27 | C31: 27 | D31: Santo Zaira | E31: 27 | F31: Santos Daylin
A32: 28 | C32: 28 | D32: Santos Dalila | E32: 28 | F32: Santos Diomedes
A33: 29 | C33: 29 | D33: Santos Ermenegildo | E33: 29 | F33: Santos Elvin
A34: 30 | C34: 30 | D34: Santos Kerlyn | E34: 30 | F34: Santos Evelyn
A35: 31 | C35: 31 | D35: Santos Yosenith | E35: 31 | F35: Santos Fidel
A36: 32 | C36: 32 | E36: 32 | F36: Santos Henry
A37: 33 | C37: 33 | E37: 33 | F37: Santos Metdy
A38: 34 | C38: 34 | E38: 34 | F38: Santos Mitzila
A39: 35 | C39: 35 | E39: 35 | F39: Santos Omar
A40: 36 | C40: 36 | E40: 36 | F40: Watson Edgar
A41: 37 | C41: 37 | E41: 37
A42: 38 | C42: 38 | E42: 38
A43: 39 | C43: 39 | E43: 39
A44: 40 | C44: 40 | E44: 40
A46: ⚠ IMPORTANTE: Solo edita esta hoja para nombres. Todas las demás hojas se actualizan automáticamente.

Sheet DASHBOARD
A1: DASHBOARD ACADEMICO
A5: Indicador | B5: Valor | D5: Grado | E5: Riesgo Academico | G5: Grado | H5: Riesgo Inasistencia
A6: Total estudiantes 7° | B6: =IFERROR(COUNTA(MAESTRO!B5:B44),0) | D6: 7° | E6: =IFERROR(MAX(COUNTIF('PROM (Ingles 7°)'!AE5:AE44,"<3"),COUNTIF('PROM (Agropecuaria 7°)'!AE5:AE44,"<3"),COUNTIF('PROM (Hogar y Desarrollo 7°)'!AE5:AE44,"<3")),"") | G6: 7° | H6: =IFERROR(SUMPRODUCT(('Asistencia (7°)'!C3:BH42="-")*1)+SUMPRODUCT(('Asistencia (7°)'!C46:BH85="-")*1)+SUMPRODUCT(('Asistencia (7°)'!C89:BH128="-")*1),"")
A7: Total estudiantes 8° | B7: =IFERROR(COUNTA(MAESTRO!D5:D44),0) | D7: 8° | E7: =IFERROR(MAX(COUNTIF('PROM (Ingles 8°)'!AE5:AE44,"<3"),COUNTIF('PROM (Agropecuaria 8°)'!AF5:AF44,"<3"),COUNTIF('PROM (Comercio 8°)'!AE5:AE44,"<3")),"") | G7: 8° | H7: =IFERROR(SUMPRODUCT(('Asistencia (8°)'!C3:BH42="-")*1)+SUMPRODUCT(('Asistencia (8°)'!C46:BH85="-")*1)+SUMPRODUCT(('Asistencia (8°)'!C89:BH128="-")*1),"")
A8: Total estudiantes 9° | B8: =IFERROR(COUNTA(MAESTRO!F5:F44),0) | D8: 9° | E8: =IFERROR(MAX(COUNTIF('PROM (Ingles 9°)'!AE5:AE44,"<3"),COUNTIF('PROM (Agropecuaria 9°)'!AE5:AE44,"<3"),COUNTIF('PROM (Comercio 9°)'!AE5:AE44,"<3"),COUNTIF('PROM (Artistica 9°)'!AE5:AE44,"<3")),"") | G8: 9° | H8: =IFERROR(SUMPRODUCT(('Asistencia (9°)'!C3:BH42="-")*1)+SUMPRODUCT(('Asistencia (9°)'!C46:BH85="-")*1)+SUMPRODUCT(('Asistencia (9°)'!C89:BH128="-")*1),"")
A9: Total general | B9: =SUM(B6:B8)
A12: Prioridad | B12: Descripcion
A13: Atencion academica | B13: =IF(MAX(E6:E8)>0,"Reforzar grado "&INDEX(D6:D8,MATCH(MAX(E6:E8),E6:E8,0))&" ("&MAX(E6:E8)&" estudiantes bajo 3.0)","✓ Sin alertas académicas")
A14: Atencion asistencia | B14: =IF(MAX(H6:H8)>0,"Revisar ausencias en grado "&INDEX(G6:G8,MATCH(MAX(H6:H8),H6:H8,0))&" ("&MAX(H6:H8)&" ausencias)","✓ Sin alertas de asistencia")
A51: 7° | B51: =IF(MAESTRO!B39="","",IFERROR(RESUMEN_7°!A38,"")) | C51: =IF(MAESTRO!B39="","",IFERROR(RESUMEN_7°!B38,"")) | D51: =IF(RESUMEN_7°!B39="","",IFERROR(RESUMEN_7°!F39,"")) | E51: =IF(RESUMEN_7°!B39="","",IFERROR(RESUMEN_7°!R39,"")) | F51: =IF(RESUMEN_7°!B39="","",IFERROR('Asistencia (7°)'!BI37+'Asistencia (7°)'!BI80+'Asistencia (7°)'!BI123,"")) | G51: =IF(AND(RESUMEN_7°!B38=""),"",IF(OR(IFERROR(RESUMEN_7°!F38,0)<3,IFERROR(RESUMEN_7°!R38,0)<3),"⚠ REVISAR","OK"))
A52: 7° | B52: =IF(MAESTRO!B40="","",IFERROR(RESUMEN_7°!A39,"")) | C52: =IF(MAESTRO!B40="","",IFERROR(RESUMEN_7°!B39,"")) | D52: =IF(RESUMEN_7°!B40="","",IFERROR(RESUMEN_7°!F40,"")) | E52: =IF(RESUMEN_7°!B40="","",IFERROR(RESUMEN_7°!R40,"")) | F52: =IF(RESUMEN_7°!B40="","",IFERROR('Asistencia (7°)'!BI38+'Asistencia (7°)'!BI81+'Asistencia (7°)'!BI124,"")) | G52: =IF(AND(RESUMEN_7°!B39=""),"",IF(OR(IFERROR(RESUMEN_7°!F39,0)<3,IFERROR(RESUMEN_7°!R39,0)<3),"⚠ REVISAR","OK"))
A53: 7° | B53: =IF(MAESTRO!B41="","",IFERROR(RESUMEN_7°!A40,"")) | C53: =IF(MAESTRO!B41="","",IFERROR(RESUMEN_7°!B40,"")) | D53: =IF(RESUMEN_7°!B41="","",IFERROR(RESUMEN_7°!F41,"")) | E53: =IF(RESUMEN_7°!B41="","",IFERROR(RESUMEN_7°!R41,"")) | F53: =IF(RESUMEN_7°!B41="","",IFERROR('Asistencia (7°)'!BI39+'Asistencia (7°)'!BI82+'Asistencia (7°)'!BI125,"")) | G53: =IF(AND(RESUMEN_7°!B40=""),"",IF(OR(IFERROR(RESUMEN_7°!F40,0)<3,IFERROR(RESUMEN_7°!R40,0)<3),"⚠ REVISAR","OK"))
A54: 7° | B54: =IF(MAESTRO!B42="","",IFERROR(RESUMEN_7°!A41,"")) | C54: =IF(MAESTRO!B42="","",IFERROR(RESUMEN_7°!B41,"")) | D54: =IF(RESUMEN_7°!B42="","",IFERROR(RESUMEN_7°!F42,"")) | E54: =IF(RESUMEN_7°!B42="","",IFERROR(RESUMEN_7°!R42,"")) | F54: =IF(RESUMEN_7°!B42="","",IFERROR('Asistencia (7°)'!BI40+'Asistencia (7°)'!BI83+'Asistencia (7°)'!BI126,"")) | G54: =IF(AND(RESUMEN_7°!B41=""),"",IF(OR(IFERROR(RESUMEN_7°!F41,0)<3,IFERROR(RESUMEN_7°!R41,0)<3),"⚠ REVISAR","OK"))
A55: 7° | B55: =IF(MAESTRO!B43="","",IFERROR(RESUMEN_7°!A42,"")) | C55: =IF(MAESTRO!B43="","",IFERROR(RESUMEN_7°!B42,"")) | D55: =IF(RESUMEN_7°!B43="","",IFERROR(RESUMEN_7°!F43,"")) | E55: =IF(RESUMEN_7°!B43="","",IFERROR(RESUMEN_7°!R43,"")) | F55: =IF(RESUMEN_7°!B43="","",IFERROR('Asistencia (7°)'!BI41+'Asistencia (7°)'!BI84+'Asistencia (7°)'!BI127,"")) | G55: =IF(AND(RESUMEN_7°!B42=""),"",IF(OR(IFERROR(RESUMEN_7°!F42,0)<3,IFERROR(RESUMEN_7°!R42,0)<3),"⚠ REVISAR","OK"))
A56: 7° | B56: =IF(MAESTRO!B44="","",IFERROR(RESUMEN_7°!A43,"")) | C56: =IF(MAESTRO!B44="","",IFERROR(RESUMEN_7°!B43,"")) | D56: =IF(RESUMEN_7°!B44="","",IFERROR(RESUMEN_7°!F44,"")) | E56: =IF(RESUMEN_7°!B44="","",IFERROR(RESUMEN_7°!R44,"")) | F56: =IF(RESUMEN_7°!B44="","",IFERROR('Asistencia (7°)'!BI42+'Asistencia (7°)'!BI85+'Asistencia (7°)'!BI128,"")) | G56: =IF(AND(RESUMEN_7°!B43=""),"",IF(OR(IFERROR(RESUMEN_7°!F43,0)<3,IFERROR(RESUMEN_7°!R43,0)<3),"⚠ REVISAR","OK"))
A57: 7° | B57: =RESUMEN_7°!A44 | C57: =RESUMEN_7°!B44 | D57: =IF(C57="","",IFERROR(RESUMEN_7°!F44,"")) | E57: =IF(C57="","",IFERROR(RESUMEN_7°!R44,"")) | F57: =IF(C57="","",IFERROR('Asistencia (7°)'!BI42,"")) | G57: =IF(AND(RESUMEN_7°!B44=""),"",IF(OR(IFERROR(RESUMEN_7°!F44,0)<3,IFERROR(RESUMEN_7°!R44,0)<3),"⚠ REVISAR","OK"))
A58: 8° | B58: =IF(MAESTRO!D5="","",IFERROR(RESUMEN_8°!A5,"")) | C58: =IF(MAESTRO!D5="","",IFERROR(RESUMEN_8°!B5,"")) | D58: =IF(RESUMEN_8°!B5="","",IFERROR(RESUMEN_8°!F5,"")) | E58: =IF(RESUMEN_8°!B5="","",IFERROR(RESUMEN_8°!R5,"")) | F58: =IF(RESUMEN_8°!B5="","",IFERROR('Asistencia (8°)'!BI3+'Asistencia (8°)'!BI46+'Asistencia (8°)'!BI89,"")) | G58: =IF(AND(RESUMEN_8°!B5=""),"",IF(OR(IFERROR(RESUMEN_8°!F5,0)<3,IFERROR(RESUMEN_8°!R5,0)<3),"⚠ REVISAR","OK"))
A59: 8° | B59: =IF(MAESTRO!D6="","",IFERROR(RESUMEN_8°!A6,"")) | C59: =IF(MAESTRO!D6="","",IFERROR(RESUMEN_8°!B6,"")) | D59: =IF(RESUMEN_8°!B6="","",IFERROR(RESUMEN_8°!F6,"")) | E59: =IF(RESUMEN_8°!B6="","",IFERROR(RESUMEN_8°!R6,"")) | F59: =IF(RESUMEN_8°!B6="","",IFERROR('Asistencia (8°)'!BI4+'Asistencia (8°)'!BI47+'Asistencia (8°)'!BI90,"")) | G59: =IF(AND(RESUMEN_8°!B6=""),"",IF(OR(IFERROR(RESUMEN_8°!F6,0)<3,IFERROR(RESUMEN_8°!R6,0)<3),"⚠ REVISAR","OK"))
A60: 8° | B60: =IF(MAESTRO!D7="","",IFERROR(RESUMEN_8°!A7,"")) | C60: =IF(MAESTRO!D7="","",IFERROR(RESUMEN_8°!B7,"")) | D60: =IF(RESUMEN_8°!B7="","",IFERROR(RESUMEN_8°!F7,"")) | E60: =IF(RESUMEN_8°!B7="","",IFERROR(RESUMEN_8°!R7,"")) | F60: =IF(RESUMEN_8°!B7="","",IFERROR('Asistencia (8°)'!BI5+'Asistencia (8°)'!BI48+'Asistencia (8°)'!BI91,"")) | G60: =IF(AND(RESUMEN_8°!B7=""),"",IF(OR(IFERROR(RESUMEN_8°!F7,0)<3,IFERROR(RESUMEN_8°!R7,0)<3),"⚠ REVISAR","OK"))
A61: 8° | B61: =IF(MAESTRO!D8="","",IFERROR(RESUMEN_8°!A8,"")) | C61: =IF(MAESTRO!D8="","",IFERROR(RESUMEN_8°!B8,"")) | D61: =IF(RESUMEN_8°!B8="","",IFERROR(RESUMEN_8°!F8,"")) | E61: =IF(RESUMEN_8°!B8="","",IFERROR(RESUMEN_8°!R8,"")) | F61: =IF(RESUMEN_8°!B8="","",IFERROR('Asistencia (8°)'!BI6+'Asistencia (8°)'!BI49+'Asistencia (8°)'!BI92,"")) | G61: =IF(AND(RESUMEN_8°!B8=""),"",IF(OR(IFERROR(RESUMEN_8°!F8,0)<3,IFERROR(RESUMEN_8°!R8,0)<3),"⚠ REVISAR","OK"))
A62: 8° | B62: =IF(MAESTRO!D9="","",IFERROR(RESUMEN_8°!A9,"")) | C62: =IF(MAESTRO!D9="","",IFERROR(RESUMEN_8°!B9,"")) | D62: =IF(RESUMEN_8°!B9="","",IFERROR(RESUMEN_8°!F9,"")) | E62: =IF(RESUMEN_8°!B9="","",IFERROR(RESUMEN_8°!R9,"")) | F62: =IF(RESUMEN_8°!B9="","",IFERROR('Asistencia (8°)'!BI7+'Asistencia (8°)'!BI50+'Asistencia (8°)'!BI93,"")) | G62: =IF(AND(RESUMEN_8°!B9=""),"",IF(OR(IFERROR(RESUMEN_8°!F9,0)<3,IFERROR(RESUMEN_8°!R9,0)<3),"⚠ REVISAR","OK"))
A63: 8° | B63: =IF(MAESTRO!D10="","",IFERROR(RESUMEN_8°!A10,"")) | C63: =IF(MAESTRO!D10="","",IFERROR(RESUMEN_8°!B10,"")) | D63: =IF(RESUMEN_8°!B10="","",IFERROR(RESUMEN_8°!F10,"")) | E63: =IF(RESUMEN_8°!B10="","",IFERROR(RESUMEN_8°!R10,"")) | F63: =IF(RESUMEN_8°!B10="","",IFERROR('Asistencia (8°)'!BI8+'Asistencia (8°)'!BI51+'Asistencia (8°)'!BI94,"")) | G63: =IF(AND(RESUMEN_8°!B10=""),"",IF(OR(IFERROR(RESUMEN_8°!F10,0)<3,IFERROR(RESUMEN_8°!R10,0)<3),"⚠ REVISAR","OK"))
A64: 8° | B64: =IF(MAESTRO!D11="","",IFERROR(RESUMEN_8°!A11,"")) | C64: =IF(MAESTRO!D11="","",IFERROR(RESUMEN_8°!B11,"")) | D64: =IF(RESUMEN_8°!B11="","",IFERROR(RESUMEN_8°!F11,"")) | E64: =IF(RESUMEN_8°!B11="","",IFERROR(RESUMEN_8°!R11,"")) | F64: =IF(RESUMEN_8°!B11="","",IFERROR('Asistencia (8°)'!BI9+'Asistencia (8°)'!BI52+'Asistencia (8°)'!BI95,"")) | G64: =IF(AND(RESUMEN_8°!B11=""),"",IF(OR(IFERROR(RESUMEN_8°!F11,0)<3,IFERROR(RESUMEN_8°!R11,0)<3),"⚠ REVISAR","OK"))
A65: 8° | B65: =IF(MAESTRO!D12="","",IFERROR(RESUMEN_8°!A12,"")) | C65: =IF(MAESTRO!D12="","",IFERROR(RESUMEN_8°!B12,"")) | D65: =IF(RESUMEN_8°!B12="","",IFERROR(RESUMEN_8°!F12,"")) | E65: =IF(RESUMEN_8°!B12="","",IFERROR(RESUMEN_8°!R12,"")) | F65: =IF(RESUMEN_8°!B12="","",IFERROR('Asistencia (8°)'!BI10+'Asistencia (8°)'!BI53+'Asistencia (8°)'!BI96,"")) | G65: =IF(AND(RESUMEN_8°!B12=""),"",IF(OR(IFERROR(RESUMEN_8°!F12,0)<3,IFERROR(RESUMEN_8°!R12,0)<3),"⚠ REVISAR","OK"))
A66: 8° | B66: =IF(MAESTRO!D13="","",IFERROR(RESUMEN_8°!A13,"")) | C66: =IF(MAESTRO!D13="","",IFERROR(RESUMEN_8°!B13,"")) | D66: =IF(RESUMEN_8°!B13="","",IFERROR(RESUMEN_8°!F13,"")) | E66: =IF(RESUMEN_8°!B13="","",IFERROR(RESUMEN_8°!R13,"")) | F66: =IF(RESUMEN_8°!B13="","",IFERROR('Asistencia (8°)'!BI11+'Asistencia (8°)'!BI54+'Asistencia (8°)'!BI97,"")) | G66: =IF(AND(RESUMEN_8°!B13=""),"",IF(OR(IFERROR(RESUMEN_8°!F13,0)<3,IFERROR(RESUMEN_8°!R13,0)<3),"⚠ REVISAR","OK"))
A67: 8° | B67: =IF(MAESTRO!D14="","",IFERROR(RESUMEN_8°!A14,"")) | C67: =IF(MAESTRO!D14="","",IFERROR(RESUMEN_8°!B14,"")) | D67: =IF(RESUMEN_8°!B14="","",IFERROR(RESUMEN_8°!F14,"")) | E67: =IF(RESUMEN_8°!B14="","",IFERROR(RESUMEN_8°!R14,"")) | F67: =IF(RESUMEN_8°!B14="","",IFERROR('Asistencia (8°)'!BI12+'Asistencia (8°)'!BI55+'Asistencia (8°)'!BI98,"")) | G67: =IF(AND(RESUMEN_8°!B14=""),"",IF(OR(IFERROR(RESUMEN_8°!F14,0)<3,IFERROR(RESUMEN_8°!R14,0)<3),"⚠ REVISAR","OK"))
A68: 8° | B68: =IF(MAESTRO!D15="","",IFERROR(RESUMEN_8°!A15,"")) | C68: =IF(MAESTRO!D15="","",IFERROR(RESUMEN_8°!B15,"")) | D68: =IF(RESUMEN_8°!B15="","",IFERROR(RESUMEN_8°!F15,"")) | E68: =IF(RESUMEN_8°!B15="","",IFERROR(RESUMEN_8°!R15,"")) | F68: =IF(RESUMEN_8°!B15="","",IFERROR('Asistencia (8°)'!BI13+'Asistencia (8°)'!BI56+'Asistencia (8°)'!BI99,"")) | G68: =IF(AND(RESUMEN_8°!B15=""),"",IF(OR(IFERROR(RESUMEN_8°!F15,0)<3,IFERROR(RESUMEN_8°!R15,0)<3),"⚠ REVISAR","OK"))
A69: 8° | B69: =IF(MAESTRO!D16="","",IFERROR(RESUMEN_8°!A16,"")) | C69: =IF(MAESTRO!D16="","",IFERROR(RESUMEN_8°!B16,"")) | D69: =IF(RESUMEN_8°!B16="","",IFERROR(RESUMEN_8°!F16,"")) | E69: =IF(RESUMEN_8°!B16="","",IFERROR(RESUMEN_8°!R16,"")) | F69: =IF(RESUMEN_8°!B16="","",IFERROR('Asistencia (8°)'!BI14+'Asistencia (8°)'!BI57+'Asistencia (8°)'!BI100,"")) | G69: =IF(AND(RESUMEN_8°!B16=""),"",IF(OR(IFERROR(RESUMEN_8°!F16,0)<3,IFERROR(RESUMEN_8°!R16,0)<3),"⚠ REVISAR","OK"))
... A97: 8° | B97: =IF(MAESTRO!D44="","",IFERROR(RESUMEN_8°!A44,"")) | C97: =IF(MAESTRO!D44="","",IFERROR(RESUMEN_8°!B44,"")) | D97: =IF(RESUMEN_8°!B44="","",IFERROR(RESUMEN_8°!F44,"")) | E97: =IF(RESUMEN_8°!B44="","",IFERROR(RESUMEN_8°!R44,"")) | F97: =IF(RESUMEN_8°!B44="","",IFERROR('Asistencia (8°)'!BI42+'Asistencia (8°)'!BI85+'Asistencia (8°)'!BI128,"")) | G97: =IF(AND(RESUMEN_8°!B44=""),"",IF(OR(IFERROR(RESUMEN_8°!F44,0)<3,IFERROR(RESUMEN_8°!R44,0)<3),"⚠ REVISAR","OK"))
A98: 9° | B98: =IF(MAESTRO!F5="","",IFERROR(RESUMEN_9°!A5,"")) | C98: =IF(MAESTRO!F5="","",IFERROR(RESUMEN_9°!B5,"")) | D98: =IF(RESUMEN_9°!B5="","",IFERROR(RESUMEN_9°!F5,"")) | E98: =IF(RESUMEN_9°!B5="","",IFERROR(RESUMEN_9°!R5,"")) | F98: =IF(RESUMEN_9°!B5="","",IFERROR('Asistencia (9°)'!BI3+'Asistencia (9°)'!BI46+'Asistencia (9°)'!BI89,"")) | G98: =IF(AND(RESUMEN_9°!B5=""),"",IF(OR(IFERROR(RESUMEN_9°!F5,0)<3,IFERROR(RESUMEN_9°!V5,0)<3),"⚠ REVISAR","OK"))
A99: 9° | B99: =IF(MAESTRO!F6="","",IFERROR(RESUMEN_9°!A6,"")) | C99: =IF(MAESTRO!F6="","",IFERROR(RESUMEN_9°!B6,"")) | D99: =IF(RESUMEN_9°!B6="","",IFERROR(RESUMEN_9°!F6,"")) | E99: =IF(RESUMEN_9°!B6="","",IFERROR(RESUMEN_9°!R6,"")) | F99: =IF(RESUMEN_9°!B6="","",IFERROR('Asistencia (9°)'!BI4+'Asistencia (9°)'!BI47+'Asistencia (9°)'!BI90,"")) | G99: =IF(AND(RESUMEN_9°!B6=""),"",IF(OR(IFERROR(RESUMEN_9°!F6,0)<3,IFERROR(RESUMEN_9°!V6,0)<3),"⚠ REVISAR","OK"))
A100: 9° | B100: =IF(MAESTRO!F7="","",IFERROR(RESUMEN_9°!A7,"")) | C100: =IF(MAESTRO!F7="","",IFERROR(RESUMEN_9°!B7,"")) | D100: =IF(RESUMEN_9°!B7="","",IFERROR(RESUMEN_9°!F7,"")) | E100: =IF(RESUMEN_9°!B7="","",IFERROR(RESUMEN_9°!R7,"")) | F100: =IF(RESUMEN_9°!B7="","",IFERROR('Asistencia (9°)'!BI5+'Asistencia (9°)'!BI48+'Asistencia (9°)'!BI91,"")) | G100: =IF(AND(RESUMEN_9°!B7=""),"",IF(OR(IFERROR(RESUMEN_9°!F7,0)<3,IFERROR(RESUMEN_9°!V7,0)<3),"⚠ REVISAR","OK"))
A101: 9° | B101: =IF(MAESTRO!F8="","",IFERROR(RESUMEN_9°!A8,"")) | C101: =IF(MAESTRO!F8="","",IFERROR(RESUMEN_9°!B8,"")) | D101: =IF(RESUMEN_9°!B8="","",IFERROR(RESUMEN_9°!F8,"")) | E101: =IF(RESUMEN_9°!B8="","",IFERROR(RESUMEN_9°!R8,"")) | F101: =IF(RESUMEN_9°!B8="","",IFERROR('Asistencia (9°)'!BI6+'Asistencia (9°)'!BI49+'Asistencia (9°)'!BI92,"")) | G101: =IF(AND(RESUMEN_9°!B8=""),"",IF(OR(IFERROR(RESUMEN_9°!F8,0)<3,IFERROR(RESUMEN_9°!V8,0)<3),"⚠ REVISAR","OK"))
A102: 9° | B102: =IF(MAESTRO!F9="","",IFERROR(RESUMEN_9°!A9,"")) | C102: =IF(MAESTRO!F9="","",IFERROR(RESUMEN_9°!B9,"")) | D102: =IF(RESUMEN_9°!B9="","",IFERROR(RESUMEN_9°!F9,"")) | E102: =IF(RESUMEN_9°!B9="","",IFERROR(RESUMEN_9°!R9,"")) | F102: =IF(RESUMEN_9°!B9="","",IFERROR('Asistencia (9°)'!BI7+'Asistencia (9°)'!BI50+'Asistencia (9°)'!BI93,"")) | G102: =IF(AND(RESUMEN_9°!B9=""),"",IF(OR(IFERROR(RESUMEN_9°!F9,0)<3,IFERROR(RESUMEN_9°!V9,0)<3),"⚠ REVISAR","OK"))
A103: 9° | B103: =IF(MAESTRO!F10="","",IFERROR(RESUMEN_9°!A10,"")) | C103: =IF(MAESTRO!F10="","",IFERROR(RESUMEN_9°!B10,"")) | D103: =IF(RESUMEN_9°!B10="","",IFERROR(RESUMEN_9°!F10,"")) | E103: =IF(RESUMEN_9°!B10="","",IFERROR(RESUMEN_9°!R10,"")) | F103: =IF(RESUMEN_9°!B10="","",IFERROR('Asistencia (9°)'!BI8+'Asistencia (9°)'!BI51+'Asistencia (9°)'!BI94,"")) | G103: =IF(AND(RESUMEN_9°!B10=""),"",IF(OR(IFERROR(RESUMEN_9°!F10,0)<3,IFERROR(RESUMEN_9°!V10,0)<3),"⚠ REVISAR","OK"))
A104: 9° | B104: =IF(MAESTRO!F11="","",IFERROR(RESUMEN_9°!A11,"")) | C104: =IF(MAESTRO!F11="","",IFERROR(RESUMEN_9°!B11,"")) | D104: =IF(RESUMEN_9°!B11="","",IFERROR(RESUMEN_9°!F11,"")) | E104: =IF(RESUMEN_9°!B11="","",IFERROR(RESUMEN_9°!R11,"")) | F104: =IF(RESUMEN_9°!B11="","",IFERROR('Asistencia (9°)'!BI9+'Asistencia (9°)'!BI52+'Asistencia (9°)'!BI95,"")) | G104: =IF(AND(RESUMEN_9°!B11=""),"",IF(OR(IFERROR(RESUMEN_9°!F11,0)<3,IFERROR(RESUMEN_9°!V11,0)<3),"⚠ REVISAR","OK"))
A105: 9° | B105: =IF(MAESTRO!F12="","",IFERROR(RESUMEN_9°!A12,"")) | C105: =IF(MAESTRO!F12="","",IFERROR(RESUMEN_9°!B12,"")) | D105: =IF(RESUMEN_9°!B12="","",IFERROR(RESUMEN_9°!F12,"")) | E105: =IF(RESUMEN_9°!B12="","",IFERROR(RESUMEN_9°!R12,"")) | F105: =IF(RESUMEN_9°!B12="","",IFERROR('Asistencia (9°)'!BI10+'Asistencia (9°)'!BI53+'Asistencia (9°)'!BI96,"")) | G105: =IF(AND(RESUMEN_9°!B12=""),"",IF(OR(IFERROR(RESUMEN_9°!F12,0)<3,IFERROR(RESUMEN_9°!V12,0)<3),"⚠ REVISAR","OK"))
A106: 9° | B106: =IF(MAESTRO!F13="","",IFERROR(RESUMEN_9°!A13,"")) | C106: =IF(MAESTRO!F13="","",IFERROR(RESUMEN_9°!B13,"")) | D106: =IF(RESUMEN_9°!B13="","",IFERROR(RESUMEN_9°!F13,"")) | E106: =IF(RESUMEN_9°!B13="","",IFERROR(RESUMEN_9°!R13,"")) | F106: =IF(RESUMEN_9°!B13="","",IFERROR('Asistencia (9°)'!BI11+'Asistencia (9°)'!BI54+'Asistencia (9°)'!BI97,"")) | G106: =IF(AND(RESUMEN_9°!B13=""),"",IF(OR(IFERROR(RESUMEN_9°!F13,0)<3,IFERROR(RESUMEN_9°!V13,0)<3),"⚠ REVISAR","OK"))
A107: 9° | B107: =IF(MAESTRO!F14="","",IFERROR(RESUMEN_9°!A14,"")) | C107: =IF(MAESTRO!F14="","",IFERROR(RESUMEN_9°!B14,"")) | D107: =IF(RESUMEN_9°!B14="","",IFERROR(RESUMEN_9°!F14,"")) | E107: =IF(RESUMEN_9°!B14="","",IFERROR(RESUMEN_9°!R14,"")) | F107: =IF(RESUMEN_9°!B14="","",IFERROR('Asistencia (9°)'!BI12+'Asistencia (9°)'!BI55+'Asistencia (9°)'!BI98,"")) | G107: =IF(AND(RESUMEN_9°!B14=""),"",IF(OR(IFERROR(RESUMEN_9°!F14,0)<3,IFERROR(RESUMEN_9°!V14,0)<3),"⚠ REVISAR","OK"))
A108: 9° | B108: =IF(MAESTRO!F15="","",IFERROR(RESUMEN_9°!A15,"")) | C108: =IF(MAESTRO!F15="","",IFERROR(RESUMEN_9°!B15,"")) | D108: =IF(RESUMEN_9°!B15="","",IFERROR(RESUMEN_9°!F15,"")) | E108: =IF(RESUMEN_9°!B15="","",IFERROR(RESUMEN_9°!R15,"")) | F108: =IF(RESUMEN_9°!B15="","",IFERROR('Asistencia (9°)'!BI13+'Asistencia (9°)'!BI56+'Asistencia (9°)'!BI99,"")) | G108: =IF(AND(RESUMEN_9°!B15=""),"",IF(OR(IFERROR(RESUMEN_9°!F15,0)<3,IFERROR(RESUMEN_9°!V15,0)<3),"⚠ REVISAR","OK"))
...

Sheet GRAFICOS
A1: GRAFICOS Y ALERTAS DE RENDIMIENTO
A5: Grado | B5: No | C5: Estudiante | D5: Ausencias | E5: NotaFinal | F5: TareasVacias | H5: Indicador | I5: Estudiante | J5: Valor | L5: Grado | M5: Ausencias | N5: RiesgoAcademico
A6: 7° | B6: 1 | C6: =IF(MAESTRO!B5="","",IFERROR(MAESTRO!B5,"")) | D6: =IF(MAESTRO!B5="","",IFERROR(COUNTIF('Asistencia (7°)'!C3:BH3,"-")+COUNTIF('Asistencia (7°)'!C46:BH46,"-")+COUNTIF('Asistencia (7°)'!C89:BH89,"-"),"")) | E6: =IF(MAESTRO!B5="","",IFERROR(TRUNC(AVERAGE(IFERROR('PROM (Ingles 7°)'!AE5,""),IFERROR('PROM (Ingles 7°)'!BL5,""),IFERROR('PROM (Ingles 7°)'!CS5,""),IFERROR('PROM (Agropecuaria 7°)'!AE5,""),IFERROR('PROM (Agropecuaria 7°)'!BL5,""),IFERROR('PROM (Agropecuaria 7°)'!CT5,""),IFERROR('PROM (Hogar y Desarrollo 7°)'!AE5,""),IFERROR('PROM (Hogar y Desarrollo 7°)'!BM5,""),IFERROR('PROM (Hogar y Desarrollo 7°)'!CT5,"")),1),"")) | F6: =IF(MAESTRO!B5="","",IFERROR(COUNTBLANK('PROM (Ingles 7°)'!C5:O5),"")) | H6: Mas inasistencia | I6: =IFERROR(INDEX(C6:C125,MATCH(MAX(D6:D125),D6:D125,0)),"") | J6: =IFERROR(MAX(D6:D125),"") | L6: 7° | M6: =IFERROR(SUMIFS(D6:D125,A6:A125,"7°"),"") | N6: =IFERROR(COUNTIFS(A6:A125,"7°",E6:E125,"<3",E6:E125,">0"),"")
A7: 7° | B7: 2 | C7: =IF(MAESTRO!B6="","",IFERROR(MAESTRO!B6,"")) | D7: =IF(MAESTRO!B6="","",IFERROR(COUNTIF('Asistencia (7°)'!C4:BH4,"-")+COUNTIF('Asistencia (7°)'!C47:BH47,"-")+COUNTIF('Asistencia (7°)'!C90:BH90,"-"),"")) | E7: =IF(MAESTRO!B6="","",IFERROR(TRUNC(AVERAGE(IFERROR('PROM (Ingles 7°)'!AE6,""),IFERROR('PROM (Ingles 7°)'!BL6,""),IFERROR('PROM (Ingles 7°)'!CS6,""),IFERROR('PROM (Agropecuaria 7°)'!AE6,""),IFERROR('PROM (Agropecuaria 7°)'!BL6,""),IFERROR('PROM (Agropecuaria 7°)'!CT6,""),IFERROR('PROM (Hogar y Desarrollo 7°)'!AE6,""),IFERROR('PROM (Hogar y Desarrollo 7°)'!BM6,""),IFERROR('PROM (Hogar y Desarrollo 7°)'!CT6,"")),1),"")) | F7: =IF(MAESTRO!B6="","",IFERROR(COUNTBLANK('PROM (Ingles 7°)'!C6:O6),"")) | H7: Nota mas baja | I7: =IFERROR(INDEX(C6:C125,MATCH(_xludf.MINIFS(E6:E125,E6:E125,">0"),E6:E125,0)),"") | J7: =IFERROR(_xludf.MINIFS(E6:E125,E6:E125,">0"),"") | L7: 8° | M7: =IFERROR(SUMIFS(D6:D125,A6:A125,"8°"),"") | N7: =IFERROR(COUNTIFS(A6:A125,"8°",E6:E125,"<3",E6:E125,">0"),"")
A8: 7° | B8: 3 | C8: =IF(MAESTRO!B7="","",IFERROR(MAESTRO!B7,"")) | D8: =IF(MAESTRO!B7="","",IFERROR(COUNTIF('Asistencia (7°)'!C5:BH5,"-")+COUNTIF('Asistencia (7°)'!C48:BH48,"-")+COUNTIF('Asistencia (7°)'!C91:BH91,"-"),"")) | E8: =IF(MAESTRO!B7="","",IFERROR(TRUNC(AVERAGE(IFERROR('PROM (Ingles 7°)'!AE7,""),IFERROR('PROM (Ingles 7°)'!BL7,""),IFERROR('PROM (Ingles 7°)'!CS7,""),IFERROR('PROM (Agropecuaria 7°)'!AE7,""),IFERROR('PROM (Agropecuaria 7°)'!BL7,""),IFERROR('PROM (Agropecuaria 7°)'!CT7,""),IFERROR('PROM (Hogar y Desarrollo 7°)'!AE7,""),IFERROR('PROM (Hogar y Desarrollo 7°)'!BM7,""),IFERROR('PROM (Hogar y Desarrollo 7°)'!CT7,"")),1),"")) | F8: =IF(MAESTRO!B7="","",IFERROR(COUNTBLANK('PROM (Ingles 7°)'!C7:O7),"")) | H8: No entrega tareas | I8: =IFERROR(INDEX(C6:C125,MATCH(MAX(F6:F125),F6:F125,0)),"") | J8: =IFERROR(MAX(F6:F125),"") | L8: 9° | M8: =IFERROR(SUMIFS(D6:D125,A6:A125,"9°"),"") | N8: =IFERROR(COUNTIFS(A6:A125,"9°",E6:E125,"<3",E6:E125,">0"),"")
A9: 7° | B9: 4 | C9: =IF(MAESTRO!B8="","",IFERROR(MAESTRO!B8,"")) | D9: =IF(MAESTRO!B8="","",IFERROR(COUNTIF('Asistencia (7°)'!C6:BH6,"-")+COUNTIF('Asistencia (7°)'!C49:BH49,"-")+COUNTIF('Asistencia (7°)'!C92:BH92,"-"),"")) | E9: =IF(MAESTRO!B8="","",IFERROR(TRUNC(AVERAGE(IFERROR('PROM (Ingles 7°)'!AE8,""),IFERROR('PROM (Ingles 7°)'!BL8,""),IFERROR('PROM (Ingles 7°)'!CS8,""),IFERROR('PROM (Agropecuaria 7°)'!AE8,""),IFERROR('PROM (Agropecuaria 7°)'!BL8,""),IFERROR('PROM (Agropecuaria 7°)'!CT8,""),IFERROR('PROM (Hogar y Desarrollo 7°)'!AE8,""),IFERROR('PROM (Hogar y Desarrollo 7°)'!BM8,""),IFERROR('PROM (Hogar y Desarrollo 7°)'!CT8,"")),1),"")) | F9: =IF(MAESTRO!B8="","",IFERROR(COUNTBLANK('PROM (Ingles 7°)'!C8:O8),"")) | H9: Mejor estudiante | I9: =IFERROR(INDEX(C6:C125,MATCH(MAX(E6:E125),E6:E125,0)),"") | J9: =IFERROR(MAX(E6:E125),"")
A10: 7° | B10: 5 | C10: =IF(MAESTRO!B9="","",IFERROR(MAESTRO!B9,"")) | D10: =IF(MAESTRO!B9="","",IFERROR(COUNTIF('Asistencia (7°)'!C7:BH7,"-")+COUNTIF('Asistencia (7°)'!C50:BH50,"-")+COUNTIF('Asistencia (7°)'!C93:BH93,"-"),"")) | E10: =IF(MAESTRO!B9="","",IFERROR(TRUNC(AVERAGE(IFERROR('PROM (Ingles 7°)'!AE9,""),IFERROR('PROM (Ingles 7°)'!BL9,""),IFERROR('PROM (Ingles 7°)'!CS9,""),IFERROR('PROM (Agropecuaria 7°)'!AE9,""),IFERROR('PROM (Agropecuaria 7°)'!BL9,""),IFERROR('PROM (Agropecuaria 7°)'!CT9,""),IFERROR('PROM (Hogar y Desarrollo 7°)'!AE9,""),IFERROR('PROM (Hogar y Desarrollo 7°)'!BM9,""),IFERROR('PROM (Hogar y Desarrollo 7°)'!CT9,"")),1),"")) | F10: =IF(MAESTRO!B9="","",IFERROR(COUNTBLANK('PROM (Ingles 7°)'!C9:O9),""))
A11: 7° | B11: 6 | C11: =IF(MAESTRO!B10="","",IFERROR(MAESTRO!B10,"")) | D11: =IF(MAESTRO!B10="","",IFERROR(COUNTIF('Asistencia (7°)'!C8:BH8,"-")+COUNTIF('Asistencia (7°)'!C51:BH51,"-")+COUNTIF('Asistencia (7°)'!C94:BH94,"-"),"")) | E11: =IF(MAESTRO!B10="","",IFERROR(TRUNC(AVERAGE(IFERROR('PROM (Ingles 7°)'!AE10,""),IFERROR('PROM (Ingles 7°)'!BL10,""),IFERROR('PROM (Ingles 7°)'!CS10,""),IFERROR('PROM (Agropecuaria 7°)'!AE10,""),IFERROR('PROM (Agropecuaria 7°)'!BL10,""),IFERROR('PROM (Agropecuaria 7°)'!CT10,""),IFERROR('PROM (Hogar y Desarrollo 7°)'!AE10,""),IFERROR('PROM (Hogar y Desarrollo 7°)'!BM10,""),IFERROR('PROM (Hogar y Desarrollo 7°)'!CT10,"")),1),"")) | F11: =IF(MAESTRO!B10="","",IFERROR(COUNTBLANK('PROM (Ingles 7°)'!C10:O10),""))
A12: 7° | B12: 7 | C12: =IF(MAESTRO!B11="","",IFERROR(MAESTRO!B11,"")) | D12: =IF(MAESTRO!B11="","",IFERROR(COUNTIF('Asistencia (7°)'!C9:BH9,"-")+COUNTIF('Asistencia (7°)'!C52:BH52,"-")+COUNTIF('Asistencia (7°)'!C95:BH95,"-"),"")) | E12: =IF(MAESTRO!B11="","",IFERROR(TRUNC(AVERAGE(IFERROR('PROM (Ingles 7°)'!AE11,""),IFERROR('PROM (Ingles 7°)'!BL11,""),IFERROR('PROM (Ingles 7°)'!CS11,""),IFERROR('PROM (Agropecuaria 7°)'!AE11,""),IFERROR('PROM (Agropecuaria 7°)'!BL11,""),IFERROR('PROM (Agropecuaria 7°)'!CT11,""),IFERROR('PROM (Hogar y Desarrollo 7°)'!AE11,""),IFERROR('PROM (Hogar y Desarrollo 7°)'!BM11,""),IFERROR('PROM (Hogar y Desarrollo 7°)'!CT11,"")),1),"")) | F12: =IF(MAESTRO!B11="","",IFERROR(COUNTBLANK('PROM (Ingles 7°)'!C11:O11),""))
A13: 7° | B13: 8 | C13: =IF(MAESTRO!B12="","",IFERROR(MAESTRO!B12,"")) | D13: =IF(MAESTRO!B12="","",IFERROR(COUNTIF('Asistencia (7°)'!C10:BH10,"-")+COUNTIF('Asistencia (7°)'!C53:BH53,"-")+COUNTIF('Asistencia (7°)'!C96:BH96,"-"),"")) | E13: =IF(MAESTRO!B12="","",IFERROR(TRUNC(AVERAGE(IFERROR('PROM (Ingles 7°)'!AE12,""),IFERROR('PROM (Ingles 7°)'!BL12,""),IFERROR('PROM (Ingles 7°)'!CS12,""),IFERROR('PROM (Agropecuaria 7°)'!AE12,""),IFERROR('PROM (Agropecuaria 7°)'!BL12,""),IFERROR('PROM (Agropecuaria 7°)'!CT12,""),IFERROR('PROM (Hogar y Desarrollo 7°)'!AE12,""),IFERROR('PROM (Hogar y Desarrollo 7°)'!BM12,""),IFERROR('PROM (Hogar y Desarrollo 7°)'!CT12,"")),1),"")) | F13: =IF(MAESTRO!B12="","",IFERROR(COUNTBLANK('PROM (Ingles 7°)'!C12:O12),""))
A14: 7° | B14: 9 | C14: =IF(MAESTRO!B13="","",IFERROR(MAESTRO!B13,"")) | D14: =IF(MAESTRO!B13="","",IFERROR(COUNTIF('Asistencia (7°)'!C11:BH11,"-")+COUNTIF('Asistencia (7°)'!C54:BH54,"-")+COUNTIF('Asistencia (7°)'!C97:BH97,"-"),"")) | E14: =IF(MAESTRO!B13="","",IFERROR(TRUNC(AVERAGE(IFERROR('PROM (Ingles 7°)'!AE13,""),IFERROR('PROM (Ingles 7°)'!BL13,""),IFERROR('PROM (Ingles 7°)'!CS13,""),IFERROR('PROM (Agropecuaria 7°)'!AE13,""),IFERROR('PROM (Agropecuaria 7°)'!BL13,""),IFERROR('PROM (Agropecuaria 7°)'!CT13,""),IFERROR('PROM (Hogar y Desarrollo 7°)'!AE13,""),IFERROR('PROM (Hogar y Desarrollo 7°)'!BM13,""),IFERROR('PROM (Hogar y Desarrollo 7°)'!CT13,"")),1),"")) | F14: =IF(MAESTRO!B13="","",IFERROR(COUNTBLANK('PROM (Ingles 7°)'!C13:O13),""))
A15: 7° | B15: 10 | C15: =IF(MAESTRO!B14="","",IFERROR(MAESTRO!B14,"")) | D15: =IF(MAESTRO!B14="","",IFERROR(COUNTIF('Asistencia (7°)'!C12:BH12,"-")+COUNTIF('Asistencia (7°)'!C55:BH55,"-")+COUNTIF('Asistencia (7°)'!C98:BH98,"-"),"")) | E15: =IF(MAESTRO!B14="","",IFERROR(TRUNC(AVERAGE(IFERROR('PROM (Ingles 7°)'!AE14,""),IFERROR('PROM (Ingles 7°)'!BL14,""),IFERROR('PROM (Ingles 7°)'!CS14,""),IFERROR('PROM (Agropecuaria 7°)'!AE14,""),IFERROR('PROM (Agropecuaria 7°)'!BL14,""),IFERROR('PROM (Agropecuaria 7°)'!CT14,""),IFERROR('PROM (Hogar y Desarrollo 7°)'!AE14,""),IFERROR('PROM (Hogar y Desarrollo 7°)'!BM14,""),IFERROR('PROM (Hogar y Desarrollo 7°)'!CT14,"")),1),"")) | F15: =IF(MAESTRO!B14="","",IFERROR(COUNTBLANK('PROM (Ingles 7°)'!C14:O14),""))
A16: 7° | B16: 11 | C16: =IF(MAESTRO!B15="","",IFERROR(MAESTRO!B15,"")) | D16: =IF(MAESTRO!B15="","",IFERROR(COUNTIF('Asistencia (7°)'!C13:BH13,"-")+COUNTIF('Asistencia (7°)'!C56:BH56,"-")+COUNTIF('Asistencia (7°)'!C99:BH99,"-"),"")) | E16: =IF(MAESTRO!B15="","",IFERROR(TRUNC(AVERAGE(IFERROR('PROM (Ingles 7°)'!AE15,""),IFERROR('PROM (Ingles 7°)'!BL15,""),IFERROR('PROM (Ingles 7°)'!CS15,""),IFERROR('PROM (Agropecuaria 7°)'!AE15,""),IFERROR('PROM (Agropecuaria 7°)'!BL15,""),IFERROR('PROM (Agropecuaria 7°)'!CT15,""),IFERROR('PROM (Hogar y Desarrollo 7°)'!AE15,""),IFERROR('PROM (Hogar y Desarrollo 7°)'!BM15,""),IFERROR('PROM (Hogar y Desarrollo 7°)'!CT15,"")),1),"")) | F16: =IF(MAESTRO!B15="","",IFERROR(COUNTBLANK('PROM (Ingles 7°)'!C15:O15),""))
A17: 7° | B17: 12 | C17: =IF(MAESTRO!B16="","",IFERROR(MAESTRO!B16,"")) | D17: =IF(MAESTRO!B16="","",IFERROR(COUNTIF('Asistencia (7°)'!C14:BH14,"-")+COUNTIF('Asistencia (7°)'!C57:BH57,"-")+COUNTIF('Asistencia (7°)'!C100:BH100,"-"),"")) | E17: =IF(MAESTRO!B16="","",IFERROR(TRUNC(AVERAGE(IFERROR('PROM (Ingles 7°)'!AE16,""),IFERROR('PROM (Ingles 7°)'!BL16,""),IFERROR('PROM (Ingles 7°)'!CS16,""),IFERROR('PROM (Agropecuaria 7°)'!AE16,""),IFERROR('PROM (Agropecuaria 7°)'!BL16,""),IFERROR('PROM (Agropecuaria 7°)'!CT16,""),IFERROR('PROM (Hogar y Desarrollo 7°)'!AE16,""),IFERROR('PROM (Hogar y Desarrollo 7°)'!BM16,""),IFERROR('PROM (Hogar y Desarrollo 7°)'!CT16,"")),1),"")) | F17: =IF(MAESTRO!B16="","",IFERROR(COUNTBLANK('PROM (Ingles 7°)'!C16:O16),""))
A18: 7° | B18: 13 | C18: =IF(MAESTRO!B17="","",IFERROR(MAESTRO!B17,"")) | D18: =IF(MAESTRO!B17="","",IFERROR(COUNTIF('Asistencia (7°)'!C15:BH15,"-")+COUNTIF('Asistencia (7°)'!C58:BH58,"-")+COUNTIF('Asistencia (7°)'!C101:BH101,"-"),"")) | E18: =IF(MAESTRO!B17="","",IFERROR(TRUNC(AVERAGE(IFERROR('PROM (Ingles 7°)'!AE17,""),IFERROR('PROM (Ingles 7°)'!BL17,""),IFERROR('PROM (Ingles 7°)'!CS17,""),IFERROR('PROM (Agropecuaria 7°)'!AE17,""),IFERROR('PROM (Agropecuaria 7°)'!BL17,""),IFERROR('PROM (Agropecuaria 7°)'!CT17,""),IFERROR('PROM (Hogar y Desarrollo 7°)'!AE17,""),IFERROR('PROM (Hogar y Desarrollo 7°)'!BM17,""),IFERROR('PROM (Hogar y Desarrollo 7°)'!CT17,"")),1),"")) | F18: =IF(MAESTRO!B17="","",IFERROR(COUNTBLANK('PROM (Ingles 7°)'!C17:O17),""))
A19: 7° | B19: 14 | C19: =IF(MAESTRO!B18="","",IFERROR(MAESTRO!B18,"")) | D19: =IF(MAESTRO!B18="","",IFERROR(COUNTIF('Asistencia (7°)'!C16:BH16,"-")+COUNTIF('Asistencia (7°)'!C59:BH59,"-")+COUNTIF('Asistencia (7°)'!C102:BH102,"-"),"")) | E19: =IF(MAESTRO!B18="","",IFERROR(TRUNC(AVERAGE(IFERROR('PROM (Ingles 7°)'!AE18,""),IFERROR('PROM (Ingles 7°)'!BL18,""),IFERROR('PROM (Ingles 7°)'!CS18,""),IFERROR('PROM (Agropecuaria 7°)'!AE18,""),IFERROR('PROM (Agropecuaria 7°)'!BL18,""),IFERROR('PROM (Agropecuaria 7°)'!CT18,""),IFERROR('PROM (Hogar y Desarrollo 7°)'!AE18,""),IFERROR('PROM (Hogar y Desarrollo 7°)'!BM18,""),IFERROR('PROM (Hogar y Desarrollo 7°)'!CT18,"")),1),"")) | F19: =IF(MAESTRO!B18="","",IFERROR(COUNTBLANK('PROM (Ingles 7°)'!C18:O18),""))
A20: 7° | B20: 15 | C20: =IF(MAESTRO!B19="","",IFERROR(MAESTRO!B19,"")) | D20: =IF(MAESTRO!B19="","",IFERROR(COUNTIF('Asistencia (7°)'!C17:BH17,"-")+COUNTIF('Asistencia (7°)'!C60:BH60,"-")+COUNTIF('Asistencia (7°)'!C103:BH103,"-"),"")) | E20: =IF(MAESTRO!B19="","",IFERROR(TRUNC(AVERAGE(IFERROR('PROM (Ingles 7°)'!AE19,""),IFERROR('PROM (Ingles 7°)'!BL19,""),IFERROR('PROM (Ingles 7°)'!CS19,""),IFERROR('PROM (Agropecuaria 7°)'!AE19,""),IFERROR('PROM (Agropecuaria 7°)'!BL19,""),IFERROR('PROM (Agropecuaria 7°)'!CT19,""),IFERROR('PROM (Hogar y Desarrollo 7°)'!AE19,""),IFERROR('PROM (Hogar y Desarrollo 7°)'!BM19,""),IFERROR('PROM (Hogar y Desarrollo 7°)'!CT19,"")),1),"")) | F20: =IF(MAESTRO!B19="","",IFERROR(COUNTBLANK('PROM (Ingles 7°)'!C19:O19),""))
A21: 7° | B21: 16 | C21: =IF(MAESTRO!B20="","",IFERROR(MAESTRO!B20,"")) | D21: =IF(MAESTRO!B20="","",IFERROR(COUNTIF('Asistencia (7°)'!C18:BH18,"-")+COUNTIF('Asistencia (7°)'!C61:BH61,"-")+COUNTIF('Asistencia (7°)'!C104:BH104,"-"),"")) | E21: =IF(MAESTRO!B20="","",IFERROR(TRUNC(AVERAGE(IFERROR('PROM (Ingles 7°)'!AE20,""),IFERROR('PROM (Ingles 7°)'!BL20,""),IFERROR('PROM (Ingles 7°)'!CS20,""),IFERROR('PROM (Agropecuaria 7°)'!AE20,""),IFERROR('PROM (Agropecuaria 7°)'!BL20,""),IFERROR('PROM (Agropecuaria 7°)'!CT20,""),IFERROR('PROM (Hogar y Desarrollo 7°)'!AE20,""),IFERROR('PROM (Hogar y Desarrollo 7°)'!BM20,""),IFERROR('PROM (Hogar y Desarrollo 7°)'!CT20,"")),1),"")) | F21: =IF(MAESTRO!B20="","",IFERROR(COUNTBLANK('PROM (Ingles 7°)'!C20:O20),""))
... A45: 7° | B45: 40 | C45: =IF(MAESTRO!B44="","",IFERROR(MAESTRO!B44,"")) | D45: =IF(MAESTRO!B44="","",IFERROR(COUNTIF('Asistencia (7°)'!C42:BH42,"-")+COUNTIF('Asistencia (7°)'!C85:BH85,"-")+COUNTIF('Asistencia (7°)'!C128:BH128,"-"),"")) | E45: =IF(MAESTRO!B44="","",IFERROR(TRUNC(AVERAGE(IFERROR('PROM (Ingles 7°)'!AE44,""),IFERROR('PROM (Ingles 7°)'!BL44,""),IFERROR('PROM (Ingles 7°)'!CS44,""),IFERROR('PROM (Agropecuaria 7°)'!AE44,""),IFERROR('PROM (Agropecuaria 7°)'!BL44,""),IFERROR('PROM (Agropecuaria 7°)'!CT44,""),IFERROR('PROM (Hogar y Desarrollo 7°)'!AE44,""),IFERROR('PROM (Hogar y Desarrollo 7°)'!BM44,""),IFERROR('PROM (Hogar y Desarrollo 7°)'!CT44,"")),1),"")) | F45: =IF(MAESTRO!B44="","",IFERROR(COUNTBLANK('PROM (Ingles 7°)'!C44:O44),""))
A46: 8° | B46: 1 | C46: =IF(MAESTRO!D5="","",IFERROR(MAESTRO!D5,"")) | D46: =IF(MAESTRO!D5="","",IFERROR(COUNTIF('Asistencia (8°)'!C3:BH3,"-")+COUNTIF('Asistencia (8°)'!C46:BH46,"-")+COUNTIF('Asistencia (8°)'!C89:BH89,"-"),"")) | E46: =IF(MAESTRO!D5="","",IFERROR(TRUNC(AVERAGE(IFERROR('PROM (Ingles 8°)'!AE5,""),IFERROR('PROM (Ingles 8°)'!BL5,""),IFERROR('PROM (Ingles 8°)'!CT5,""),IFERROR('PROM (Agropecuaria 8°)'!AF5,""),IFERROR('PROM (Agropecuaria 8°)'!BM5,""),IFERROR('PROM (Agropecuaria 8°)'!CU5,""),IFERROR('PROM (Comercio 8°)'!AE5,""),IFERROR('PROM (Comercio 8°)'!BL5,""),IFERROR('PROM (Comercio 8°)'!CT5,"")),1),"")) | F46: =IF(MAESTRO!D5="","",IFERROR(COUNTBLANK('PROM (Ingles 8°)'!C5:O5),""))
A47: 8° | B47: 2 | C47: =IF(MAESTRO!D6="","",IFERROR(MAESTRO!D6,"")) | D47: =IF(MAESTRO!D6="","",IFERROR(COUNTIF('Asistencia (8°)'!C4:BH4,"-")+COUNTIF('Asistencia (8°)'!C47:BH47,"-")+COUNTIF('Asistencia (8°)'!C90:BH90,"-"),"")) | E47: =IF(MAESTRO!D6="","",IFERROR(TRUNC(AVERAGE(IFERROR('PROM (Ingles 8°)'!AE6,""),IFERROR('PROM (Ingles 8°)'!BL6,""),IFERROR('PROM (Ingles 8°)'!CT6,""),IFERROR('PROM (Agropecuaria 8°)'!AF6,""),IFERROR('PROM (Agropecuaria 8°)'!BM6,""),IFERROR('PROM (Agropecuaria 8°)'!CU6,""),IFERROR('PROM (Comercio 8°)'!AE6,""),IFERROR('PROM (Comercio 8°)'!BL6,""),IFERROR('PROM (Comercio 8°)'!CT6,"")),1),"")) | F47: =IF(MAESTRO!D6="","",IFERROR(COUNTBLANK('PROM (Ingles 8°)'!C6:O6),""))
A48: 8° | B48: 3 | C48: =IF(MAESTRO!D7="","",IFERROR(MAESTRO!D7,"")) | D48: =IF(MAESTRO!D7="","",IFERROR(COUNTIF('Asistencia (8°)'!C5:BH5,"-")+COUNTIF('Asistencia (8°)'!C48:BH48,"-")+COUNTIF('Asistencia (8°)'!C91:BH91,"-"),"")) | E48: =IF(MAESTRO!D7="","",IFERROR(TRUNC(AVERAGE(IFERROR('PROM (Ingles 8°)'!AE7,""),IFERROR('PROM (Ingles 8°)'!BL7,""),IFERROR('PROM (Ingles 8°)'!CT7,""),IFERROR('PROM (Agropecuaria 8°)'!AF7,""),IFERROR('PROM (Agropecuaria 8°)'!BM7,""),IFERROR('PROM (Agropecuaria 8°)'!CU7,""),IFERROR('PROM (Comercio 8°)'!AE7,""),IFERROR('PROM (Comercio 8°)'!BL7,""),IFERROR('PROM (Comercio 8°)'!CT7,"")),1),"")) | F48: =IF(MAESTRO!D7="","",IFERROR(COUNTBLANK('PROM (Ingles 8°)'!C7:O7),""))
A49: 8° | B49: 4 | C49: =IF(MAESTRO!D8="","",IFERROR(MAESTRO!D8,"")) | D49: =IF(MAESTRO!D8="","",IFERROR(COUNTIF('Asistencia (8°)'!C6:BH6,"-")+COUNTIF('Asistencia (8°)'!C49:BH49,"-")+COUNTIF('Asistencia (8°)'!C92:BH92,"-"),"")) | E49: =IF(MAESTRO!D8="","",IFERROR(TRUNC(AVERAGE(IFERROR('PROM (Ingles 8°)'!AE8,""),IFERROR('PROM (Ingles 8°)'!BL8,""),IFERROR('PROM (Ingles 8°)'!CT8,""),IFERROR('PROM (Agropecuaria 8°)'!AF8,""),IFERROR('PROM (Agropecuaria 8°)'!BM8,""),IFERROR('PROM (Agropecuaria 8°)'!CU8,""),IFERROR('PROM (Comercio 8°)'!AE8,""),IFERROR('PROM (Comercio 8°)'!BL8,""),IFERROR('PROM (Comercio 8°)'!CT8,"")),1),"")) | F49: =IF(MAESTRO!D8="","",IFERROR(COUNTBLANK('PROM (Ingles 8°)'!C8:O8),""))
A50: 8° | B50: 5 | C50: =IF(MAESTRO!D9="","",IFERROR(MAESTRO!D9,"")) | D50: =IF(MAESTRO!D9="","",IFERROR(COUNTIF('Asistencia (8°)'!C7:BH7,"-")+COUNTIF('Asistencia (8°)'!C50:BH50,"-")+COUNTIF('Asistencia (8°)'!C93:BH93,"-"),"")) | E50: =IF(MAESTRO!D9="","",IFERROR(TRUNC(AVERAGE(IFERROR('PROM (Ingles 8°)'!AE9,""),IFERROR('PROM (Ingles 8°)'!BL9,""),IFERROR('PROM (Ingles 8°)'!CT9,""),IFERROR('PROM (Agropecuaria 8°)'!AF9,""),IFERROR('PROM (Agropecuaria 8°)'!BM9,""),IFERROR('PROM (Agropecuaria 8°)'!CU9,""),IFERROR('PROM (Comercio 8°)'!AE9,""),IFERROR('PROM (Comercio 8°)'!BL9,""),IFERROR('PROM (Comercio 8°)'!CT9,"")),1),"")) | F50: =IF(MAESTRO!D9="","",IFERROR(COUNTBLANK('PROM (Ingles 8°)'!C9:O9),""))
A51: 8° | B51: 6 | C51: =IF(MAESTRO!D10="","",IFERROR(MAESTRO!D10,"")) | D51: =IF(MAESTRO!D10="","",IFERROR(COUNTIF('Asistencia (8°)'!C8:BH8,"-")+COUNTIF('Asistencia (8°)'!C51:BH51,"-")+COUNTIF('Asistencia (8°)'!C94:BH94,"-"),"")) | E51: =IF(MAESTRO!D10="","",IFERROR(TRUNC(AVERAGE(IFERROR('PROM (Ingles 8°)'!AE10,""),IFERROR('PROM (Ingles 8°)'!BL10,""),IFERROR('PROM (Ingles 8°)'!CT10,""),IFERROR('PROM (Agropecuaria 8°)'!AF10,""),IFERROR('PROM (Agropecuaria 8°)'!BM10,""),IFERROR('PROM (Agropecuaria 8°)'!CU10,""),IFERROR('PROM (Comercio 8°)'!AE10,""),IFERROR('PROM (Comercio 8°)'!BL10,""),IFERROR('PROM (Comercio 8°)'!CT10,"")),1),"")) | F51: =IF(MAESTRO!D10="","",IFERROR(COUNTBLANK('PROM (Ingles 8°)'!C10:O10),""))
A52: 8° | B52: 7 | C52: =IF(MAESTRO!D11="","",IFERROR(MAESTRO!D11,"")) | D52: =IF(MAESTRO!D11="","",IFERROR(COUNTIF('Asistencia (8°)'!C9:BH9,"-")+COUNTIF('Asistencia (8°)'!C52:BH52,"-")+COUNTIF('Asistencia (8°)'!C95:BH95,"-"),"")) | E52: =IF(MAESTRO!D11="","",IFERROR(TRUNC(AVERAGE(IFERROR('PROM (Ingles 8°)'!AE11,""),IFERROR('PROM (Ingles 8°)'!BL11,""),IFERROR('PROM (Ingles 8°)'!CT11,""),IFERROR('PROM (Agropecuaria 8°)'!AF11,""),IFERROR('PROM (Agropecuaria 8°)'!BM11,""),IFERROR('PROM (Agropecuaria 8°)'!CU11,""),IFERROR('PROM (Comercio 8°)'!AE11,""),IFERROR('PROM (Comercio 8°)'!BL11,""),IFERROR('PROM (Comercio 8°)'!CT11,"")),1),"")) | F52: =IF(MAESTRO!D11="","",IFERROR(COUNTBLANK('PROM (Ingles 8°)'!C11:O11),""))
A53: 8° | B53: 8 | C53: =IF(MAESTRO!D12="","",IFERROR(MAESTRO!D12,"")) | D53: =IF(MAESTRO!D12="","",IFERROR(COUNTIF('Asistencia (8°)'!C10:BH10,"-")+COUNTIF('Asistencia (8°)'!C53:BH53,"-")+COUNTIF('Asistencia (8°)'!C96:BH96,"-"),"")) | E53: =IF(MAESTRO!D12="","",IFERROR(TRUNC(AVERAGE(IFERROR('PROM (Ingles 8°)'!AE12,""),IFERROR('PROM (Ingles 8°)'!BL12,""),IFERROR('PROM (Ingles 8°)'!CT12,""),IFERROR('PROM (Agropecuaria 8°)'!AF12,""),IFERROR('PROM (Agropecuaria 8°)'!BM12,""),IFERROR('PROM (Agropecuaria 8°)'!CU12,""),IFERROR('PROM (Comercio 8°)'!AE12,""),IFERROR('PROM (Comercio 8°)'!BL12,""),IFERROR('PROM (Comercio 8°)'!CT12,"")),1),"")) | F53: =IF(MAESTRO!D12="","",IFERROR(COUNTBLANK('PROM (Ingles 8°)'!C12:O12),""))
A54: 8° | B54: 9 | C54: =IF(MAESTRO!D13="","",IFERROR(MAESTRO!D13,"")) | D54: =IF(MAESTRO!D13="","",IFERROR(COUNTIF('Asistencia (8°)'!C11:BH11,"-")+COUNTIF('Asistencia (8°)'!C54:BH54,"-")+COUNTIF('Asistencia (8°)'!C97:BH97,"-"),"")) | E54: =IF(MAESTRO!D13="","",IFERROR(TRUNC(AVERAGE(IFERROR('PROM (Ingles 8°)'!AE13,""),IFERROR('PROM (Ingles 8°)'!BL13,""),IFERROR('PROM (Ingles 8°)'!CT13,""),IFERROR('PROM (Agropecuaria 8°)'!AF13,""),IFERROR('PROM (Agropecuaria 8°)'!BM13,""),IFERROR('PROM (Agropecuaria 8°)'!CU13,""),IFERROR('PROM (Comercio 8°)'!AE13,""),IFERROR('PROM (Comercio 8°)'!BL13,""),IFERROR('PROM (Comercio 8°)'!CT13,"")),1),"")) | F54: =IF(MAESTRO!D13="","",IFERROR(COUNTBLANK('PROM (Ingles 8°)'!C13:O13),""))
A55: 8° | B55: 10 | C55: =IF(MAESTRO!D14="","",IFERROR(MAESTRO!D14,"")) | D55: =IF(MAESTRO!D14="","",IFERROR(COUNTIF('Asistencia (8°)'!C12:BH12,"-")+COUNTIF('Asistencia (8°)'!C55:BH55,"-")+COUNTIF('Asistencia (8°)'!C98:BH98,"-"),"")) | E55: =IF(MAESTRO!D14="","",IFERROR(TRUNC(AVERAGE(IFERROR('PROM (Ingles 8°)'!AE14,""),IFERROR('PROM (Ingles 8°)'!BL14,""),IFERROR('PROM (Ingles 8°)'!CT14,""),IFERROR('PROM (Agropecuaria 8°)'!AF14,""),IFERROR('PROM (Agropecuaria 8°)'!BM14,""),IFERROR('PROM (Agropecuaria 8°)'!CU14,""),IFERROR('PROM (Comercio 8°)'!AE14,""),IFERROR('PROM (Comercio 8°)'!BL14,""),IFERROR('PROM (Comercio 8°)'!CT14,"")),1),"")) | F55: =IF(MAESTRO!D14="","",IFERROR(COUNTBLANK('PROM (Ingles 8°)'!C14:O14),""))
A56: 8° | B56: 11 | C56: =IF(MAESTRO!D15="","",IFERROR(MAESTRO!D15,"")) | D56: =IF(MAESTRO!D15="","",IFERROR(COUNTIF('Asistencia (8°)'!C13:BH13,"-")+COUNTIF('Asistencia (8°)'!C56:BH56,"-")+COUNTIF('Asistencia (8°)'!C99:BH99,"-"),"")) | E56: =IF(MAESTRO!D15="","",IFERROR(TRUNC(AVERAGE(IFERROR('PROM (Ingles 8°)'!AE15,""),IFERROR('PROM (Ingles 8°)'!BL15,""),IFERROR('PROM (Ingles 8°)'!CT15,""),IFERROR('PROM (Agropecuaria 8°)'!AF15,""),IFERROR('PROM (Agropecuaria 8°)'!BM15,""),IFERROR('PROM (Agropecuaria 8°)'!CU15,""),IFERROR('PROM (Comercio 8°)'!AE15,""),IFERROR('PROM (Comercio 8°)'!BL15,""),IFERROR('PROM (Comercio 8°)'!CT15,"")),1),"")) | F56: =IF(MAESTRO!D15="","",IFERROR(COUNTBLANK('PROM (Ingles 8°)'!C15:O15),""))
A57: 8° | B57: 12 | C57: =IF(MAESTRO!D16="","",IFERROR(MAESTRO!D16,"")) | D57: =IF(MAESTRO!D16="","",IFERROR(COUNTIF('Asistencia (8°)'!C14:BH14,"-")+COUNTIF('Asistencia (8°)'!C57:BH57,"-")+COUNTIF('Asistencia (8°)'!C100:BH100,"-"),"")) | E57: =IF(MAESTRO!D16="","",IFERROR(TRUNC(AVERAGE(IFERROR('PROM (Ingles 8°)'!AE16,""),IFERROR('PROM (Ingles 8°)'!BL16,""),IFERROR('PROM (Ingles 8°)'!CT16,""),IFERROR('PROM (Agropecuaria 8°)'!AF16,""),IFERROR('PROM (Agropecuaria 8°)'!BM16,""),IFERROR('PROM (Agropecuaria 8°)'!CU16,""),IFERROR('PROM (Comercio 8°)'!AE16,""),IFERROR('PROM (Comercio 8°)'!BL16,""),IFERROR('PROM (Comercio 8°)'!CT16,"")),1),"")) | F57: =IF(MAESTRO!D16="","",IFERROR(COUNTBLANK('PROM (Ingles 8°)'!C16:O16),""))
... A85: 8° | B85: 40 | C85: =IF(MAESTRO!D44="","",IFERROR(MAESTRO!D44,"")) | D85: =IF(MAESTRO!D44="","",IFERROR(COUNTIF('Asistencia (8°)'!C42:BH42,"-")+COUNTIF('Asistencia (8°)'!C85:BH85,"-")+COUNTIF('Asistencia (8°)'!C128:BH128,"-"),"")) | E85: =IF(MAESTRO!D44="","",IFERROR(TRUNC(AVERAGE(IFERROR('PROM (Ingles 8°)'!AE44,""),IFERROR('PROM (Ingles 8°)'!BL44,""),IFERROR('PROM (Ingles 8°)'!CT44,""),IFERROR('PROM (Agropecuaria 8°)'!AF44,""),IFERROR('PROM (Agropecuaria 8°)'!BM44,""),IFERROR('PROM (Agropecuaria 8°)'!CU44,""),IFERROR('PROM (Comercio 8°)'!AE44,""),IFERROR('PROM (Comercio 8°)'!BL44,""),IFERROR('PROM (Comercio 8°)'!CT44,"")),1),"")) | F85: =IF(MAESTRO!D44="","",IFERROR(COUNTBLANK('PROM (Ingles 8°)'!C44:O44),""))
A86: 9° | B86: 1 | C86: =IF(MAESTRO!F5="","",IFERROR(MAESTRO!F5,"")) | D86: =IF(MAESTRO!F5="","",IFERROR(COUNTIF('Asistencia (9°)'!C3:BH3,"-")+COUNTIF('Asistencia (9°)'!C46:BH46,"-")+COUNTIF('Asistencia (9°)'!C89:BH89,"-"),"")) | E86: =IF(MAESTRO!F5="","",IFERROR(TRUNC(AVERAGE(IFERROR('PROM (Ingles 9°)'!AE5,""),IFERROR('PROM (Ingles 9°)'!BL5,""),IFERROR('PROM (Ingles 9°)'!CT5,""),IFERROR('PROM (Agropecuaria 9°)'!AE5,""),IFERROR('PROM (Agropecuaria 9°)'!BL5,""),IFERROR('PROM (Agropecuaria 9°)'!CT5,""),IFERROR('PROM (Comercio 9°)'!AE5,""),IFERROR('PROM (Comercio 9°)'!BL5,""),IFERROR('PROM (Comercio 9°)'!CT5,""),IFERROR('PROM (Artistica 9°)'!AE5,""),IFERROR('PROM (Artistica 9°)'!BL5,""),IFERROR('PROM (Artistica 9°)'!CT5,"")),1),"")) | F86: =IF(MAESTRO!F5="","",IFERROR(COUNTBLANK('PROM (Ingles 9°)'!C5:O5),""))
A87: 9° | B87: 2 | C87: =IF(MAESTRO!F6="","",IFERROR(MAESTRO!F6,"")) | D87: =IF(MAESTRO!F6="","",IFERROR(COUNTIF('Asistencia (9°)'!C4:BH4,"-")+COUNTIF('Asistencia (9°)'!C47:BH47,"-")+COUNTIF('Asistencia (9°)'!C90:BH90,"-"),"")) | E87: =IF(MAESTRO!F6="","",IFERROR(TRUNC(AVERAGE(IFERROR('PROM (Ingles 9°)'!AE6,""),IFERROR('PROM (Ingles 9°)'!BL6,""),IFERROR('PROM (Ingles 9°)'!CT6,""),IFERROR('PROM (Agropecuaria 9°)'!AE6,""),IFERROR('PROM (Agropecuaria 9°)'!BL6,""),IFERROR('PROM (Agropecuaria 9°)'!CT6,""),IFERROR('PROM (Comercio 9°)'!AE6,""),IFERROR('PROM (Comercio 9°)'!BL6,""),IFERROR('PROM (Comercio 9°)'!CT6,""),IFERROR('PROM (Artistica 9°)'!AE6,""),IFERROR('PROM (Artistica 9°)'!BL6,""),IFERROR('PROM (Artistica 9°)'!CT6,"")),1),"")) | F87: =IF(MAESTRO!F6="","",IFERROR(COUNTBLANK('PROM (Ingles 9°)'!C6:O6),""))
A88: 9° | B88: 3 | C88: =IF(MAESTRO!F7="","",IFERROR(MAESTRO!F7,"")) | D88: =IF(MAESTRO!F7="","",IFERROR(COUNTIF('Asistencia (9°)'!C5:BH5,"-")+COUNTIF('Asistencia (9°)'!C48:BH48,"-")+COUNTIF('Asistencia (9°)'!C91:BH91,"-"),"")) | E88: =IF(MAESTRO!F7="","",IFERROR(TRUNC(AVERAGE(IFERROR('PROM (Ingles 9°)'!AE7,""),IFERROR('PROM (Ingles 9°)'!BL7,""),IFERROR('PROM (Ingles 9°)'!CT7,""),IFERROR('PROM (Agropecuaria 9°)'!AE7,""),IFERROR('PROM (Agropecuaria 9°)'!BL7,""),IFERROR('PROM (Agropecuaria 9°)'!CT7,""),IFERROR('PROM (Comercio 9°)'!AE7,""),IFERROR('PROM (Comercio 9°)'!BL7,""),IFERROR('PROM (Comercio 9°)'!CT7,""),IFERROR('PROM (Artistica 9°)'!AE7,""),IFERROR('PROM (Artistica 9°)'!BL7,""),IFERROR('PROM (Artistica 9°)'!CT7,"")),1),"")) | F88: =IF(MAESTRO!F7="","",IFERROR(COUNTBLANK('PROM (Ingles 9°)'!C7:O7),""))
A89: 9° | B89: 4 | C89: =IF(MAESTRO!F8="","",IFERROR(MAESTRO!F8,"")) | D89: =IF(MAESTRO!F8="","",IFERROR(COUNTIF('Asistencia (9°)'!C6:BH6,"-")+COUNTIF('Asistencia (9°)'!C49:BH49,"-")+COUNTIF('Asistencia (9°)'!C92:BH92,"-"),"")) | E89: =IF(MAESTRO!F8="","",IFERROR(TRUNC(AVERAGE(IFERROR('PROM (Ingles 9°)'!AE8,""),IFERROR('PROM (Ingles 9°)'!BL8,""),IFERROR('PROM (Ingles 9°)'!CT8,""),IFERROR('PROM (Agropecuaria 9°)'!AE8,""),IFERROR('PROM (Agropecuaria 9°)'!BL8,""),IFERROR('PROM (Agropecuaria 9°)'!CT8,""),IFERROR('PROM (Comercio 9°)'!AE8,""),IFERROR('PROM (Comercio 9°)'!BL8,""),IFERROR('PROM (Comercio 9°)'!CT8,""),IFERROR('PROM (Artistica 9°)'!AE8,""),IFERROR('PROM (Artistica 9°)'!BL8,""),IFERROR('PROM (Artistica 9°)'!CT8,"")),1),"")) | F89: =IF(MAESTRO!F8="","",IFERROR(COUNTBLANK('PROM (Ingles 9°)'!C8:O8),""))
A90: 9° | B90: 5 | C90: =IF(MAESTRO!F9="","",IFERROR(MAESTRO!F9,"")) | D90: =IF(MAESTRO!F9="","",IFERROR(COUNTIF('Asistencia (9°)'!C7:BH7,"-")+COUNTIF('Asistencia (9°)'!C50:BH50,"-")+COUNTIF('Asistencia (9°)'!C93:BH93,"-"),"")) | E90: =IF(MAESTRO!F9="","",IFERROR(TRUNC(AVERAGE(IFERROR('PROM (Ingles 9°)'!AE9,""),IFERROR('PROM (Ingles 9°)'!BL9,""),IFERROR('PROM (Ingles 9°)'!CT9,""),IFERROR('PROM (Agropecuaria 9°)'!AE9,""),IFERROR('PROM (Agropecuaria 9°)'!BL9,""),IFERROR('PROM (Agropecuaria 9°)'!CT9,""),IFERROR('PROM (Comercio 9°)'!AE9,""),IFERROR('PROM (Comercio 9°)'!BL9,""),IFERROR('PROM (Comercio 9°)'!CT9,""),IFERROR('PROM (Artistica 9°)'!AE9,""),IFERROR('PROM (Artistica 9°)'!BL9,""),IFERROR('PROM (Artistica 9°)'!CT9,"")),1),"")) | F90: =IF(MAESTRO!F9="","",IFERROR(COUNTBLANK('PROM (Ingles 9°)'!C9:O9),""))
A91: 9° | B91: 6 | C91: =IF(MAESTRO!F10="","",IFERROR(MAESTRO!F10,"")) | D91: =IF(MAESTRO!F10="","",IFERROR(COUNTIF('Asistencia (9°)'!C8:BH8,"-")+COUNTIF('Asistencia (9°)'!C51:BH51,"-")+COUNTIF('Asistencia (9°)'!C94:BH94,"-"),"")) | E91: =IF(MAESTRO!F10="","",IFERROR(TRUNC(AVERAGE(IFERROR('PROM (Ingles 9°)'!AE10,""),IFERROR('PROM (Ingles 9°)'!BL10,""),IFERROR('PROM (Ingles 9°)'!CT10,""),IFERROR('PROM (Agropecuaria 9°)'!AE10,""),IFERROR('PROM (Agropecuaria 9°)'!BL10,""),IFERROR('PROM (Agropecuaria 9°)'!CT10,""),IFERROR('PROM (Comercio 9°)'!AE10,""),IFERROR('PROM (Comercio 9°)'!BL10,""),IFERROR('PROM (Comercio 9°)'!CT10,""),IFERROR('PROM (Artistica 9°)'!AE10,""),IFERROR('PROM (Artistica 9°)'!BL10,""),IFERROR('PROM (Artistica 9°)'!CT10,"")),1),"")) | F91: =IF(MAESTRO!F10="","",IFERROR(COUNTBLANK('PROM (Ingles 9°)'!C10:O10),""))
A92: 9° | B92: 7 | C92: =IF(MAESTRO!F11="","",IFERROR(MAESTRO!F11,"")) | D92: =IF(MAESTRO!F11="","",IFERROR(COUNTIF('Asistencia (9°)'!C9:BH9,"-")+COUNTIF('Asistencia (9°)'!C52:BH52,"-")+COUNTIF('Asistencia (9°)'!C95:BH95,"-"),"")) | E92: =IF(MAESTRO!F11="","",IFERROR(TRUNC(AVERAGE(IFERROR('PROM (Ingles 9°)'!AE11,""),IFERROR('PROM (Ingles 9°)'!BL11,""),IFERROR('PROM (Ingles 9°)'!CT11,""),IFERROR('PROM (Agropecuaria 9°)'!AE11,""),IFERROR('PROM (Agropecuaria 9°)'!BL11,""),IFERROR('PROM (Agropecuaria 9°)'!CT11,""),IFERROR('PROM (Comercio 9°)'!AE11,""),IFERROR('PROM (Comercio 9°)'!BL11,""),IFERROR('PROM (Comercio 9°)'!CT11,""),IFERROR('PROM (Artistica 9°)'!AE11,""),IFERROR('PROM (Artistica 9°)'!BL11,""),IFERROR('PROM (Artistica 9°)'!CT11,"")),1),"")) | F92: =IF(MAESTRO!F11="","",IFERROR(COUNTBLANK('PROM (Ingles 9°)'!C11:O11),""))
A93: 9° | B93: 8 | C93: =IF(MAESTRO!F12="","",IFERROR(MAESTRO!F12,"")) | D93: =IF(MAESTRO!F12="","",IFERROR(COUNTIF('Asistencia (9°)'!C10:BH10,"-")+COUNTIF('Asistencia (9°)'!C53:BH53,"-")+COUNTIF('Asistencia (9°)'!C96:BH96,"-"),"")) | E93: =IF(MAESTRO!F12="","",IFERROR(TRUNC(AVERAGE(IFERROR('PROM (Ingles 9°)'!AE12,""),IFERROR('PROM (Ingles 9°)'!BL12,""),IFERROR('PROM (Ingles 9°)'!CT12,""),IFERROR('PROM (Agropecuaria 9°)'!AE12,""),IFERROR('PROM (Agropecuaria 9°)'!BL12,""),IFERROR('PROM (Agropecuaria 9°)'!CT12,""),IFERROR('PROM (Comercio 9°)'!AE12,""),IFERROR('PROM (Comercio 9°)'!BL12,""),IFERROR('PROM (Comercio 9°)'!CT12,""),IFERROR('PROM (Artistica 9°)'!AE12,""),IFERROR('PROM (Artistica 9°)'!BL12,""),IFERROR('PROM (Artistica 9°)'!CT12,"")),1),"")) | F93: =IF(MAESTRO!F12="","",IFERROR(COUNTBLANK('PROM (Ingles 9°)'!C12:O12),""))
...

Sheet RESUMEN_7°
A1: CUADRO DE NOTAS FINALES — 7° GRADO · ESCUELA CERRO CACICÓN 2026
A2: Nota: Las calificaciones se obtienen automáticamente de las hojas PROM de cada materia
A3: No. | B3: APELLIDO, NOMBRE | C3: INGLÉS | G3: AGROPECUARIA | K3: HOGAR Y DESARROLLO | O3: TECNOLOGÍA | S3: ESTADO
C4: T1 | D4: T2 | E4: T3 | F4: FINAL | G4: T1 | H4: T2 | I4: T3 | J4: FINAL | K4: T1 | L4: T2 | M4: T3 | N4: FINAL | O4: T1 | P4: T2 | Q4: T3 | R4: FINAL
A5: 1 | B5: =IF(MAESTRO!B5="","",MAESTRO!B5) | C5: =IF(MAESTRO!B5="","",IFERROR('Planilla (Ingles 7°) '!F16,"")) | D5: =IF(MAESTRO!B5="","",IFERROR('Planilla (Ingles 7°) '!G16,"")) | E5: =IF(MAESTRO!B5="","",IFERROR('Planilla (Ingles 7°) '!H16,"")) | F5: =IF(MAESTRO!B5="","",IFERROR('Planilla (Ingles 7°) '!I16,"")) | G5: =IF(MAESTRO!B5="","",IFERROR('Planilla (Agropecuaria 7°)'!F16,"")) | H5: =IF(MAESTRO!B5="","",IFERROR('Planilla (Agropecuaria 7°)'!G16,"")) | I5: =IF(MAESTRO!B5="","",IFERROR('Planilla (Agropecuaria 7°)'!H16,"")) | J5: =IF(MAESTRO!B5="","",IFERROR('Planilla (Agropecuaria 7°)'!I16,"")) | K5: =IF(MAESTRO!B5="","",IFERROR('Planilla (Hogar y Desarrollo 7)'!F16,"")) | L5: =IF(MAESTRO!B5="","",IFERROR('Planilla (Hogar y Desarrollo 7)'!G16,"")) | M5: =IF(MAESTRO!B5="","",IFERROR('Planilla (Hogar y Desarrollo 7)'!H16,"")) | N5: =IF(MAESTRO!B5="","",IFERROR('Planilla (Hogar y Desarrollo 7)'!I16,"")) | O5: =IF(MAESTRO!B5="","",IFERROR(AVERAGE(G5,K5),"")) | P5: =IF(MAESTRO!B5="","",IFERROR(AVERAGE(H5,L5),"")) | Q5: =IF(MAESTRO!B5="","",IFERROR(AVERAGE(I5,M5),"")) | R5: =IF(MAESTRO!B5="","",IFERROR(TRUNC(AVERAGE(O5,P5,Q5),1),"")) | S5: =IF(MAESTRO!B5="","",IF(AND(F5="",J5="",N5="",R5=""),"",IF(AND(OR(F5="",F5>=3),OR(J5="",J5>=3),OR(N5="",N5>=3),OR(R5="",R5>=3)),"✓ APROBADO","✗ REPROBADO")))
A6: 2 | B6: =IF(MAESTRO!B6="","",MAESTRO!B6) | C6: =IF(MAESTRO!B6="","",IFERROR('Planilla (Ingles 7°) '!F17,"")) | D6: =IF(MAESTRO!B6="","",IFERROR('Planilla (Ingles 7°) '!G17,"")) | E6: =IF(MAESTRO!B6="","",IFERROR('Planilla (Ingles 7°) '!H17,"")) | F6: =IF(MAESTRO!B6="","",IFERROR('Planilla (Ingles 7°) '!I17,"")) | G6: =IF(MAESTRO!B6="","",IFERROR('Planilla (Agropecuaria 7°)'!F17,"")) | H6: =IF(MAESTRO!B6="","",IFERROR('Planilla (Agropecuaria 7°)'!G17,"")) | I6: =IF(MAESTRO!B6="","",IFERROR('Planilla (Agropecuaria 7°)'!H17,"")) | J6: =IF(MAESTRO!B6="","",IFERROR('Planilla (Agropecuaria 7°)'!I17,"")) | K6: =IF(MAESTRO!B6="","",IFERROR('Planilla (Hogar y Desarrollo 7)'!F17,"")) | L6: =IF(MAESTRO!B6="","",IFERROR('Planilla (Hogar y Desarrollo 7)'!G17,"")) | M6: =IF(MAESTRO!B6="","",IFERROR('Planilla (Hogar y Desarrollo 7)'!H17,"")) | N6: =IF(MAESTRO!B6="","",IFERROR('Planilla (Hogar y Desarrollo 7)'!I17,"")) | O6: =IF(MAESTRO!B6="","",IFERROR(AVERAGE(G6,K6),"")) | P6: =IF(MAESTRO!B6="","",IFERROR(AVERAGE(H6,L6),"")) | Q6: =IF(MAESTRO!B6="","",IFERROR(AVERAGE(I6,M6),"")) | R6: =IF(MAESTRO!B6="","",IFERROR(TRUNC(AVERAGE(O6,P6,Q6),1),"")) | S6: =IF(MAESTRO!B6="","",IF(AND(F6="",J6="",N6="",R6=""),"",IF(AND(OR(F6="",F6>=3),OR(J6="",J6>=3),OR(N6="",N6>=3),OR(R6="",R6>=3)),"✓ APROBADO","✗ REPROBADO")))
A7: 3 | B7: =IF(MAESTRO!B7="","",MAESTRO!B7) | C7: =IF(MAESTRO!B7="","",IFERROR('Planilla (Ingles 7°) '!F18,"")) | D7: =IF(MAESTRO!B7="","",IFERROR('Planilla (Ingles 7°) '!G18,"")) | E7: =IF(MAESTRO!B7="","",IFERROR('Planilla (Ingles 7°) '!H18,"")) | F7: =IF(MAESTRO!B7="","",IFERROR('Planilla (Ingles 7°) '!I18,"")) | G7: =IF(MAESTRO!B7="","",IFERROR('Planilla (Agropecuaria 7°)'!F18,"")) | H7: =IF(MAESTRO!B7="","",IFERROR('Planilla (Agropecuaria 7°)'!G18,"")) | I7: =IF(MAESTRO!B7="","",IFERROR('Planilla (Agropecuaria 7°)'!H18,"")) | J7: =IF(MAESTRO!B7="","",IFERROR('Planilla (Agropecuaria 7°)'!I18,"")) | K7: =IF(MAESTRO!B7="","",IFERROR('Planilla (Hogar y Desarrollo 7)'!F18,"")) | L7: =IF(MAESTRO!B7="","",IFERROR('Planilla (Hogar y Desarrollo 7)'!G18,"")) | M7: =IF(MAESTRO!B7="","",IFERROR('Planilla (Hogar y Desarrollo 7)'!H18,"")) | N7: =IF(MAESTRO!B7="","",IFERROR('Planilla (Hogar y Desarrollo 7)'!I18,"")) | O7: =IF(MAESTRO!B7="","",IFERROR(AVERAGE(G7,K7),"")) | P7: =IF(MAESTRO!B7="","",IFERROR(AVERAGE(H7,L7),"")) | Q7: =IF(MAESTRO!B7="","",IFERROR(AVERAGE(I7,M7),"")) | R7: =IF(MAESTRO!B7="","",IFERROR(TRUNC(AVERAGE(O7,P7,Q7),1),"")) | S7: =IF(MAESTRO!B7="","",IF(AND(F7="",J7="",N7="",R7=""),"",IF(AND(OR(F7="",F7>=3),OR(J7="",J7>=3),OR(N7="",N7>=3),OR(R7="",R7>=3)),"✓ APROBADO","✗ REPROBADO")))
