Workbook

Sheet Caratula
A15: Registro de Asistencia
A16: y Evaluación
A17: para Docentes de Centros
A18: Educativos Oficiales
Q23: Maestro Elmer Tugri
Q24: Maestro de Grado
Q25: Grupo: 1°

Sheet Portada
A4: REGISTRO DE ASISTENCIA Y EVALUACIÓN
A5: PARA PROFESORES DE LOS CENTROS
A6: EDUCATIVOS OFICIALES
A8: Año lectivo: | P8: 2026
A10: Grado:
A12: Área Curricular: | O12: PREMEDIA MULTIGRADO
A14: Nombre del Docente: | P14: Elmer Tugri
A16: N° de Cédula: | H16: 4-785-823 | V16: N° S. S. | AI16: N° de Pos.:
A18: Condición de Nombramiento: | U18: Instructor Vocacional
A20: Jornada: | H20: Matutina | X20: Asignatura: | AD20: Tecnología - Expresiones Artísticas - Ingles
A22: Nombre del Director(ar): | S22: Mardel Camarena
A24: Nombre del Subdirector(ar): | T24: Jairo Marciaga
A26: Nombre del Coordinador:
A28: Centro Educativo: | Q28: Escuela Cerro Cacicon
A30: Teléfono: | F30: 64185780 | U30: Correo Electrónico: | AF30: elmer.tugri7@meduca.edu.pa
A32: Regional: | M32: Comarca Ngabe Bugle
A34: Distrito de: | L34: MÜNA
A36: Corregimiento de: | Q36: MARACA
A38: Zona Escolar: | O38: 31

Sheet Horarios
I2: Profesor:
C4: Jornada:
C6: Asignatura:
C8: Grados:
D10: PERIODO | J10: HORAS | O10: LUNES | P10: MARTES | Q10: MIERCOLES | R10: JUEVES | S10: VIERNES
D11: I
D12: II
D13: III
D14: IV
D15: RECESO ACADÉMICO
D16: V
D17: VI
D18: VII
D19: VIII

Sheet Guía del Registro
A1: GUÍA PARA EL CORRECTO MANEJO DEL REGISTRO ESCOLAR | C1: . Debe anotarse toda la información relacionada con el nombre y apellido.
C2: . En caso de retiros, no se debe tachar el nombre, sino hacer la correspondiente anotación en el espacio previsto para ello al final de cada grupo.
A3: La libreta de Registro Escolar es propiedad del Estado. Sin embargo, la docente y el docente la utilizan durante el periodo lectivo para llevar un control de las actividades que realiza con sus estudiantes. Este documento recoge toda la información sobre la asistencia, rendimiento académico, comportamiento, etc., de los estudiantes.
C5: . En la sección para observaciones, debe aparecer el nombre de la profesora o del profesor consejero así como el grupo de consejería a que pertenece la estudiante o el estudiante.
C7: SIMBOLOGÍA RECOMENDADA
C9: El registro o control de la asistencia tiene una trascendental importancia con los diferentes aspectos que debe manejar el docente para dar respuesta a las solicitudes que se formulen en torno a sus estudiantes. El profesor y la profesora deberán:
A10: Para asegurar el correcto reistro, tanto de la asistencia como las calificaciones, el docente debe guiarse por el nombre del estudiante como por el número de casilla que le corresponde.
A15: Al finalizar el año lectivo, todos los docentes deben devolver el Registro Escolar a la Dirección del Plantel. | C15: 1. Registrar la asistencia diariamente, anotando la fecha correspondiente (día: número arábigo; mes: número arabigo). Utilizar la siguiente simbología:
A18: Esperamos que los señalamientos aquí presentados sean considerados por los docentes quienes oportunamente deberán presentar opiniones o nuevas ideas relacionadas con el manejo del Registro Escolar. | C18: a. Asistencia: un punto (.)
C19: b. Ausencia: una raya horizontal (-)
C20: c. Ausencia justificada (excusa): la letra mayúscula €
C21: d. Tardanza: La letra mayúscula (T)
C22: e. Fuga: la letra (F)
A23: PRESENTACIÓN | C23: f. Sin nota: las letras (S/N)
C24: g. Sin profesor: las letras (S/P)
A25: El Registro Escolar refleja la personalidad de la docente o del docente, por lo tanto, se debe tener especial cuidado con su aspecto físico. | C25: h. Alumno retirado: La letra (R) mayúscula.
C27: CONSIDERACIONES FINALES
A29: En cuanto a su presentación se tendrá en cuenta lo siguiente:
C30: El registro de notas o calificaciones es importante por su trascendencia en la determinación cuantitativa y cualitativa del aprovechamiento escolar. Por eso debemos:
A32: 1. Debe estar forrado con sobriedad; si es posible, encuadernado o empastado.
A34: 2. La información se anotará con tinta sin exagerar el uso de los colores.
C35: . Utilizar la escala numérica de 1 a 5 (incluye decimales con números arábigos).
A36: 3. Al escribir en él puede usar la letra de imprenta o cursiva legible.
C37: . Recordar que el cero (0) no existe dentro de esta escala.
A38: 4. Debe conservarse en forma nítida, sin manchas, sin borrones y sin tachaduras.
C39: . No utilizar ganchos, equis ni otros símbolos.
A40: 5. La libreta no debe contener información ajena a sus propósitos. | C40: . Registrar las notas con tinta, sin borrones ni tachaduras. Evitar escribir un número sobre otro.
C42: . Se debe registrar según la carga horaria, un mínimo de pruebas y actividades.
A43: CONFECCIÓN DEL LISTADO DE LAS ESTUDIANTES Y LOS ESTUDIANTES.
C44: . Debemos recordar que el trabajo en la libreta debe ser exacto, completo, claro y legible.
A46: . El listado debe hacerse por apellidos, en orden alfabético, sin distinción de género.
A47: Según el Resuelto No.1840 de 1 de noviembre de 2000.

Sheet Observaciones
A4: OBSERVACIONES

Sheet MAESTRO
A1: HOJA MAESTRO — ESCUELA CERRO CACICÓN · AÑO LECTIVO 2026
A2: Ingresa aquí los nombres de cada grado. Se copiarán automáticamente a TODAS las hojas.
A3: 1° GRADO
A4: No. | B4: APELLIDO, NOMBRE | E4: CEDULA
A5: 1
A6: 2
A7: 3
A8: 4
A9: 5
A10: 6
A11: 7
A12: 8
A13: 9
A14: 10
A15: 11
A16: 12
... A38: 34
A40: ⚠ IMPORTANTE: Solo edita esta hoja para nombres. Todas las demás hojas se actualizan automáticamente.

Sheet RESUMEN
A1: CUADRO DE NOTAS FINALES — ___ ° GRADO · ESCUELA _______________ 202_ | N1: CUADRO DE NOTAS FINALES — ___ ° GRADO · ESCUELA _______________ 202_
A2: Nota: PRIMER TRIMESTRE | N2: Nota: ANUAL
A3: No. | B3: APELLIDO, NOMBRE | C3: INGLES | D3: ESPAÑOL | E3: Matemática | F3: C.SOCIALES | G3: C.NATURALES | H3: Religión | I3: Artística | J3: TECNOLOGIA | K3: E. FISICA | L3: ESTADO | N3: No. | O3: APELLIDO, NOMBRE | P3: INGLES | Q3: ESPAÑOL | R3: Matemática | S3: C.SOCIALES | T3: C.NATURALES | U3: Religión | V3: Artística | W3: TECNOLOGIA | X3: E. FISICA | Y3: ESTADO
C4: FINAL | D4: FINAL | E4: FINAL | F4: FINAL | G4: FINAL | H4: FINAL | I4: FINAL | J4: FINAL | K4: FINAL | P4: FINAL | Q4: FINAL | R4: FINAL | S4: FINAL | T4: FINAL | U4: FINAL | V4: FINAL | W4: FINAL | X4: FINAL
A5: 1 | B5: =IF(MAESTRO!B5="","",MAESTRO!B5) | C5: =IF(MAESTRO!F5="","",IFERROR('Planilla (Ingles) '!F16,"")) | D5: =IF(MAESTRO!I5="","",IFERROR('Planilla (Español)'!F16,"")) | E5: =IF(MAESTRO!M5="","",IFERROR('Planilla (Matematica)'!F16,"")) | F5: =IF(MAESTRO!Q5="","",IFERROR('Planilla (C. Sociales)'!F16,"")) | G5: =IF(MAESTRO!B5="","",IFERROR('Planilla (C. Naturales)'!F16,"")) | H5: =IF(MAESTRO!F5="","",IFERROR('Planilla (Religión)'!F16,"")) | I5: =IF(MAESTRO!B5="","",IFERROR('Planilla (E. Artisticas)'!F16,"")) | J5: =IF(MAESTRO!M5="","",IFERROR('Planilla (Tecnologia)'!F16,"")) | K5: =IF(MAESTRO!N5="","",IFERROR('Planilla (E. Fisica)'!F16,"")) | N5: 1 | O5: =IF(MAESTRO!O5="","",MAESTRO!O5) | P5: =IF(MAESTRO!S5="","",IFERROR('Planilla (Ingles) '!I16,"")) | Q5: =IF(MAESTRO!V5="","",IFERROR('Planilla (Español)'!I16,"")) | R5: =IF(MAESTRO!Z5="","",IFERROR('Planilla (Matematica)'!I16,"")) | S5: =IF(MAESTRO!AD5="","",IFERROR('Planilla (C. Sociales)'!I16,"")) | T5: =IF(MAESTRO!O5="","",IFERROR('Planilla (C. Naturales)'!I16,"")) | U5: =IF(MAESTRO!S5="","",IFERROR('Planilla (Religión)'!I16,"")) | V5: =IF(MAESTRO!O5="","",IFERROR('Planilla (E. Artisticas)'!I16,"")) | W5: =IF(MAESTRO!Z5="","",IFERROR('Planilla (Tecnologia)'!I16,"")) | X5: =IF(MAESTRO!AA5="","",IFERROR('Planilla (E. Fisica)'!I16,""))
A6: 2 | B6: =IF(MAESTRO!B6="","",MAESTRO!B6) | C6: =IF(MAESTRO!F6="","",IFERROR('Planilla (Ingles) '!F17,"")) | D6: =IF(MAESTRO!I6="","",IFERROR('Planilla (Español)'!F17,"")) | E6: =IF(MAESTRO!M6="","",IFERROR('Planilla (Matematica)'!F17,"")) | F6: =IF(MAESTRO!Q6="","",IFERROR('Planilla (C. Sociales)'!F17,"")) | G6: =IF(MAESTRO!B6="","",IFERROR('Planilla (C. Naturales)'!F17,"")) | H6: =IF(MAESTRO!F6="","",IFERROR('Planilla (Religión)'!F17,"")) | I6: =IF(MAESTRO!B6="","",IFERROR('Planilla (E. Artisticas)'!F17,"")) | J6: =IF(MAESTRO!M6="","",IFERROR('Planilla (Tecnologia)'!F17,"")) | K6: =IF(MAESTRO!N6="","",IFERROR('Planilla (E. Fisica)'!F17,"")) | N6: 2 | O6: =IF(MAESTRO!O6="","",MAESTRO!O6) | P6: =IF(MAESTRO!S6="","",IFERROR('Planilla (Ingles) '!I17,"")) | Q6: =IF(MAESTRO!V6="","",IFERROR('Planilla (Español)'!I17,"")) | R6: =IF(MAESTRO!Z6="","",IFERROR('Planilla (Matematica)'!I17,"")) | S6: =IF(MAESTRO!AD6="","",IFERROR('Planilla (C. Sociales)'!I17,"")) | T6: =IF(MAESTRO!O6="","",IFERROR('Planilla (C. Naturales)'!I17,"")) | U6: =IF(MAESTRO!S6="","",IFERROR('Planilla (Religión)'!I17,"")) | V6: =IF(MAESTRO!O6="","",IFERROR('Planilla (E. Artisticas)'!I17,"")) | W6: =IF(MAESTRO!Z6="","",IFERROR('Planilla (Tecnologia)'!I17,"")) | X6: =IF(MAESTRO!AA6="","",IFERROR('Planilla (E. Fisica)'!I17,""))
A7: 3 | B7: =IF(MAESTRO!B7="","",MAESTRO!B7) | C7: =IF(MAESTRO!F7="","",IFERROR('Planilla (Ingles) '!F18,"")) | D7: =IF(MAESTRO!I7="","",IFERROR('Planilla (Español)'!F18,"")) | E7: =IF(MAESTRO!M7="","",IFERROR('Planilla (Matematica)'!F18,"")) | F7: =IF(MAESTRO!Q7="","",IFERROR('Planilla (C. Sociales)'!F18,"")) | G7: =IF(MAESTRO!B7="","",IFERROR('Planilla (C. Naturales)'!F18,"")) | H7: =IF(MAESTRO!F7="","",IFERROR('Planilla (Religión)'!F18,"")) | I7: =IF(MAESTRO!B7="","",IFERROR('Planilla (E. Artisticas)'!F18,"")) | J7: =IF(MAESTRO!M7="","",IFERROR('Planilla (Tecnologia)'!F18,"")) | K7: =IF(MAESTRO!N7="","",IFERROR('Planilla (E. Fisica)'!F18,"")) | N7: 3 | O7: =IF(MAESTRO!O7="","",MAESTRO!O7) | P7: =IF(MAESTRO!S7="","",IFERROR('Planilla (Ingles) '!I18,"")) | Q7: =IF(MAESTRO!V7="","",IFERROR('Planilla (Español)'!I18,"")) | R7: =IF(MAESTRO!Z7="","",IFERROR('Planilla (Matematica)'!I18,"")) | S7: =IF(MAESTRO!AD7="","",IFERROR('Planilla (C. Sociales)'!I18,"")) | T7: =IF(MAESTRO!O7="","",IFERROR('Planilla (C. Naturales)'!I18,"")) | U7: =IF(MAESTRO!S7="","",IFERROR('Planilla (Religión)'!I18,"")) | V7: =IF(MAESTRO!O7="","",IFERROR('Planilla (E. Artisticas)'!I18,"")) | W7: =IF(MAESTRO!Z7="","",IFERROR('Planilla (Tecnologia)'!I18,"")) | X7: =IF(MAESTRO!AA7="","",IFERROR('Planilla (E. Fisica)'!I18,""))
A8: 4 | B8: =IF(MAESTRO!B8="","",MAESTRO!B8) | C8: =IF(MAESTRO!F8="","",IFERROR('Planilla (Ingles) '!F19,"")) | D8: =IF(MAESTRO!I8="","",IFERROR('Planilla (Español)'!F19,"")) | E8: =IF(MAESTRO!M8="","",IFERROR('Planilla (Matematica)'!F19,"")) | F8: =IF(MAESTRO!Q8="","",IFERROR('Planilla (C. Sociales)'!F19,"")) | G8: =IF(MAESTRO!B8="","",IFERROR('Planilla (C. Naturales)'!F19,"")) | H8: =IF(MAESTRO!F8="","",IFERROR('Planilla (Religión)'!F19,"")) | I8: =IF(MAESTRO!B8="","",IFERROR('Planilla (E. Artisticas)'!F19,"")) | J8: =IF(MAESTRO!M8="","",IFERROR('Planilla (Tecnologia)'!F19,"")) | K8: =IF(MAESTRO!N8="","",IFERROR('Planilla (E. Fisica)'!F19,"")) | N8: 4 | O8: =IF(MAESTRO!O8="","",MAESTRO!O8) | P8: =IF(MAESTRO!S8="","",IFERROR('Planilla (Ingles) '!I19,"")) | Q8: =IF(MAESTRO!V8="","",IFERROR('Planilla (Español)'!I19,"")) | R8: =IF(MAESTRO!Z8="","",IFERROR('Planilla (Matematica)'!I19,"")) | S8: =IF(MAESTRO!AD8="","",IFERROR('Planilla (C. Sociales)'!I19,"")) | T8: =IF(MAESTRO!O8="","",IFERROR('Planilla (C. Naturales)'!I19,"")) | U8: =IF(MAESTRO!S8="","",IFERROR('Planilla (Religión)'!I19,"")) | V8: =IF(MAESTRO!O8="","",IFERROR('Planilla (E. Artisticas)'!I19,"")) | W8: =IF(MAESTRO!Z8="","",IFERROR('Planilla (Tecnologia)'!I19,"")) | X8: =IF(MAESTRO!AA8="","",IFERROR('Planilla (E. Fisica)'!I19,""))
A9: 5 | B9: =IF(MAESTRO!B9="","",MAESTRO!B9) | C9: =IF(MAESTRO!F9="","",IFERROR('Planilla (Ingles) '!F20,"")) | D9: =IF(MAESTRO!I9="","",IFERROR('Planilla (Español)'!F20,"")) | E9: =IF(MAESTRO!M9="","",IFERROR('Planilla (Matematica)'!F20,"")) | F9: =IF(MAESTRO!Q9="","",IFERROR('Planilla (C. Sociales)'!F20,"")) | G9: =IF(MAESTRO!B9="","",IFERROR('Planilla (C. Naturales)'!F20,"")) | H9: =IF(MAESTRO!F9="","",IFERROR('Planilla (Religión)'!F20,"")) | I9: =IF(MAESTRO!B9="","",IFERROR('Planilla (E. Artisticas)'!F20,"")) | J9: =IF(MAESTRO!M9="","",IFERROR('Planilla (Tecnologia)'!F20,"")) | K9: =IF(MAESTRO!N9="","",IFERROR('Planilla (E. Fisica)'!F20,"")) | N9: 5 | O9: =IF(MAESTRO!O9="","",MAESTRO!O9) | P9: =IF(MAESTRO!S9="","",IFERROR('Planilla (Ingles) '!I20,"")) | Q9: =IF(MAESTRO!V9="","",IFERROR('Planilla (Español)'!I20,"")) | R9: =IF(MAESTRO!Z9="","",IFERROR('Planilla (Matematica)'!I20,"")) | S9: =IF(MAESTRO!AD9="","",IFERROR('Planilla (C. Sociales)'!I20,"")) | T9: =IF(MAESTRO!O9="","",IFERROR('Planilla (C. Naturales)'!I20,"")) | U9: =IF(MAESTRO!S9="","",IFERROR('Planilla (Religión)'!I20,"")) | V9: =IF(MAESTRO!O9="","",IFERROR('Planilla (E. Artisticas)'!I20,"")) | W9: =IF(MAESTRO!Z9="","",IFERROR('Planilla (Tecnologia)'!I20,"")) | X9: =IF(MAESTRO!AA9="","",IFERROR('Planilla (E. Fisica)'!I20,""))
A10: 6 | B10: =IF(MAESTRO!B10="","",MAESTRO!B10) | C10: =IF(MAESTRO!F10="","",IFERROR('Planilla (Ingles) '!F21,"")) | D10: =IF(MAESTRO!I10="","",IFERROR('Planilla (Español)'!F21,"")) | E10: =IF(MAESTRO!M10="","",IFERROR('Planilla (Matematica)'!F21,"")) | F10: =IF(MAESTRO!Q10="","",IFERROR('Planilla (C. Sociales)'!F21,"")) | G10: =IF(MAESTRO!B10="","",IFERROR('Planilla (C. Naturales)'!F21,"")) | H10: =IF(MAESTRO!F10="","",IFERROR('Planilla (Religión)'!F21,"")) | I10: =IF(MAESTRO!B10="","",IFERROR('Planilla (E. Artisticas)'!F21,"")) | J10: =IF(MAESTRO!M10="","",IFERROR('Planilla (Tecnologia)'!F21,"")) | K10: =IF(MAESTRO!N10="","",IFERROR('Planilla (E. Fisica)'!F21,"")) | N10: 6 | O10: =IF(MAESTRO!O10="","",MAESTRO!O10) | P10: =IF(MAESTRO!S10="","",IFERROR('Planilla (Ingles) '!I21,"")) | Q10: =IF(MAESTRO!V10="","",IFERROR('Planilla (Español)'!I21,"")) | R10: =IF(MAESTRO!Z10="","",IFERROR('Planilla (Matematica)'!I21,"")) | S10: =IF(MAESTRO!AD10="","",IFERROR('Planilla (C. Sociales)'!I21,"")) | T10: =IF(MAESTRO!O10="","",IFERROR('Planilla (C. Naturales)'!I21,"")) | U10: =IF(MAESTRO!S10="","",IFERROR('Planilla (Religión)'!I21,"")) | V10: =IF(MAESTRO!O10="","",IFERROR('Planilla (E. Artisticas)'!I21,"")) | W10: =IF(MAESTRO!Z10="","",IFERROR('Planilla (Tecnologia)'!I21,"")) | X10: =IF(MAESTRO!AA10="","",IFERROR('Planilla (E. Fisica)'!I21,""))
A11: 7 | B11: =IF(MAESTRO!B11="","",MAESTRO!B11) | C11: =IF(MAESTRO!F11="","",IFERROR('Planilla (Ingles) '!F22,"")) | D11: =IF(MAESTRO!I11="","",IFERROR('Planilla (Español)'!F22,"")) | E11: =IF(MAESTRO!M11="","",IFERROR('Planilla (Matematica)'!F22,"")) | F11: =IF(MAESTRO!Q11="","",IFERROR('Planilla (C. Sociales)'!F22,"")) | G11: =IF(MAESTRO!B11="","",IFERROR('Planilla (C. Naturales)'!F22,"")) | H11: =IF(MAESTRO!F11="","",IFERROR('Planilla (Religión)'!F22,"")) | I11: =IF(MAESTRO!B11="","",IFERROR('Planilla (E. Artisticas)'!F22,"")) | J11: =IF(MAESTRO!M11="","",IFERROR('Planilla (Tecnologia)'!F22,"")) | K11: =IF(MAESTRO!N11="","",IFERROR('Planilla (E. Fisica)'!F22,"")) | N11: 7 | O11: =IF(MAESTRO!O11="","",MAESTRO!O11) | P11: =IF(MAESTRO!S11="","",IFERROR('Planilla (Ingles) '!I22,"")) | Q11: =IF(MAESTRO!V11="","",IFERROR('Planilla (Español)'!I22,"")) | R11: =IF(MAESTRO!Z11="","",IFERROR('Planilla (Matematica)'!I22,"")) | S11: =IF(MAESTRO!AD11="","",IFERROR('Planilla (C. Sociales)'!I22,"")) | T11: =IF(MAESTRO!O11="","",IFERROR('Planilla (C. Naturales)'!I22,"")) | U11: =IF(MAESTRO!S11="","",IFERROR('Planilla (Religión)'!I22,"")) | V11: =IF(MAESTRO!O11="","",IFERROR('Planilla (E. Artisticas)'!I22,"")) | W11: =IF(MAESTRO!Z11="","",IFERROR('Planilla (Tecnologia)'!I22,"")) | X11: =IF(MAESTRO!AA11="","",IFERROR('Planilla (E. Fisica)'!I22,""))
A12: 8 | B12: =IF(MAESTRO!B12="","",MAESTRO!B12) | C12: =IF(MAESTRO!F12="","",IFERROR('Planilla (Ingles) '!F23,"")) | D12: =IF(MAESTRO!I12="","",IFERROR('Planilla (Español)'!F23,"")) | E12: =IF(MAESTRO!M12="","",IFERROR('Planilla (Matematica)'!F23,"")) | F12: =IF(MAESTRO!Q12="","",IFERROR('Planilla (C. Sociales)'!F23,"")) | G12: =IF(MAESTRO!B12="","",IFERROR('Planilla (C. Naturales)'!F23,"")) | H12: =IF(MAESTRO!F12="","",IFERROR('Planilla (Religión)'!F23,"")) | I12: =IF(MAESTRO!B12="","",IFERROR('Planilla (E. Artisticas)'!F23,"")) | J12: =IF(MAESTRO!M12="","",IFERROR('Planilla (Tecnologia)'!F23,"")) | K12: =IF(MAESTRO!N12="","",IFERROR('Planilla (E. Fisica)'!F23,"")) | N12: 8 | O12: =IF(MAESTRO!O12="","",MAESTRO!O12) | P12: =IF(MAESTRO!S12="","",IFERROR('Planilla (Ingles) '!I23,"")) | Q12: =IF(MAESTRO!V12="","",IFERROR('Planilla (Español)'!I23,"")) | R12: =IF(MAESTRO!Z12="","",IFERROR('Planilla (Matematica)'!I23,"")) | S12: =IF(MAESTRO!AD12="","",IFERROR('Planilla (C. Sociales)'!I23,"")) | T12: =IF(MAESTRO!O12="","",IFERROR('Planilla (C. Naturales)'!I23,"")) | U12: =IF(MAESTRO!S12="","",IFERROR('Planilla (Religión)'!I23,"")) | V12: =IF(MAESTRO!O12="","",IFERROR('Planilla (E. Artisticas)'!I23,"")) | W12: =IF(MAESTRO!Z12="","",IFERROR('Planilla (Tecnologia)'!I23,"")) | X12: =IF(MAESTRO!AA12="","",IFERROR('Planilla (E. Fisica)'!I23,""))
A13: 9 | B13: =IF(MAESTRO!B13="","",MAESTRO!B13) | C13: =IF(MAESTRO!F13="","",IFERROR('Planilla (Ingles) '!F24,"")) | D13: =IF(MAESTRO!I13="","",IFERROR('Planilla (Español)'!F24,"")) | E13: =IF(MAESTRO!M13="","",IFERROR('Planilla (Matematica)'!F24,"")) | F13: =IF(MAESTRO!Q13="","",IFERROR('Planilla (C. Sociales)'!F24,"")) | G13: =IF(MAESTRO!B13="","",IFERROR('Planilla (C. Naturales)'!F24,"")) | H13: =IF(MAESTRO!F13="","",IFERROR('Planilla (Religión)'!F24,"")) | I13: =IF(MAESTRO!B13="","",IFERROR('Planilla (E. Artisticas)'!F24,"")) | J13: =IF(MAESTRO!M13="","",IFERROR('Planilla (Tecnologia)'!F24,"")) | K13: =IF(MAESTRO!N13="","",IFERROR('Planilla (E. Fisica)'!F24,"")) | N13: 9 | O13: =IF(MAESTRO!O13="","",MAESTRO!O13) | P13: =IF(MAESTRO!S13="","",IFERROR('Planilla (Ingles) '!I24,"")) | Q13: =IF(MAESTRO!V13="","",IFERROR('Planilla (Español)'!I24,"")) | R13: =IF(MAESTRO!Z13="","",IFERROR('Planilla (Matematica)'!I24,"")) | S13: =IF(MAESTRO!AD13="","",IFERROR('Planilla (C. Sociales)'!I24,"")) | T13: =IF(MAESTRO!O13="","",IFERROR('Planilla (C. Naturales)'!I24,"")) | U13: =IF(MAESTRO!S13="","",IFERROR('Planilla (Religión)'!I24,"")) | V13: =IF(MAESTRO!O13="","",IFERROR('Planilla (E. Artisticas)'!I24,"")) | W13: =IF(MAESTRO!Z13="","",IFERROR('Planilla (Tecnologia)'!I24,"")) | X13: =IF(MAESTRO!AA13="","",IFERROR('Planilla (E. Fisica)'!I24,""))
A14: 10 | B14: =IF(MAESTRO!B14="","",MAESTRO!B14) | C14: =IF(MAESTRO!F14="","",IFERROR('Planilla (Ingles) '!F25,"")) | D14: =IF(MAESTRO!I14="","",IFERROR('Planilla (Español)'!F25,"")) | E14: =IF(MAESTRO!M14="","",IFERROR('Planilla (Matematica)'!F25,"")) | F14: =IF(MAESTRO!Q14="","",IFERROR('Planilla (C. Sociales)'!F25,"")) | G14: =IF(MAESTRO!B14="","",IFERROR('Planilla (C. Naturales)'!F25,"")) | H14: =IF(MAESTRO!F14="","",IFERROR('Planilla (Religión)'!F25,"")) | I14: =IF(MAESTRO!B14="","",IFERROR('Planilla (E. Artisticas)'!F25,"")) | J14: =IF(MAESTRO!M14="","",IFERROR('Planilla (Tecnologia)'!F25,"")) | K14: =IF(MAESTRO!N14="","",IFERROR('Planilla (E. Fisica)'!F25,"")) | N14: 10 | O14: =IF(MAESTRO!O14="","",MAESTRO!O14) | P14: =IF(MAESTRO!S14="","",IFERROR('Planilla (Ingles) '!I25,"")) | Q14: =IF(MAESTRO!V14="","",IFERROR('Planilla (Español)'!I25,"")) | R14: =IF(MAESTRO!Z14="","",IFERROR('Planilla (Matematica)'!I25,"")) | S14: =IF(MAESTRO!AD14="","",IFERROR('Planilla (C. Sociales)'!I25,"")) | T14: =IF(MAESTRO!O14="","",IFERROR('Planilla (C. Naturales)'!I25,"")) | U14: =IF(MAESTRO!S14="","",IFERROR('Planilla (Religión)'!I25,"")) | V14: =IF(MAESTRO!O14="","",IFERROR('Planilla (E. Artisticas)'!I25,"")) | W14: =IF(MAESTRO!Z14="","",IFERROR('Planilla (Tecnologia)'!I25,"")) | X14: =IF(MAESTRO!AA14="","",IFERROR('Planilla (E. Fisica)'!I25,""))
A15: 11 | B15: =IF(MAESTRO!B15="","",MAESTRO!B15) | C15: =IF(MAESTRO!F15="","",IFERROR('Planilla (Ingles) '!F26,"")) | D15: =IF(MAESTRO!I15="","",IFERROR('Planilla (Español)'!F26,"")) | E15: =IF(MAESTRO!M15="","",IFERROR('Planilla (Matematica)'!F26,"")) | F15: =IF(MAESTRO!Q15="","",IFERROR('Planilla (C. Sociales)'!F26,"")) | G15: =IF(MAESTRO!B15="","",IFERROR('Planilla (C. Naturales)'!F26,"")) | H15: =IF(MAESTRO!F15="","",IFERROR('Planilla (Religión)'!F26,"")) | I15: =IF(MAESTRO!B15="","",IFERROR('Planilla (E. Artisticas)'!F26,"")) | J15: =IF(MAESTRO!M15="","",IFERROR('Planilla (Tecnologia)'!F26,"")) | K15: =IF(MAESTRO!N15="","",IFERROR('Planilla (E. Fisica)'!F26,"")) | N15: 11 | O15: =IF(MAESTRO!O15="","",MAESTRO!O15) | P15: =IF(MAESTRO!S15="","",IFERROR('Planilla (Ingles) '!I26,"")) | Q15: =IF(MAESTRO!V15="","",IFERROR('Planilla (Español)'!I26,"")) | R15: =IF(MAESTRO!Z15="","",IFERROR('Planilla (Matematica)'!I26,"")) | S15: =IF(MAESTRO!AD15="","",IFERROR('Planilla (C. Sociales)'!I26,"")) | T15: =IF(MAESTRO!O15="","",IFERROR('Planilla (C. Naturales)'!I26,"")) | U15: =IF(MAESTRO!S15="","",IFERROR('Planilla (Religión)'!I26,"")) | V15: =IF(MAESTRO!O15="","",IFERROR('Planilla (E. Artisticas)'!I26,"")) | W15: =IF(MAESTRO!Z15="","",IFERROR('Planilla (Tecnologia)'!I26,"")) | X15: =IF(MAESTRO!AA15="","",IFERROR('Planilla (E. Fisica)'!I26,""))
A16: 12 | B16: =IF(MAESTRO!B16="","",MAESTRO!B16) | C16: =IF(MAESTRO!F16="","",IFERROR('Planilla (Ingles) '!F27,"")) | D16: =IF(MAESTRO!I16="","",IFERROR('Planilla (Español)'!F27,"")) | E16: =IF(MAESTRO!M16="","",IFERROR('Planilla (Matematica)'!F27,"")) | F16: =IF(MAESTRO!Q16="","",IFERROR('Planilla (C. Sociales)'!F27,"")) | G16: =IF(MAESTRO!B16="","",IFERROR('Planilla (C. Naturales)'!F27,"")) | H16: =IF(MAESTRO!F16="","",IFERROR('Planilla (Religión)'!F27,"")) | I16: =IF(MAESTRO!B16="","",IFERROR('Planilla (E. Artisticas)'!F27,"")) | J16: =IF(MAESTRO!M16="","",IFERROR('Planilla (Tecnologia)'!F27,"")) | K16: =IF(MAESTRO!N16="","",IFERROR('Planilla (E. Fisica)'!F27,"")) | N16: 12 | O16: =IF(MAESTRO!O16="","",MAESTRO!O16) | P16: =IF(MAESTRO!S16="","",IFERROR('Planilla (Ingles) '!I27,"")) | Q16: =IF(MAESTRO!V16="","",IFERROR('Planilla (Español)'!I27,"")) | R16: =IF(MAESTRO!Z16="","",IFERROR('Planilla (Matematica)'!I27,"")) | S16: =IF(MAESTRO!AD16="","",IFERROR('Planilla (C. Sociales)'!I27,"")) | T16: =IF(MAESTRO!O16="","",IFERROR('Planilla (C. Naturales)'!I27,"")) | U16: =IF(MAESTRO!S16="","",IFERROR('Planilla (Religión)'!I27,"")) | V16: =IF(MAESTRO!O16="","",IFERROR('Planilla (E. Artisticas)'!I27,"")) | W16: =IF(MAESTRO!Z16="","",IFERROR('Planilla (Tecnologia)'!I27,"")) | X16: =IF(MAESTRO!AA16="","",IFERROR('Planilla (E. Fisica)'!I27,""))
... A38: 34 | B38: =IF(MAESTRO!B38="","",MAESTRO!B38) | C38: =IF(MAESTRO!F38="","",IFERROR('Planilla (Ingles) '!F49,"")) | D38: =IF(MAESTRO!I38="","",IFERROR('Planilla (Español)'!F49,"")) | E38: =IF(MAESTRO!M38="","",IFERROR('Planilla (Matematica)'!F49,"")) | F38: =IF(MAESTRO!Q38="","",IFERROR('Planilla (C. Sociales)'!F49,"")) | G38: =IF(MAESTRO!B38="","",IFERROR('Planilla (C. Naturales)'!F49,"")) | H38: =IF(MAESTRO!F38="","",IFERROR('Planilla (Religión)'!F49,"")) | I38: =IF(MAESTRO!B38="","",IFERROR('Planilla (E. Artisticas)'!F49,"")) | J38: =IF(MAESTRO!M38="","",IFERROR('Planilla (Tecnologia)'!F49,"")) | K38: =IF(MAESTRO!N38="","",IFERROR('Planilla (E. Fisica)'!F49,"")) | N38: 34 | O38: =IF(MAESTRO!O38="","",MAESTRO!O38) | P38: =IF(MAESTRO!S38="","",IFERROR('Planilla (Ingles) '!I49,"")) | Q38: =IF(MAESTRO!V38="","",IFERROR('Planilla (Español)'!I49,"")) | R38: =IF(MAESTRO!Z38="","",IFERROR('Planilla (Matematica)'!I49,"")) | S38: =IF(MAESTRO!AD38="","",IFERROR('Planilla (C. Sociales)'!I49,"")) | T38: =IF(MAESTRO!O38="","",IFERROR('Planilla (C. Naturales)'!I49,"")) | U38: =IF(MAESTRO!S38="","",IFERROR('Planilla (Religión)'!I49,"")) | V38: =IF(MAESTRO!O38="","",IFERROR('Planilla (E. Artisticas)'!I49,"")) | W38: =IF(MAESTRO!Z38="","",IFERROR('Planilla (Tecnologia)'!I49,"")) | X38: =IF(MAESTRO!AA38="","",IFERROR('Planilla (E. Fisica)'!I49,""))
A39: PROMEDIO DEL GRUPO | C39: =IFERROR(ROUND(AVERAGEIF(C5:C38,"<>"&""),1),"") | D39: =IFERROR(ROUND(AVERAGEIF(D5:D38,"<>"&""),1),"") | E39: =IFERROR(ROUND(AVERAGEIF(E5:E38,"<>"&""),1),"") | F39: =IFERROR(ROUND(AVERAGEIF(F5:F38,"<>"&""),1),"") | G39: =IFERROR(ROUND(AVERAGEIF(G5:G38,"<>"&""),1),"") | H39: =IFERROR(ROUND(AVERAGEIF(H5:H38,"<>"&""),1),"") | I39: =IFERROR(ROUND(AVERAGEIF(I5:I38,"<>"&""),1),"") | J39: =IFERROR(ROUND(AVERAGEIF(J5:J38,"<>"&""),1),"") | N39: PROMEDIO DEL GRUPO | P39: =IFERROR(ROUND(AVERAGEIF(P5:P38,"<>"&""),1),"") | Q39: =IFERROR(ROUND(AVERAGEIF(Q5:Q38,"<>"&""),1),"") | R39: =IFERROR(ROUND(AVERAGEIF(R5:R38,"<>"&""),1),"") | S39: =IFERROR(ROUND(AVERAGEIF(S5:S38,"<>"&""),1),"") | T39: =IFERROR(ROUND(AVERAGEIF(T5:T38,"<>"&""),1),"") | U39: =IFERROR(ROUND(AVERAGEIF(U5:U38,"<>"&""),1),"") | V39: =IFERROR(ROUND(AVERAGEIF(V5:V38,"<>"&""),1),"") | W39: =IFERROR(ROUND(AVERAGEIF(W5:W38,"<>"&""),1),"")
A41: Nota: SEGUNDO TRIMESTRE
A42: No. | B42: APELLIDO, NOMBRE | C42: INGLES | D42: ESPAÑOL | E42: Matemática | F42: C.SOCIALES | G42: C.NATURALES | H42: Religión | I42: Artística | J42: TECNOLOGIA | K42: E. FISICA | L42: ESTADO
C43: FINAL | D43: FINAL | E43: FINAL | F43: FINAL | G43: FINAL | H43: FINAL | I43: FINAL | J43: FINAL | K43: FINAL
A44: 1 | B44: =IF(MAESTRO!B46="","",MAESTRO!B46) | C44: =IF(MAESTRO!F46="","",IFERROR('Planilla (Ingles) '!G16,"")) | D44: =IF(MAESTRO!I46="","",IFERROR('Planilla (Español)'!G16,"")) | E44: =IF(MAESTRO!M46="","",IFERROR('Planilla (Matematica)'!G16,"")) | F44: =IF(MAESTRO!Q46="","",IFERROR('Planilla (C. Sociales)'!G16,"")) | G44: =IF(MAESTRO!B46="","",IFERROR('Planilla (C. Naturales)'!G16,"")) | H44: =IF(MAESTRO!F46="","",IFERROR('Planilla (Religión)'!G16,"")) | I44: =IF(MAESTRO!B46="","",IFERROR('Planilla (E. Artisticas)'!G16,"")) | J44: =IF(MAESTRO!M46="","",IFERROR('Planilla (Tecnologia)'!G16,"")) | K44: =IF(MAESTRO!N46="","",IFERROR('Planilla (E. Fisica)'!G16,""))
A45: 2 | B45: =IF(MAESTRO!B47="","",MAESTRO!B47) | C45: =IF(MAESTRO!F47="","",IFERROR('Planilla (Ingles) '!G17,"")) | D45: =IF(MAESTRO!I47="","",IFERROR('Planilla (Español)'!G17,"")) | E45: =IF(MAESTRO!M47="","",IFERROR('Planilla (Matematica)'!G17,"")) | F45: =IF(MAESTRO!Q47="","",IFERROR('Planilla (C. Sociales)'!G17,"")) | G45: =IF(MAESTRO!B47="","",IFERROR('Planilla (C. Naturales)'!G17,"")) | H45: =IF(MAESTRO!F47="","",IFERROR('Planilla (Religión)'!G17,"")) | I45: =IF(MAESTRO!B47="","",IFERROR('Planilla (E. Artisticas)'!G17,"")) | J45: =IF(MAESTRO!M47="","",IFERROR('Planilla (Tecnologia)'!G17,"")) | K45: =IF(MAESTRO!N47="","",IFERROR('Planilla (E. Fisica)'!G17,""))
A46: 3 | B46: =IF(MAESTRO!B48="","",MAESTRO!B48) | C46: =IF(MAESTRO!F48="","",IFERROR('Planilla (Ingles) '!G18,"")) | D46: =IF(MAESTRO!I48="","",IFERROR('Planilla (Español)'!G18,"")) | E46: =IF(MAESTRO!M48="","",IFERROR('Planilla (Matematica)'!G18,"")) | F46: =IF(MAESTRO!Q48="","",IFERROR('Planilla (C. Sociales)'!G18,"")) | G46: =IF(MAESTRO!B48="","",IFERROR('Planilla (C. Naturales)'!G18,"")) | H46: =IF(MAESTRO!F48="","",IFERROR('Planilla (Religión)'!G18,"")) | I46: =IF(MAESTRO!B48="","",IFERROR('Planilla (E. Artisticas)'!G18,"")) | J46: =IF(MAESTRO!M48="","",IFERROR('Planilla (Tecnologia)'!G18,"")) | K46: =IF(MAESTRO!N48="","",IFERROR('Planilla (E. Fisica)'!G18,""))
A47: 4 | B47: =IF(MAESTRO!B49="","",MAESTRO!B49) | C47: =IF(MAESTRO!F49="","",IFERROR('Planilla (Ingles) '!G19,"")) | D47: =IF(MAESTRO!I49="","",IFERROR('Planilla (Español)'!G19,"")) | E47: =IF(MAESTRO!M49="","",IFERROR('Planilla (Matematica)'!G19,"")) | F47: =IF(MAESTRO!Q49="","",IFERROR('Planilla (C. Sociales)'!G19,"")) | G47: =IF(MAESTRO!B49="","",IFERROR('Planilla (C. Naturales)'!G19,"")) | H47: =IF(MAESTRO!F49="","",IFERROR('Planilla (Religión)'!G19,"")) | I47: =IF(MAESTRO!B49="","",IFERROR('Planilla (E. Artisticas)'!G19,"")) | J47: =IF(MAESTRO!M49="","",IFERROR('Planilla (Tecnologia)'!G19,"")) | K47: =IF(MAESTRO!N49="","",IFERROR('Planilla (E. Fisica)'!G19,""))
A48: 5 | B48: =IF(MAESTRO!B50="","",MAESTRO!B50) | C48: =IF(MAESTRO!F50="","",IFERROR('Planilla (Ingles) '!G20,"")) | D48: =IF(MAESTRO!I50="","",IFERROR('Planilla (Español)'!G20,"")) | E48: =IF(MAESTRO!M50="","",IFERROR('Planilla (Matematica)'!G20,"")) | F48: =IF(MAESTRO!Q50="","",IFERROR('Planilla (C. Sociales)'!G20,"")) | G48: =IF(MAESTRO!B50="","",IFERROR('Planilla (C. Naturales)'!G20,"")) | H48: =IF(MAESTRO!F50="","",IFERROR('Planilla (Religión)'!G20,"")) | I48: =IF(MAESTRO!B50="","",IFERROR('Planilla (E. Artisticas)'!G20,"")) | J48: =IF(MAESTRO!M50="","",IFERROR('Planilla (Tecnologia)'!G20,"")) | K48: =IF(MAESTRO!N50="","",IFERROR('Planilla (E. Fisica)'!G20,""))
A49: 6 | B49: =IF(MAESTRO!B51="","",MAESTRO!B51) | C49: =IF(MAESTRO!F51="","",IFERROR('Planilla (Ingles) '!G21,"")) | D49: =IF(MAESTRO!I51="","",IFERROR('Planilla (Español)'!G21,"")) | E49: =IF(MAESTRO!M51="","",IFERROR('Planilla (Matematica)'!G21,"")) | F49: =IF(MAESTRO!Q51="","",IFERROR('Planilla (C. Sociales)'!G21,"")) | G49: =IF(MAESTRO!B51="","",IFERROR('Planilla (C. Naturales)'!G21,"")) | H49: =IF(MAESTRO!F51="","",IFERROR('Planilla (Religión)'!G21,"")) | I49: =IF(MAESTRO!B51="","",IFERROR('Planilla (E. Artisticas)'!G21,"")) | J49: =IF(MAESTRO!M51="","",IFERROR('Planilla (Tecnologia)'!G21,"")) | K49: =IF(MAESTRO!N51="","",IFERROR('Planilla (E. Fisica)'!G21,""))
A50: 7 | B50: =IF(MAESTRO!B52="","",MAESTRO!B52) | C50: =IF(MAESTRO!F52="","",IFERROR('Planilla (Ingles) '!G22,"")) | D50: =IF(MAESTRO!I52="","",IFERROR('Planilla (Español)'!G22,"")) | E50: =IF(MAESTRO!M52="","",IFERROR('Planilla (Matematica)'!G22,"")) | F50: =IF(MAESTRO!Q52="","",IFERROR('Planilla (C. Sociales)'!G22,"")) | G50: =IF(MAESTRO!B52="","",IFERROR('Planilla (C. Naturales)'!G22,"")) | H50: =IF(MAESTRO!F52="","",IFERROR('Planilla (Religión)'!G22,"")) | I50: =IF(MAESTRO!B52="","",IFERROR('Planilla (E. Artisticas)'!G22,"")) | J50: =IF(MAESTRO!M52="","",IFERROR('Planilla (Tecnologia)'!G22,"")) | K50: =IF(MAESTRO!N52="","",IFERROR('Planilla (E. Fisica)'!G22,""))
A51: 8 | B51: =IF(MAESTRO!B53="","",MAESTRO!B53) | C51: =IF(MAESTRO!F53="","",IFERROR('Planilla (Ingles) '!G23,"")) | D51: =IF(MAESTRO!I53="","",IFERROR('Planilla (Español)'!G23,"")) | E51: =IF(MAESTRO!M53="","",IFERROR('Planilla (Matematica)'!G23,"")) | F51: =IF(MAESTRO!Q53="","",IFERROR('Planilla (C. Sociales)'!G23,"")) | G51: =IF(MAESTRO!B53="","",IFERROR('Planilla (C. Naturales)'!G23,"")) | H51: =IF(MAESTRO!F53="","",IFERROR('Planilla (Religión)'!G23,"")) | I51: =IF(MAESTRO!B53="","",IFERROR('Planilla (E. Artisticas)'!G23,"")) | J51: =IF(MAESTRO!M53="","",IFERROR('Planilla (Tecnologia)'!G23,"")) | K51: =IF(MAESTRO!N53="","",IFERROR('Planilla (E. Fisica)'!G23,""))
A52: 9 | B52: =IF(MAESTRO!B54="","",MAESTRO!B54) | C52: =IF(MAESTRO!F54="","",IFERROR('Planilla (Ingles) '!G24,"")) | D52: =IF(MAESTRO!I54="","",IFERROR('Planilla (Español)'!G24,"")) | E52: =IF(MAESTRO!M54="","",IFERROR('Planilla (Matematica)'!G24,"")) | F52: =IF(MAESTRO!Q54="","",IFERROR('Planilla (C. Sociales)'!G24,"")) | G52: =IF(MAESTRO!B54="","",IFERROR('Planilla (C. Naturales)'!G24,"")) | H52: =IF(MAESTRO!F54="","",IFERROR('Planilla (Religión)'!G24,"")) | I52: =IF(MAESTRO!B54="","",IFERROR('Planilla (E. Artisticas)'!G24,"")) | J52: =IF(MAESTRO!M54="","",IFERROR('Planilla (Tecnologia)'!G24,"")) | K52: =IF(MAESTRO!N54="","",IFERROR('Planilla (E. Fisica)'!G24,""))
A53: 10 | B53: =IF(MAESTRO!B55="","",MAESTRO!B55) | C53: =IF(MAESTRO!F55="","",IFERROR('Planilla (Ingles) '!G25,"")) | D53: =IF(MAESTRO!I55="","",IFERROR('Planilla (Español)'!G25,"")) | E53: =IF(MAESTRO!M55="","",IFERROR('Planilla (Matematica)'!G25,"")) | F53: =IF(MAESTRO!Q55="","",IFERROR('Planilla (C. Sociales)'!G25,"")) | G53: =IF(MAESTRO!B55="","",IFERROR('Planilla (C. Naturales)'!G25,"")) | H53: =IF(MAESTRO!F55="","",IFERROR('Planilla (Religión)'!G25,"")) | I53: =IF(MAESTRO!B55="","",IFERROR('Planilla (E. Artisticas)'!G25,"")) | J53: =IF(MAESTRO!M55="","",IFERROR('Planilla (Tecnologia)'!G25,"")) | K53: =IF(MAESTRO!N55="","",IFERROR('Planilla (E. Fisica)'!G25,""))
A54: 11 | B54: =IF(MAESTRO!B56="","",MAESTRO!B56) | C54: =IF(MAESTRO!F56="","",IFERROR('Planilla (Ingles) '!G26,"")) | D54: =IF(MAESTRO!I56="","",IFERROR('Planilla (Español)'!G26,"")) | E54: =IF(MAESTRO!M56="","",IFERROR('Planilla (Matematica)'!G26,"")) | F54: =IF(MAESTRO!Q56="","",IFERROR('Planilla (C. Sociales)'!G26,"")) | G54: =IF(MAESTRO!B56="","",IFERROR('Planilla (C. Naturales)'!G26,"")) | H54: =IF(MAESTRO!F56="","",IFERROR('Planilla (Religión)'!G26,"")) | I54: =IF(MAESTRO!B56="","",IFERROR('Planilla (E. Artisticas)'!G26,"")) | J54: =IF(MAESTRO!M56="","",IFERROR('Planilla (Tecnologia)'!G26,"")) | K54: =IF(MAESTRO!N56="","",IFERROR('Planilla (E. Fisica)'!G26,""))
A55: 12 | B55: =IF(MAESTRO!B57="","",MAESTRO!B57) | C55: =IF(MAESTRO!F57="","",IFERROR('Planilla (Ingles) '!G27,"")) | D55: =IF(MAESTRO!I57="","",IFERROR('Planilla (Español)'!G27,"")) | E55: =IF(MAESTRO!M57="","",IFERROR('Planilla (Matematica)'!G27,"")) | F55: =IF(MAESTRO!Q57="","",IFERROR('Planilla (C. Sociales)'!G27,"")) | G55: =IF(MAESTRO!B57="","",IFERROR('Planilla (C. Naturales)'!G27,"")) | H55: =IF(MAESTRO!F57="","",IFERROR('Planilla (Religión)'!G27,"")) | I55: =IF(MAESTRO!B57="","",IFERROR('Planilla (E. Artisticas)'!G27,"")) | J55: =IF(MAESTRO!M57="","",IFERROR('Planilla (Tecnologia)'!G27,"")) | K55: =IF(MAESTRO!N57="","",IFERROR('Planilla (E. Fisica)'!G27,""))
... A78: 35 | B78: =IF(MAESTRO!B80="","",MAESTRO!B80) | C78: =IF(MAESTRO!F80="","",IFERROR('Planilla (Ingles) '!G50,"")) | D78: =IF(MAESTRO!I80="","",IFERROR('Planilla (Español)'!G50,"")) | E78: =IF(MAESTRO!M80="","",IFERROR('Planilla (Matematica)'!G50,"")) | F78: =IF(MAESTRO!Q80="","",IFERROR('Planilla (C. Sociales)'!G50,"")) | G78: =IF(MAESTRO!B80="","",IFERROR('Planilla (C. Naturales)'!G50,"")) | H78: =IF(MAESTRO!F80="","",IFERROR('Planilla (Religión)'!G50,"")) | I78: =IF(MAESTRO!B80="","",IFERROR('Planilla (E. Artisticas)'!G50,"")) | J78: =IF(MAESTRO!M80="","",IFERROR('Planilla (Tecnologia)'!G50,"")) | K78: =IF(MAESTRO!N80="","",IFERROR('Planilla (E. Fisica)'!G50,""))
A79: PROMEDIO DEL GRUPO | C79: =IFERROR(ROUND(AVERAGEIF(C44:C78,"<>"&""),1),"") | D79: =IFERROR(ROUND(AVERAGEIF(D44:D78,"<>"&""),1),"") | E79: =IFERROR(ROUND(AVERAGEIF(E44:E78,"<>"&""),1),"") | F79: =IFERROR(ROUND(AVERAGEIF(F44:F78,"<>"&""),1),"") | G79: =IFERROR(ROUND(AVERAGEIF(G44:G78,"<>"&""),1),"") | H79: =IFERROR(ROUND(AVERAGEIF(H44:H78,"<>"&""),1),"") | I79: =IFERROR(ROUND(AVERAGEIF(I44:I78,"<>"&""),1),"") | J79: =IFERROR(ROUND(AVERAGEIF(J44:J78,"<>"&""),1),"") | K79: =IFERROR(ROUND(AVERAGEIF(K44:K78,"<>"&""),1),"")
A83: Nota: TERCER TRIMESTRE
A84: No. | B84: APELLIDO, NOMBRE | C84: INGLES | D84: ESPAÑOL | E84: Matemática | F84: C.SOCIALES | G84: C.NATURALES | H84: Religión | I84: Artística | J84: TECNOLOGIA | K84: E. FISICA | L84: ESTADO
C85: FINAL | D85: FINAL | E85: FINAL | F85: FINAL | G85: FINAL | H85: FINAL | I85: FINAL | J85: FINAL | K85: FINAL
A86: 1 | B86: =IF(MAESTRO!B88="","",MAESTRO!B88) | C86: =IF(MAESTRO!F88="","",IFERROR('Planilla (Ingles) '!H16,"")) | D86: =IF(MAESTRO!I88="","",IFERROR('Planilla (Español)'!H16,"")) | E86: =IF(MAESTRO!M88="","",IFERROR('Planilla (Matematica)'!H16,"")) | F86: =IF(MAESTRO!Q88="","",IFERROR('Planilla (C. Sociales)'!H16,"")) | G86: =IF(MAESTRO!B88="","",IFERROR('Planilla (C. Naturales)'!H16,"")) | H86: =IF(MAESTRO!F88="","",IFERROR('Planilla (Religión)'!H16,"")) | I86: =IF(MAESTRO!B88="","",IFERROR('Planilla (E. Artisticas)'!H16,"")) | J86: =IF(MAESTRO!M88="","",IFERROR('Planilla (Tecnologia)'!H16,"")) | K86: =IF(MAESTRO!N88="","",IFERROR('Planilla (E. Fisica)'!H16,""))
A87: 2 | B87: =IF(MAESTRO!B89="","",MAESTRO!B89) | C87: =IF(MAESTRO!F89="","",IFERROR('Planilla (Ingles) '!H17,"")) | D87: =IF(MAESTRO!I89="","",IFERROR('Planilla (Español)'!H17,"")) | E87: =IF(MAESTRO!M89="","",IFERROR('Planilla (Matematica)'!H17,"")) | F87: =IF(MAESTRO!Q89="","",IFERROR('Planilla (C. Sociales)'!H17,"")) | G87: =IF(MAESTRO!B89="","",IFERROR('Planilla (C. Naturales)'!H17,"")) | H87: =IF(MAESTRO!F89="","",IFERROR('Planilla (Religión)'!H17,"")) | I87: =IF(MAESTRO!B89="","",IFERROR('Planilla (E. Artisticas)'!H17,"")) | J87: =IF(MAESTRO!M89="","",IFERROR('Planilla (Tecnologia)'!H17,"")) | K87: =IF(MAESTRO!N89="","",IFERROR('Planilla (E. Fisica)'!H17,""))
...

Sheet Asistencia 
B1: NOMBRE ALUMNA-ALUMNO | C1: ASISTENCIA DEL__17__DE___Marzo______AL__13___DE_____Junio_____ | BI1: PRIMER TRIMESTRE | BK1: OBSERVACIONES
BI2: TOTAL AUSENCIAS | BJ2: TOTAL TARDANZAS
A3: 1 | B3: =IF(MAESTRO!B5="","",MAESTRO!B5) | BI3: =IFERROR(COUNTIF(C3:BH3,"-"),"") -> 0 | BJ3: =IFERROR(COUNTIF(D3:BI3,"T"),"") -> 0 | BL3: 1
A4: 2 | B4: =IF(MAESTRO!B6="","",MAESTRO!B6) | BI4: =IFERROR(COUNTIF(C4:BH4,"-"),"") -> 0 | BJ4: =IFERROR(COUNTIF(D4:BI4,"T"),"") -> 0 | BL4: 2
A5: 3 | B5: =IF(MAESTRO!B7="","",MAESTRO!B7) | BI5: =IFERROR(COUNTIF(C5:BH5,"-"),"") -> 0 | BJ5: =IFERROR(COUNTIF(D5:BI5,"T"),"") -> 0 | BL5: 3
A6: 4 | B6: =IF(MAESTRO!B8="","",MAESTRO!B8) | BI6: =IFERROR(COUNTIF(C6:BH6,"-"),"") -> 0 | BJ6: =IFERROR(COUNTIF(D6:BI6,"T"),"") -> 0 | BL6: 4
A7: 5 | B7: =IF(MAESTRO!B9="","",MAESTRO!B9) | BI7: =IFERROR(COUNTIF(C7:BH7,"-"),"") -> 0 | BJ7: =IFERROR(COUNTIF(D7:BI7,"T"),"") -> 0 | BL7: 5
A8: 6 | B8: =IF(MAESTRO!B10="","",MAESTRO!B10) | BI8: =IFERROR(COUNTIF(C8:BH8,"-"),"") -> 0 | BJ8: =IFERROR(COUNTIF(D8:BI8,"T"),"") -> 0 | BL8: 6
A9: 7 | B9: =IF(MAESTRO!B11="","",MAESTRO!B11) | BI9: =IFERROR(COUNTIF(C9:BH9,"-"),"") -> 0 | BJ9: =IFERROR(COUNTIF(D9:BI9,"T"),"") -> 0 | BL9: 7
A10: 8 | B10: =IF(MAESTRO!B12="","",MAESTRO!B12) | BI10: =IFERROR(COUNTIF(C10:BH10,"-"),"") -> 0 | BJ10: =IFERROR(COUNTIF(D10:BI10,"T"),"") -> 0 | BL10: 8
A11: 9 | B11: =IF(MAESTRO!B13="","",MAESTRO!B13) | BI11: =IFERROR(COUNTIF(C11:BH11,"-"),"") -> 0 | BJ11: =IFERROR(COUNTIF(D11:BI11,"T"),"") -> 0 | BL11: 9
A12: 10 | B12: =IF(MAESTRO!B14="","",MAESTRO!B14) | BI12: =IFERROR(COUNTIF(C12:BH12,"-"),"") -> 0 | BJ12: =IFERROR(COUNTIF(D12:BI12,"T"),"") -> 0 | BL12: 10
A13: 11 | B13: =IF(MAESTRO!B15="","",MAESTRO!B15) | BI13: =IFERROR(COUNTIF(C13:BH13,"-"),"") -> 0 | BJ13: =IFERROR(COUNTIF(D13:BI13,"T"),"") -> 0 | BL13: 11
A14: 12 | B14: =IF(MAESTRO!B16="","",MAESTRO!B16) | BI14: =IFERROR(COUNTIF(C14:BH14,"-"),"") -> 0 | BJ14: =IFERROR(COUNTIF(D14:BI14,"T"),"") -> 0 | BL14: 12
... A36: 34 | B36: =IF(MAESTRO!B38="","",MAESTRO!B38) | BI36: =IFERROR(COUNTIF(C36:BH36,"-"),"") -> 0 | BJ36: =IFERROR(COUNTIF(D36:BI36,"T"),"") -> 0 | BL36: 34
A37: 35 | B37: =IF(MAESTRO!#REF!="","",MAESTRO!#REF!) -> #REF! | BI37: =IFERROR(COUNTIF(C37:BH37,"-"),"") -> 0 | BJ37: =IFERROR(COUNTIF(D37:BI37,"T"),"") -> 0 | BL37: 35
A38: 36 | B38: =IF(MAESTRO!#REF!="","",MAESTRO!#REF!) -> #REF! | BI38: =IFERROR(COUNTIF(C38:BH38,"-"),"") -> 0 | BJ38: =IFERROR(COUNTIF(D38:BI38,"T"),"") -> 0 | BL38: 36
A39: 37 | B39: =IF(MAESTRO!#REF!="","",MAESTRO!#REF!) -> #REF! | BI39: =IFERROR(COUNTIF(C39:BH39,"-"),"") -> 0 | BJ39: =IFERROR(COUNTIF(D39:BI39,"T"),"") -> 0 | BL39: 37
A40: 38 | B40: =IF(MAESTRO!#REF!="","",MAESTRO!#REF!) -> #REF! | BI40: =IFERROR(COUNTIF(C40:BH40,"-"),"") -> 0 | BJ40: =IFERROR(COUNTIF(D40:BI40,"T"),"") -> 0 | BL40: 38
A41: 39 | B41: =IF(MAESTRO!#REF!="","",MAESTRO!#REF!) -> #REF! | BI41: =IFERROR(COUNTIF(C41:BH41,"A"),"") -> 0 | BJ41: =IFERROR(COUNTIF(D41:BI41,"T"),"") -> 0 | BL41: 39
A42: 40 | B42: =IF(MAESTRO!#REF!="","",MAESTRO!#REF!) -> #REF! | BI42: =IFERROR(COUNTIF(C42:BH42,"A"),"") -> 0 | BJ42: =IFERROR(COUNTIF(D42:BI42,"T"),"") -> 0 | BL42: 40
A43: 41 | BI43: =IFERROR(COUNTIF(C43:BH43,"A"),"") -> 0 | BJ43: =IFERROR(COUNTIF(D43:BI43,"T"),"") -> 0 | BL43: 41
B44: NOMBRE ALUMNA-ALUMNO | C44: ASISTENCIA DEL__23__DE____JUNIO____AL__12___DE___SEPTIEMBRE__ | BI44: SEGUNDO TRIMESTRE | BK44: OBSERVACIONES
BI45: TOTAL AUSENCIAS | BJ45: TOTAL TARDANZAS
A46: 1 | B46: =IF(MAESTRO!B5="","",MAESTRO!B5) | BI46: =IFERROR(COUNTIF(C46:BH46,"-"),"") -> 0 | BJ46: =IFERROR(COUNTIF(D46:BI46,"T"),"") -> 0 | BL46: 1
A47: 2 | B47: =IF(MAESTRO!B6="","",MAESTRO!B6) | BI47: =IFERROR(COUNTIF(C47:BH47,"-"),"") -> 0 | BJ47: =IFERROR(COUNTIF(D47:BI47,"T"),"") -> 0 | BL47: 2
A48: 3 | B48: =IF(MAESTRO!B7="","",MAESTRO!B7) | BI48: =IFERROR(COUNTIF(C48:BH48,"-"),"") -> 0 | BJ48: =IFERROR(COUNTIF(D48:BI48,"T"),"") -> 0 | BL48: 3
A49: 4 | B49: =IF(MAESTRO!B8="","",MAESTRO!B8) | BI49: =IFERROR(COUNTIF(C49:BH49,"-"),"") -> 0 | BJ49: =IFERROR(COUNTIF(D49:BI49,"T"),"") -> 0 | BL49: 4
A50: 5 | B50: =IF(MAESTRO!B9="","",MAESTRO!B9) | BI50: =IFERROR(COUNTIF(C50:BH50,"-"),"") -> 0 | BJ50: =IFERROR(COUNTIF(D50:BI50,"T"),"") -> 0 | BL50: 5
A51: 6 | B51: =IF(MAESTRO!B10="","",MAESTRO!B10) | BI51: =IFERROR(COUNTIF(C51:BH51,"-"),"") -> 0 | BJ51: =IFERROR(COUNTIF(D51:BI51,"T"),"") -> 0 | BL51: 6
A52: 7 | B52: =IF(MAESTRO!B11="","",MAESTRO!B11) | BI52: =IFERROR(COUNTIF(C52:BH52,"-"),"") -> 0 | BJ52: =IFERROR(COUNTIF(D52:BI52,"T"),"") -> 0 | BL52: 7
A53: 8 | B53: =IF(MAESTRO!B12="","",MAESTRO!B12) | BI53: =IFERROR(COUNTIF(C53:BH53,"-"),"") -> 0 | BJ53: =IFERROR(COUNTIF(D53:BI53,"T"),"") -> 0 | BL53: 8
A54: 9 | B54: =IF(MAESTRO!B13="","",MAESTRO!B13) | BI54: =IFERROR(COUNTIF(C54:BH54,"-"),"") -> 0 | BJ54: =IFERROR(COUNTIF(D54:BI54,"T"),"") -> 0 | BL54: 9
A55: 10 | B55: =IF(MAESTRO!B14="","",MAESTRO!B14) | BI55: =IFERROR(COUNTIF(C55:BH55,"-"),"") -> 0 | BJ55: =IFERROR(COUNTIF(D55:BI55,"T"),"") -> 0 | BL55: 10
A56: 11 | B56: =IF(MAESTRO!B15="","",MAESTRO!B15) | BI56: =IFERROR(COUNTIF(C56:BH56,"-"),"") -> 0 | BJ56: =IFERROR(COUNTIF(D56:BI56,"T"),"") -> 0 | BL56: 11
A57: 12 | B57: =IF(MAESTRO!B16="","",MAESTRO!B16) | BI57: =IFERROR(COUNTIF(C57:BH57,"-"),"") -> 0 | BJ57: =IFERROR(COUNTIF(D57:BI57,"T"),"") -> 0 | BL57: 12
... A79: 34 | B79: =IF(MAESTRO!B38="","",MAESTRO!B38) | BI79: =IFERROR(COUNTIF(C79:BH79,"-"),"") -> 0 | BJ79: =IFERROR(COUNTIF(D79:BI79,"T"),"") -> 0 | BL79: 34
A80: 35 | B80: =IF(MAESTRO!#REF!="","",MAESTRO!#REF!) -> #REF! | C80: . | BI80: =IFERROR(COUNTIF(C80:BH80,"-"),"") -> 0 | BJ80: =IFERROR(COUNTIF(D80:BI80,"T"),"") -> 0 | BL80: 35
A81: 36 | B81: =IF(MAESTRO!#REF!="","",MAESTRO!#REF!) -> #REF! | C81: . | BI81: =IFERROR(COUNTIF(C81:BH81,"-"),"") -> 0 | BJ81: =IFERROR(COUNTIF(D81:BI81,"T"),"") -> 0 | BL81: 36
A82: 37 | B82: =IF(MAESTRO!#REF!="","",MAESTRO!#REF!) -> #REF! | C82: . | BI82: =IFERROR(COUNTIF(C82:BH82,"-"),"") -> 0 | BJ82: =IFERROR(COUNTIF(D82:BI82,"T"),"") -> 0 | BL82: 37
...

Sheet PROM (Ingles)
A1: CALIFICACIONES-PRIMER TRIMESTRE | R1: CALIFICACIONES-PRIMER TRIMESTRE | AH1: CALIFICACIONES-SEGUNDO TRIMESTRE | AY1: CALIFICACIONES-SEGUNDO TRIMESTRE | BP1: CALIFICACIONES-TERCER TIMESTRE | CG1: CALIFICACIONES-TERCER BIMESTRE
B3: NOMBRE ALUMNA-ALUMNO | C3: NOTAS | R3: NOTAS | AE3: CALIFICACIÓN TRIMESTRAL | AF3: OBSERVACIONES | AI3: NOMBRE ALUMNA-ALUMNO | AK3: NOTAS | AY3: NOTAS | BM3: PROMEDIO | BN3: OBSERVACIONES | BQ3: NOMBRE ALUMNA-ALUMNO | BS3: NOTAS | CG3: NOTAS | CU3: PROMEDIO | CV3: OBSERVACIONES
A5: 1 | B5: =IF(MAESTRO!B5="","",MAESTRO!B5) | AE5: =IF(MAESTRO!B5="","",IFERROR(TRUNC(AVERAGE(C5:AD5),1),"")) | AG5: 1 | AH5: 1 | AI5: =IF(MAESTRO!B5="","",MAESTRO!B5) | BM5: =IF(MAESTRO!B5="","",IFERROR(TRUNC(AVERAGE(AK5:BL5),1),"")) | BO5: 1 | BP5: 1 | BQ5: =IF(MAESTRO!B5="","",MAESTRO!B5) | CU5: =IF(MAESTRO!B5="","",IFERROR(TRUNC(AVERAGE(BS5:CT5),1),"")) | CW5: 1
A6: 2 | B6: =IF(MAESTRO!B6="","",MAESTRO!B6) | AE6: =IF(MAESTRO!B6="","",IFERROR(TRUNC(AVERAGE(C6:AD6),1),"")) | AG6: 2 | AH6: 2 | AI6: =IF(MAESTRO!B6="","",MAESTRO!B6) | BM6: =IF(MAESTRO!B6="","",IFERROR(TRUNC(AVERAGE(AK6:BL6),1),"")) | BO6: 2 | BP6: 2 | BQ6: =IF(MAESTRO!B6="","",MAESTRO!B6) | CU6: =IF(MAESTRO!B6="","",IFERROR(TRUNC(AVERAGE(BS6:CT6),1),"")) | CW6: 2
A7: 3 | B7: =IF(MAESTRO!B7="","",MAESTRO!B7) | AE7: =IF(MAESTRO!B7="","",IFERROR(TRUNC(AVERAGE(C7:AD7),1),"")) | AG7: 3 | AH7: 3 | AI7: =IF(MAESTRO!B7="","",MAESTRO!B7) | BM7: =IF(MAESTRO!B7="","",IFERROR(TRUNC(AVERAGE(AK7:BL7),1),"")) | BO7: 3 | BP7: 3 | BQ7: =IF(MAESTRO!B7="","",MAESTRO!B7) | CU7: =IF(MAESTRO!B7="","",IFERROR(TRUNC(AVERAGE(BS7:CT7),1),"")) | CW7: 3
A8: 4 | B8: =IF(MAESTRO!B8="","",MAESTRO!B8) | AE8: =IF(MAESTRO!B8="","",IFERROR(TRUNC(AVERAGE(C8:AD8),1),"")) | AG8: 4 | AH8: 4 | AI8: =IF(MAESTRO!B8="","",MAESTRO!B8) | BM8: =IF(MAESTRO!B8="","",IFERROR(TRUNC(AVERAGE(AK8:BL8),1),"")) | BO8: 4 | BP8: 4 | BQ8: =IF(MAESTRO!B8="","",MAESTRO!B8) | CU8: =IF(MAESTRO!B8="","",IFERROR(TRUNC(AVERAGE(BS8:CT8),1),"")) | CW8: 4
A9: 5 | B9: =IF(MAESTRO!B9="","",MAESTRO!B9) | AE9: =IF(MAESTRO!B9="","",IFERROR(TRUNC(AVERAGE(C9:AD9),1),"")) | AG9: 5 | AH9: 5 | AI9: =IF(MAESTRO!B9="","",MAESTRO!B9) | BM9: =IF(MAESTRO!B9="","",IFERROR(TRUNC(AVERAGE(AK9:BL9),1),"")) | BO9: 5 | BP9: 5 | BQ9: =IF(MAESTRO!B9="","",MAESTRO!B9) | CU9: =IF(MAESTRO!B9="","",IFERROR(TRUNC(AVERAGE(BS9:CT9),1),"")) | CW9: 5
A10: 6 | B10: =IF(MAESTRO!B10="","",MAESTRO!B10) | AE10: =IF(MAESTRO!B10="","",IFERROR(TRUNC(AVERAGE(C10:AD10),1),"")) | AG10: 6 | AH10: 6 | AI10: =IF(MAESTRO!B10="","",MAESTRO!B10) | BM10: =IF(MAESTRO!B10="","",IFERROR(TRUNC(AVERAGE(AK10:BL10),1),"")) | BO10: 6 | BP10: 6 | BQ10: =IF(MAESTRO!B10="","",MAESTRO!B10) | CU10: =IF(MAESTRO!B10="","",IFERROR(TRUNC(AVERAGE(BS10:CT10),1),"")) | CW10: 6
A11: 7 | B11: =IF(MAESTRO!B11="","",MAESTRO!B11) | AE11: =IF(MAESTRO!B11="","",IFERROR(TRUNC(AVERAGE(C11:AD11),1),"")) | AG11: 7 | AH11: 7 | AI11: =IF(MAESTRO!B11="","",MAESTRO!B11) | BM11: =IF(MAESTRO!B11="","",IFERROR(TRUNC(AVERAGE(AK11:BL11),1),"")) | BO11: 7 | BP11: 7 | BQ11: =IF(MAESTRO!B11="","",MAESTRO!B11) | CU11: =IF(MAESTRO!B11="","",IFERROR(TRUNC(AVERAGE(BS11:CT11),1),"")) | CW11: 7
A12: 8 | B12: =IF(MAESTRO!B12="","",MAESTRO!B12) | AE12: =IF(MAESTRO!B12="","",IFERROR(TRUNC(AVERAGE(C12:AD12),1),"")) | AG12: 8 | AH12: 8 | AI12: =IF(MAESTRO!B12="","",MAESTRO!B12) | BM12: =IF(MAESTRO!B12="","",IFERROR(TRUNC(AVERAGE(AK12:BL12),1),"")) | BO12: 8 | BP12: 8 | BQ12: =IF(MAESTRO!B12="","",MAESTRO!B12) | CU12: =IF(MAESTRO!B12="","",IFERROR(TRUNC(AVERAGE(BS12:CT12),1),"")) | CW12: 8
A13: 9 | B13: =IF(MAESTRO!B13="","",MAESTRO!B13) | AE13: =IF(MAESTRO!B13="","",IFERROR(TRUNC(AVERAGE(C13:AD13),1),"")) | AG13: 9 | AH13: 9 | AI13: =IF(MAESTRO!B13="","",MAESTRO!B13) | BM13: =IF(MAESTRO!B13="","",IFERROR(TRUNC(AVERAGE(AK13:BL13),1),"")) | BO13: 9 | BP13: 9 | BQ13: =IF(MAESTRO!B13="","",MAESTRO!B13) | CU13: =IF(MAESTRO!B13="","",IFERROR(TRUNC(AVERAGE(BS13:CT13),1),"")) | CW13: 9
A14: 10 | B14: =IF(MAESTRO!B14="","",MAESTRO!B14) | AE14: =IF(MAESTRO!B14="","",IFERROR(TRUNC(AVERAGE(C14:AD14),1),"")) | AG14: 10 | AH14: 10 | AI14: =IF(MAESTRO!B14="","",MAESTRO!B14) | BM14: =IF(MAESTRO!B14="","",IFERROR(TRUNC(AVERAGE(AK14:BL14),1),"")) | BO14: 10 | BP14: 10 | BQ14: =IF(MAESTRO!B14="","",MAESTRO!B14) | CU14: =IF(MAESTRO!B14="","",IFERROR(TRUNC(AVERAGE(BS14:CT14),1),"")) | CW14: 10
A15: 11 | B15: =IF(MAESTRO!B15="","",MAESTRO!B15) | AE15: =IF(MAESTRO!B15="","",IFERROR(TRUNC(AVERAGE(C15:AD15),1),"")) | AG15: 11 | AH15: 11 | AI15: =IF(MAESTRO!B15="","",MAESTRO!B15) | BM15: =IF(MAESTRO!B15="","",IFERROR(TRUNC(AVERAGE(AK15:BL15),1),"")) | BO15: 11 | BP15: 11 | BQ15: =IF(MAESTRO!B15="","",MAESTRO!B15) | CU15: =IF(MAESTRO!B15="","",IFERROR(TRUNC(AVERAGE(BS15:CT15),1),"")) | CW15: 11
A16: 12 | B16: =IF(MAESTRO!B16="","",MAESTRO!B16) | AE16: =IF(MAESTRO!B16="","",IFERROR(TRUNC(AVERAGE(C16:AD16),1),"")) | AG16: 12 | AH16: 12 | AI16: =IF(MAESTRO!B16="","",MAESTRO!B16) | BM16: =IF(MAESTRO!B16="","",IFERROR(TRUNC(AVERAGE(AK16:BL16),1),"")) | BO16: 12 | BP16: 12 | BQ16: =IF(MAESTRO!B16="","",MAESTRO!B16) | CU16: =IF(MAESTRO!B16="","",IFERROR(TRUNC(AVERAGE(BS16:CT16),1),"")) | CW16: 12
... A38: 34 | B38: =IF(MAESTRO!B38="","",MAESTRO!B38) | AE38: =IF(MAESTRO!B38="","",IFERROR(TRUNC(AVERAGE(C38:AD38),1),"")) | AG38: 34 | AH38: 34 | AI38: =IF(MAESTRO!B38="","",MAESTRO!B38) | BM38: =IF(MAESTRO!B38="","",IFERROR(TRUNC(AVERAGE(AK38:BL38),1),"")) | BO38: 34 | BP38: 34 | BQ38: =IF(MAESTRO!B38="","",MAESTRO!B38) | CU38: =IF(MAESTRO!B38="","",IFERROR(TRUNC(AVERAGE(BS38:CT38),1),"")) | CW38: 34
A39: 35 | B39: =IF(MAESTRO!#REF!="","",MAESTRO!#REF!) -> #REF! | AE39: =IF(MAESTRO!#REF!="","",IFERROR(TRUNC(AVERAGE(C39:AD39),1),"")) -> #REF! | AG39: 35 | AH39: 35 | AI39: =IF(MAESTRO!#REF!="","",MAESTRO!#REF!) -> #REF! | BM39: =IF(MAESTRO!#REF!="","",IFERROR(TRUNC(AVERAGE(AK39:BL39),1),"")) -> #REF! | BO39: 35 | BP39: 35 | BQ39: =IF(MAESTRO!#REF!="","",MAESTRO!#REF!) -> #REF! | CU39: =IF(MAESTRO!#REF!="","",IFERROR(TRUNC(AVERAGE(BS39:CT39),1),"")) -> #REF! | CW39: 35
A40: 36 | B40: =IF(MAESTRO!#REF!="","",MAESTRO!#REF!) -> #REF! | AE40: =IF(MAESTRO!#REF!="","",IFERROR(TRUNC(AVERAGE(C40:AD40),1),"")) -> #REF! | AG40: 36 | AH40: 36 | AI40: =IF(MAESTRO!#REF!="","",MAESTRO!#REF!) -> #REF! | BM40: =IF(MAESTRO!#REF!="","",IFERROR(TRUNC(AVERAGE(AK40:BL40),1),"")) -> #REF! | BO40: 36 | BP40: 36 | BQ40: =IF(MAESTRO!#REF!="","",MAESTRO!#REF!) -> #REF! | CU40: =IF(MAESTRO!#REF!="","",IFERROR(TRUNC(AVERAGE(CF40,CT40,CQ40),1),"")) -> #REF! | CW40: 36
A41: 37 | B41: =IF(MAESTRO!#REF!="","",MAESTRO!#REF!) -> #REF! | AE41: =IF(MAESTRO!#REF!="","",IFERROR(TRUNC(AVERAGE(C41:AD41),1),"")) -> #REF! | AG41: 37 | AH41: 37 | AI41: =IF(MAESTRO!#REF!="","",MAESTRO!#REF!) -> #REF! | BM41: =IF(MAESTRO!#REF!="","",IFERROR(TRUNC(AVERAGE(AK41:BL41),1),"")) -> #REF! | BO41: 37 | BP41: 37 | BQ41: =IF(MAESTRO!#REF!="","",MAESTRO!#REF!) -> #REF! | CU41: =IF(MAESTRO!#REF!="","",IFERROR(TRUNC(AVERAGE(CF41,CT41,CQ41),1),"")) -> #REF! | CW41: 37
A42: 38 | B42: =IF(MAESTRO!#REF!="","",MAESTRO!#REF!) -> #REF! | AG42: 38 | AH42: 38 | AI42: =IF(MAESTRO!#REF!="","",MAESTRO!#REF!) -> #REF! | BO42: 38 | BP42: 38 | BQ42: =IF(MAESTRO!#REF!="","",MAESTRO!#REF!) -> #REF! | CW42: 38
A43: 39 | B43: =IF(MAESTRO!#REF!="","",MAESTRO!#REF!) -> #REF! | AG43: 39 | AH43: 39 | AI43: =IF(MAESTRO!#REF!="","",MAESTRO!#REF!) -> #REF! | BO43: 39 | BP43: 39 | BQ43: =IF(MAESTRO!#REF!="","",MAESTRO!#REF!) -> #REF! | CW43: 39
A44: 40 | B44: =IF(MAESTRO!#REF!="","",MAESTRO!#REF!) -> #REF! | AG44: 40 | AH44: 40 | AI44: =IF(MAESTRO!#REF!="","",MAESTRO!#REF!) -> #REF! | BO44: 40 | BP44: 40 | BQ44: =IF(MAESTRO!#REF!="","",MAESTRO!#REF!) -> #REF! | CW44: 40
A45: 41 | AG45: 41 | AH45: 41 | BO45: 41 | BP45: 41 | CW45: 41
A46: 42 | AG46: 42 | AH46: 42 | BO46: 42 | BP46: 42 | CW46: 42
A47: 43 | AG47: 43 | AH47: 43 | BO47: 43 | BP47: 43 | CW47: 43
A48: 44 | AG48: 44 | AH48: 44 | BO48: 44 | BP48: 44 | CW48: 44

Sheet Planilla (Ingles) 
B3: MINISTERIO DE EDUCACION
B5: ESCUELA CERRO CACICON
B6: CACICON, COMARCA NGABE BUGLE
B7: INFORME DE CALIFICACIONES, AUSENCIAS Y TARDANZAS
B9: AÑO LECTIVO: | D9: 2026 | I9: GRUPO: | L9: 7°
B11: ASIGNATURA: | D11: INGLES | I11: PROFESOR: | L11: ELMER TUGRI
F13: TRIMESTRES | J13: AUSENCIAS/TARDANZAS | P13: TOTAL FINAL
B14: No | C14: APELLIDO, NOMBRE | E14: CEDULA | F14: I | G14: II | H14: III | I14: NOTA FINAL | J14: I | L14: II | N14: III
J15: A | K15: T | L15: A | M15: T | N15: A | O15: T | P15: A | Q15: T
B16: 1 | C16: =IF(MAESTRO!B5="","",MAESTRO!B5) | E16: =IF(MAESTRO!D5="","",MAESTRO!E5) | F16: =IF(MAESTRO!B5="","",IFERROR('PROM (Ingles)'!AE5,"")) | G16: =IF(MAESTRO!B5="","",IFERROR('PROM (Ingles)'!BM5,"")) | H16: =IF(MAESTRO!B5="","",IFERROR('PROM (Ingles)'!CU5,"")) | I16: =IF(MAESTRO!B5="","",IFERROR(TRUNC(AVERAGE(F16,G16,H16),1),"")) | J16: =IF(MAESTRO!B5="","",IFERROR('Asistencia '!BI3,"")) | K16: =IF(MAESTRO!B5="","",IFERROR('Asistencia '!BJ3,"")) | L16: =IF(MAESTRO!B5="","",IFERROR('Asistencia '!BI46,"")) | M16: =IF(MAESTRO!B5="","",IFERROR('Asistencia '!BJ46,"")) | N16: =IF(MAESTRO!B5="","",IFERROR('Asistencia '!BI89,"")) | O16: =IF(MAESTRO!B5="","",IFERROR('Asistencia '!BJ89,"")) | P16: =SUM(J16,L16,N16) -> 0 | Q16: =SUM(K16,M16,O16) -> 0
B17: 2 | C17: =IF(MAESTRO!B6="","",MAESTRO!B6) | E17: =IF(MAESTRO!D6="","",MAESTRO!E6) | F17: =IF(MAESTRO!B6="","",IFERROR('PROM (Ingles)'!AE6,"")) | G17: =IF(MAESTRO!B6="","",IFERROR('PROM (Ingles)'!BM6,"")) | H17: =IF(MAESTRO!B6="","",IFERROR('PROM (Ingles)'!CU6,"")) | I17: =IF(MAESTRO!B6="","",IFERROR(TRUNC(AVERAGE(F17,G17,H17),1),"")) | J17: =IF(MAESTRO!B6="","",IFERROR('Asistencia '!BI4,"")) | K17: =IF(MAESTRO!B6="","",IFERROR('Asistencia '!BJ4,"")) | L17: =IF(MAESTRO!B6="","",IFERROR('Asistencia '!BI47,"")) | M17: =IF(MAESTRO!B6="","",IFERROR('Asistencia '!BJ47,"")) | N17: =IF(MAESTRO!B6="","",IFERROR('Asistencia '!BI90,"")) | O17: =IF(MAESTRO!B6="","",IFERROR('Asistencia '!BJ90,"")) | P17: =SUM(J17,L17,N17) -> 0 | Q17: =SUM(K17,M17,O17) -> 0
B18: 3 | C18: =IF(MAESTRO!B7="","",MAESTRO!B7) | E18: =IF(MAESTRO!D7="","",MAESTRO!E7) | F18: =IF(MAESTRO!B7="","",IFERROR('PROM (Ingles)'!AE7,"")) | G18: =IF(MAESTRO!B7="","",IFERROR('PROM (Ingles)'!BM7,"")) | H18: =IF(MAESTRO!B7="","",IFERROR('PROM (Ingles)'!CU7,"")) | I18: =IF(MAESTRO!B7="","",IFERROR(TRUNC(AVERAGE(F18,G18,H18),1),"")) | J18: =IF(MAESTRO!B7="","",IFERROR('Asistencia '!BI5,"")) | K18: =IF(MAESTRO!B7="","",IFERROR('Asistencia '!BJ5,"")) | L18: =IF(MAESTRO!B7="","",IFERROR('Asistencia '!BI48,"")) | M18: =IF(MAESTRO!B7="","",IFERROR('Asistencia '!BJ48,"")) | N18: =IF(MAESTRO!B7="","",IFERROR('Asistencia '!BI91,"")) | O18: =IF(MAESTRO!B7="","",IFERROR('Asistencia '!BJ91,"")) | P18: =SUM(J18,L18,N18) -> 0 | Q18: =SUM(K18,M18,O18) -> 0
B19: 4 | C19: =IF(MAESTRO!B8="","",MAESTRO!B8) | E19: =IF(MAESTRO!D8="","",MAESTRO!E8) | F19: =IF(MAESTRO!B8="","",IFERROR('PROM (Ingles)'!AE8,"")) | G19: =IF(MAESTRO!B8="","",IFERROR('PROM (Ingles)'!BM8,"")) | H19: =IF(MAESTRO!B8="","",IFERROR('PROM (Ingles)'!CU8,"")) | I19: =IF(MAESTRO!B8="","",IFERROR(TRUNC(AVERAGE(F19,G19,H19),1),"")) | J19: =IF(MAESTRO!B8="","",IFERROR('Asistencia '!BI6,"")) | K19: =IF(MAESTRO!B8="","",IFERROR('Asistencia '!BJ6,"")) | L19: =IF(MAESTRO!B8="","",IFERROR('Asistencia '!BI49,"")) | M19: =IF(MAESTRO!B8="","",IFERROR('Asistencia '!BJ49,"")) | N19: =IF(MAESTRO!B8="","",IFERROR('Asistencia '!BI92,"")) | O19: =IF(MAESTRO!B8="","",IFERROR('Asistencia '!BJ92,"")) | P19: =SUM(J19,L19,N19) -> 0 | Q19: =SUM(K19,M19,O19) -> 0
B20: 5 | C20: =IF(MAESTRO!B9="","",MAESTRO!B9) | E20: =IF(MAESTRO!D9="","",MAESTRO!E9) | F20: =IF(MAESTRO!B9="","",IFERROR('PROM (Ingles)'!AE9,"")) | G20: =IF(MAESTRO!B9="","",IFERROR('PROM (Ingles)'!BM9,"")) | H20: =IF(MAESTRO!B9="","",IFERROR('PROM (Ingles)'!CU9,"")) | I20: =IF(MAESTRO!B9="","",IFERROR(TRUNC(AVERAGE(F20,G20,H20),1),"")) | J20: =IF(MAESTRO!B9="","",IFERROR('Asistencia '!BI7,"")) | K20: =IF(MAESTRO!B9="","",IFERROR('Asistencia '!BJ7,"")) | L20: =IF(MAESTRO!B9="","",IFERROR('Asistencia '!BI50,"")) | M20: =IF(MAESTRO!B9="","",IFERROR('Asistencia '!BJ50,"")) | N20: =IF(MAESTRO!B9="","",IFERROR('Asistencia '!BI93,"")) | O20: =IF(MAESTRO!B9="","",IFERROR('Asistencia '!BJ93,"")) | P20: =SUM(J20,L20,N20) -> 0 | Q20: =SUM(K20,M20,O20) -> 0
B21: 6 | C21: =IF(MAESTRO!B10="","",MAESTRO!B10) | E21: =IF(MAESTRO!D10="","",MAESTRO!E10) | F21: =IF(MAESTRO!B10="","",IFERROR('PROM (Ingles)'!AE10,"")) | G21: =IF(MAESTRO!B10="","",IFERROR('PROM (Ingles)'!BM10,"")) | H21: =IF(MAESTRO!B10="","",IFERROR('PROM (Ingles)'!CU10,"")) | I21: =IF(MAESTRO!B10="","",IFERROR(TRUNC(AVERAGE(F21,G21,H21),1),"")) | J21: =IF(MAESTRO!B10="","",IFERROR('Asistencia '!BI8,"")) | K21: =IF(MAESTRO!B10="","",IFERROR('Asistencia '!BJ8,"")) | L21: =IF(MAESTRO!B10="","",IFERROR('Asistencia '!BI51,"")) | M21: =IF(MAESTRO!B10="","",IFERROR('Asistencia '!BJ51,"")) | N21: =IF(MAESTRO!B10="","",IFERROR('Asistencia '!BI94,"")) | O21: =IF(MAESTRO!B10="","",IFERROR('Asistencia '!BJ94,"")) | P21: =SUM(J21,L21,N21) -> 0 | Q21: =SUM(K21,M21,O21) -> 0
B22: 7 | C22: =IF(MAESTRO!B11="","",MAESTRO!B11) | E22: =IF(MAESTRO!D11="","",MAESTRO!E11) | F22: =IF(MAESTRO!B11="","",IFERROR('PROM (Ingles)'!AE11,"")) | G22: =IF(MAESTRO!B11="","",IFERROR('PROM (Ingles)'!BM11,"")) | H22: =IF(MAESTRO!B11="","",IFERROR('PROM (Ingles)'!CU11,"")) | I22: =IF(MAESTRO!B11="","",IFERROR(TRUNC(AVERAGE(F22,G22,H22),1),"")) | J22: =IF(MAESTRO!B11="","",IFERROR('Asistencia '!BI9,"")) | K22: =IF(MAESTRO!B11="","",IFERROR('Asistencia '!BJ9,"")) | L22: =IF(MAESTRO!B11="","",IFERROR('Asistencia '!BI52,"")) | M22: =IF(MAESTRO!B11="","",IFERROR('Asistencia '!BJ52,"")) | N22: =IF(MAESTRO!B11="","",IFERROR('Asistencia '!BI95,"")) | O22: =IF(MAESTRO!B11="","",IFERROR('Asistencia '!BJ95,"")) | P22: =SUM(J22,L22,N22) -> 0 | Q22: =SUM(K22,M22,O22) -> 0
B23: 8 | C23: =IF(MAESTRO!B12="","",MAESTRO!B12) | E23: =IF(MAESTRO!D12="","",MAESTRO!E12) | F23: =IF(MAESTRO!B12="","",IFERROR('PROM (Ingles)'!AE12,"")) | G23: =IF(MAESTRO!B12="","",IFERROR('PROM (Ingles)'!BM12,"")) | H23: =IF(MAESTRO!B12="","",IFERROR('PROM (Ingles)'!CU12,"")) | I23: =IF(MAESTRO!B12="","",IFERROR(TRUNC(AVERAGE(F23,G23,H23),1),"")) | J23: =IF(MAESTRO!B12="","",IFERROR('Asistencia '!BI10,"")) | K23: =IF(MAESTRO!B12="","",IFERROR('Asistencia '!BJ10,"")) | L23: =IF(MAESTRO!B12="","",IFERROR('Asistencia '!BI53,"")) | M23: =IF(MAESTRO!B12="","",IFERROR('Asistencia '!BJ53,"")) | N23: =IF(MAESTRO!B12="","",IFERROR('Asistencia '!BI96,"")) | O23: =IF(MAESTRO!B12="","",IFERROR('Asistencia '!BJ96,"")) | P23: =SUM(J23,L23,N23) -> 0 | Q23: =SUM(K23,M23,O23) -> 0
B24: 9 | C24: =IF(MAESTRO!B13="","",MAESTRO!B13) | E24: =IF(MAESTRO!D13="","",MAESTRO!E13) | F24: =IF(MAESTRO!B13="","",IFERROR('PROM (Ingles)'!AE13,"")) | G24: =IF(MAESTRO!B13="","",IFERROR('PROM (Ingles)'!BM13,"")) | H24: =IF(MAESTRO!B13="","",IFERROR('PROM (Ingles)'!CU13,"")) | I24: =IF(MAESTRO!B13="","",IFERROR(TRUNC(AVERAGE(F24,G24,H24),1),"")) | J24: =IF(MAESTRO!B13="","",IFERROR('Asistencia '!BI11,"")) | K24: =IF(MAESTRO!B13="","",IFERROR('Asistencia '!BJ11,"")) | L24: =IF(MAESTRO!B13="","",IFERROR('Asistencia '!BI54,"")) | M24: =IF(MAESTRO!B13="","",IFERROR('Asistencia '!BJ54,"")) | N24: =IF(MAESTRO!B13="","",IFERROR('Asistencia '!BI97,"")) | O24: =IF(MAESTRO!B13="","",IFERROR('Asistencia '!BJ97,"")) | P24: =SUM(J24,L24,N24) -> 0 | Q24: =SUM(K24,M24,O24) -> 0
B25: 10 | C25: =IF(MAESTRO!B14="","",MAESTRO!B14) | E25: =IF(MAESTRO!D14="","",MAESTRO!E14) | F25: =IF(MAESTRO!B14="","",IFERROR('PROM (Ingles)'!AE14,"")) | G25: =IF(MAESTRO!B14="","",IFERROR('PROM (Ingles)'!BM14,"")) | H25: =IF(MAESTRO!B14="","",IFERROR('PROM (Ingles)'!CU14,"")) | I25: =IF(MAESTRO!B14="","",IFERROR(TRUNC(AVERAGE(F25,G25,H25),1),"")) | J25: =IF(MAESTRO!B14="","",IFERROR('Asistencia '!BI12,"")) | K25: =IF(MAESTRO!B14="","",IFERROR('Asistencia '!BJ12,"")) | L25: =IF(MAESTRO!B14="","",IFERROR('Asistencia '!BI55,"")) | M25: =IF(MAESTRO!B14="","",IFERROR('Asistencia '!BJ55,"")) | N25: =IF(MAESTRO!B14="","",IFERROR('Asistencia '!BI98,"")) | O25: =IF(MAESTRO!B14="","",IFERROR('Asistencia '!BJ98,"")) | P25: =SUM(J25,L25,N25) -> 0 | Q25: =SUM(K25,M25,O25) -> 0
B26: 11 | C26: =IF(MAESTRO!B15="","",MAESTRO!B15) | E26: =IF(MAESTRO!D15="","",MAESTRO!E15) | F26: =IF(MAESTRO!B15="","",IFERROR('PROM (Ingles)'!AE15,"")) | G26: =IF(MAESTRO!B15="","",IFERROR('PROM (Ingles)'!BM15,"")) | H26: =IF(MAESTRO!B15="","",IFERROR('PROM (Ingles)'!CU15,"")) | I26: =IF(MAESTRO!B15="","",IFERROR(TRUNC(AVERAGE(F26,G26,H26),1),"")) | J26: =IF(MAESTRO!B15="","",IFERROR('Asistencia '!BI13,"")) | K26: =IF(MAESTRO!B15="","",IFERROR('Asistencia '!BJ13,"")) | L26: =IF(MAESTRO!B15="","",IFERROR('Asistencia '!BI56,"")) | M26: =IF(MAESTRO!B15="","",IFERROR('Asistencia '!BJ56,"")) | N26: =IF(MAESTRO!B15="","",IFERROR('Asistencia '!BI99,"")) | O26: =IF(MAESTRO!B15="","",IFERROR('Asistencia '!BJ99,"")) | P26: =SUM(J26,L26,N26) -> 0 | Q26: =SUM(K26,M26,O26) -> 0
B27: 12 | C27: =IF(MAESTRO!B16="","",MAESTRO!B16) | E27: =IF(MAESTRO!D16="","",MAESTRO!E16) | F27: =IF(MAESTRO!B16="","",IFERROR('PROM (Ingles)'!AE16,"")) | G27: =IF(MAESTRO!B16="","",IFERROR('PROM (Ingles)'!BM16,"")) | H27: =IF(MAESTRO!B16="","",IFERROR('PROM (Ingles)'!CU16,"")) | I27: =IF(MAESTRO!B16="","",IFERROR(TRUNC(AVERAGE(F27,G27,H27),1),"")) | J27: =IF(MAESTRO!B16="","",IFERROR('Asistencia '!BI14,"")) | K27: =IF(MAESTRO!B16="","",IFERROR('Asistencia '!BJ14,"")) | L27: =IF(MAESTRO!B16="","",IFERROR('Asistencia '!BI57,"")) | M27: =IF(MAESTRO!B16="","",IFERROR('Asistencia '!BJ57,"")) | N27: =IF(MAESTRO!B16="","",IFERROR('Asistencia '!BI100,"")) | O27: =IF(MAESTRO!B16="","",IFERROR('Asistencia '!BJ100,"")) | P27: =SUM(J27,L27,N27) -> 0 | Q27: =SUM(K27,M27,O27) -> 0
