Workbook

Sheet MAESTRO
A1: HOJA MAESTRO — ESCUELA CERRO CACICÓN · AÑO LECTIVO 2026
A2: Ingresa aquí los nombres de cada grado. Se copiarán automáticamente a TODAS las hojas.
A3: 7° GRADO | C3: 8° GRADO | E3: 9° GRADO
A4: No. | B4: APELLIDO, NOMBRE | C4: No. | D4: APELLIDO, NOMBRE | E4: No. | F4: APELLIDO, NOMBRE
A5: 1 | C5: 1 | E5: 1
A6: 2 | C6: 2 | E6: 2
A7: 3 | C7: 3 | E7: 3
A8: 4 | C8: 4 | E8: 4
A9: 5 | C9: 5 | E9: 5
A10: 6 | C10: 6 | E10: 6
A11: 7 | C11: 7 | E11: 7
A12: 8 | C12: 8 | E12: 8
A13: 9 | C13: 9 | E13: 9
A14: 10 | C14: 10 | E14: 10
A15: 11 | C15: 11 | E15: 11
A16: 12 | C16: 12 | E16: 12
... A44: 40 | C44: 40 | E44: 40
A46: ⚠ IMPORTANTE: Solo edita esta hoja para nombres. Todas las demás hojas se actualizan automáticamente.

Sheet DASHBOARD
A1: PANEL DE CONTROL ACADÉMICO — ESCUELA CERRO CACICÓN 2026
A2: Actualización automática. Las alertas muestran estudiantes con nota menor a 60 o ausencias elevadas.
A4: 📊 7° Grado | G4: 📊 8° Grado | M4: 📊 9° Grado
A5: Matriculados | D5: =COUNTA(MAESTRO!B5:'MAESTRO'!B44) -> 0 | G5: Matriculados | J5: =COUNTA(MAESTRO!D5:'MAESTRO'!D44) -> 0 | M5: Matriculados | P5: =COUNTA(MAESTRO!F5:'MAESTRO'!F44) -> 0
A6: Aprobados | D6: =COUNTIF(RESUMEN_7°!T5:'RESUMEN_7°'!T44,"✓ APROBADO") -> 0 | G6: Aprobados | J6: =COUNTIF(RESUMEN_8°!T5:'RESUMEN_8°'!T44,"✓ APROBADO") -> 0 | M6: Aprobados | P6: =COUNTIF(RESUMEN_9°!X5:'RESUMEN_9°'!X44,"✓ APROBADO") -> 0
A7: Reprobados | D7: =COUNTIF(RESUMEN_7°!T5:'RESUMEN_7°'!T44,"✗ REPROBADO") -> 0 | G7: Reprobados | J7: =COUNTIF(RESUMEN_8°!T5:'RESUMEN_8°'!T44,"✗ REPROBADO") -> 0 | M7: Reprobados | P7: =COUNTIF(RESUMEN_9°!X5:'RESUMEN_9°'!X44,"✗ REPROBADO") -> 0
A8: Ausencias >5 | D8: =COUNTIF('Asistencia (7°)'!BI3:'Asistencia (7°)'!BI42,">5") -> 0 | G8: Ausencias >5 | J8: =COUNTIF('Asistencia (8°)'!BI3:'Asistencia (8°)'!BI42,">5") -> 0 | M8: Ausencias >5 | P8: =COUNTIF('Asistencia (9°)'!BI3:'Asistencia (9°)'!BI42,">5") -> 0
A10: LEYENDA DE ALERTAS EN LOS CUADROS DE NOTAS
A11: 🔴 Nota menor de 3.0 → REPROBADO
A12: 🟡 Nota entre 3.0 y 3.4 → En riesgo
A13: 🟢 Nota mayor o igual a 4.5 → Excelente
A14: ℹ Celda vacía → Nota no ingresada aún
A16: ⚠ ESTUDIANTES EN RIESGO (nota final Tecnología o Inglés < 3.0)
A17: GRADO | B17: No. | C17: APELLIDO, NOMBRE | D17: INGLÉS FINAL | E17: TECNOLOGÍA FINAL | F17: AUSENCIAS | G17: ESTADO
A18: 7° | B18: =RESUMEN_7°!A5 -> 1 | C18: =RESUMEN_7°!B5 -> 0 | D18: =IFERROR(RESUMEN_7°!F5,"") | E18: =IFERROR(RESUMEN_7°!R5,"") | F18: =IFERROR('Asistencia (7°)'!BI3,"") -> 0 | G18: =IF(AND(RESUMEN_7°!B5=""),"",IF(OR(IFERROR(RESUMEN_7°!F5,0)<3,IFERROR(RESUMEN_7°!R5,0)<3),"⚠ REVISAR","OK")) -> OK
A19: 7° | B19: =RESUMEN_7°!A6 -> 2 | C19: =RESUMEN_7°!B6 -> 0 | D19: =IF(C19="","",IFERROR(RESUMEN_7°!F6,"")) | E19: =IF(C19="","",IFERROR(RESUMEN_7°!R6,"")) | F19: =IF(C19="","",IFERROR('Asistencia (7°)'!BI4,"")) -> 0 | G19: =IF(AND(RESUMEN_7°!B6=""),"",IF(OR(IFERROR(RESUMEN_7°!F6,0)<3,IFERROR(RESUMEN_7°!R6,0)<3),"⚠ REVISAR","OK")) -> OK
A20: 7° | B20: =RESUMEN_7°!A7 -> 3 | C20: =RESUMEN_7°!B7 -> 0 | D20: =IF(C20="","",IFERROR(RESUMEN_7°!F7,"")) | E20: =IF(C20="","",IFERROR(RESUMEN_7°!R7,"")) | F20: =IF(C20="","",IFERROR('Asistencia (7°)'!BI5,"")) -> 0 | G20: =IF(AND(RESUMEN_7°!B7=""),"",IF(OR(IFERROR(RESUMEN_7°!F7,0)<3,IFERROR(RESUMEN_7°!R7,0)<3),"⚠ REVISAR","OK")) -> OK
A21: 7° | B21: =RESUMEN_7°!A8 -> 4 | C21: =RESUMEN_7°!B8 -> 0 | D21: =IF(C21="","",IFERROR(RESUMEN_7°!F8,"")) | E21: =IF(C21="","",IFERROR(RESUMEN_7°!R8,"")) | F21: =IF(C21="","",IFERROR('Asistencia (7°)'!BI6,"")) -> 0 | G21: =IF(AND(RESUMEN_7°!B8=""),"",IF(OR(IFERROR(RESUMEN_7°!F8,0)<3,IFERROR(RESUMEN_7°!R8,0)<3),"⚠ REVISAR","OK")) -> OK
A22: 7° | B22: =RESUMEN_7°!A9 -> 5 | C22: =RESUMEN_7°!B9 -> 0 | D22: =IF(C22="","",IFERROR(RESUMEN_7°!F9,"")) | E22: =IF(C22="","",IFERROR(RESUMEN_7°!R9,"")) | F22: =IF(C22="","",IFERROR('Asistencia (7°)'!BI7,"")) -> 0 | G22: =IF(AND(RESUMEN_7°!B9=""),"",IF(OR(IFERROR(RESUMEN_7°!F9,0)<3,IFERROR(RESUMEN_7°!R9,0)<3),"⚠ REVISAR","OK")) -> OK
A23: 7° | B23: =RESUMEN_7°!A10 -> 6 | C23: =RESUMEN_7°!B10 -> 0 | D23: =IF(C23="","",IFERROR(RESUMEN_7°!F10,"")) | E23: =IF(C23="","",IFERROR(RESUMEN_7°!R10,"")) | F23: =IF(C23="","",IFERROR('Asistencia (7°)'!BI8,"")) -> 0 | G23: =IF(AND(RESUMEN_7°!B10=""),"",IF(OR(IFERROR(RESUMEN_7°!F10,0)<3,IFERROR(RESUMEN_7°!R10,0)<3),"⚠ REVISAR","OK")) -> OK
A24: 7° | B24: =RESUMEN_7°!A11 -> 7 | C24: =RESUMEN_7°!B11 -> 0 | D24: =IF(C24="","",IFERROR(RESUMEN_7°!F11,"")) | E24: =IF(C24="","",IFERROR(RESUMEN_7°!R11,"")) | F24: =IF(C24="","",IFERROR('Asistencia (7°)'!BI9,"")) -> 0 | G24: =IF(AND(RESUMEN_7°!B11=""),"",IF(OR(IFERROR(RESUMEN_7°!F11,0)<3,IFERROR(RESUMEN_7°!R11,0)<3),"⚠ REVISAR","OK")) -> OK
A25: 7° | B25: =RESUMEN_7°!A12 -> 8 | C25: =RESUMEN_7°!B12 -> 0 | D25: =IF(C25="","",IFERROR(RESUMEN_7°!F12,"")) | E25: =IF(C25="","",IFERROR(RESUMEN_7°!R12,"")) | F25: =IF(C25="","",IFERROR('Asistencia (7°)'!BI10,"")) -> 0 | G25: =IF(AND(RESUMEN_7°!B12=""),"",IF(OR(IFERROR(RESUMEN_7°!F12,0)<3,IFERROR(RESUMEN_7°!R12,0)<3),"⚠ REVISAR","OK")) -> OK
A26: 7° | B26: =RESUMEN_7°!A13 -> 9 | C26: =RESUMEN_7°!B13 -> 0 | D26: =IF(C26="","",IFERROR(RESUMEN_7°!F13,"")) | E26: =IF(C26="","",IFERROR(RESUMEN_7°!R13,"")) | F26: =IF(C26="","",IFERROR('Asistencia (7°)'!BI11,"")) -> 0 | G26: =IF(AND(RESUMEN_7°!B13=""),"",IF(OR(IFERROR(RESUMEN_7°!F13,0)<3,IFERROR(RESUMEN_7°!R13,0)<3),"⚠ REVISAR","OK")) -> OK
A27: 7° | B27: =RESUMEN_7°!A14 -> 10 | C27: =RESUMEN_7°!B14 -> 0 | D27: =IF(C27="","",IFERROR(RESUMEN_7°!F14,"")) | E27: =IF(C27="","",IFERROR(RESUMEN_7°!R14,"")) | F27: =IF(C27="","",IFERROR('Asistencia (7°)'!BI12,"")) -> 0 | G27: =IF(AND(RESUMEN_7°!B14=""),"",IF(OR(IFERROR(RESUMEN_7°!F14,0)<3,IFERROR(RESUMEN_7°!R14,0)<3),"⚠ REVISAR","OK")) -> OK
A28: 7° | B28: =RESUMEN_7°!A15 -> 11 | C28: =RESUMEN_7°!B15 -> 0 | D28: =IF(C28="","",IFERROR(RESUMEN_7°!F15,"")) | E28: =IF(C28="","",IFERROR(RESUMEN_7°!R15,"")) | F28: =IF(C28="","",IFERROR('Asistencia (7°)'!BI13,"")) -> 0 | G28: =IF(AND(RESUMEN_7°!B15=""),"",IF(OR(IFERROR(RESUMEN_7°!F15,0)<3,IFERROR(RESUMEN_7°!R15,0)<3),"⚠ REVISAR","OK")) -> OK
A29: 7° | B29: =RESUMEN_7°!A16 -> 12 | C29: =RESUMEN_7°!B16 -> 0 | D29: =IF(C29="","",IFERROR(RESUMEN_7°!F16,"")) | E29: =IF(C29="","",IFERROR(RESUMEN_7°!R16,"")) | F29: =IF(C29="","",IFERROR('Asistencia (7°)'!BI14,"")) -> 0 | G29: =IF(AND(RESUMEN_7°!B16=""),"",IF(OR(IFERROR(RESUMEN_7°!F16,0)<3,IFERROR(RESUMEN_7°!R16,0)<3),"⚠ REVISAR","OK")) -> OK
A30: 7° | B30: =RESUMEN_7°!A17 -> 13 | C30: =RESUMEN_7°!B17 -> 0 | D30: =IF(C30="","",IFERROR(RESUMEN_7°!F17,"")) | E30: =IF(C30="","",IFERROR(RESUMEN_7°!R17,"")) | F30: =IF(C30="","",IFERROR('Asistencia (7°)'!BI15,"")) -> 0 | G30: =IF(AND(RESUMEN_7°!B17=""),"",IF(OR(IFERROR(RESUMEN_7°!F17,0)<3,IFERROR(RESUMEN_7°!R17,0)<3),"⚠ REVISAR","OK")) -> OK
... A57: 7° | B57: =RESUMEN_7°!A44 -> 40 | C57: =RESUMEN_7°!B44 -> 0 | D57: =IF(C57="","",IFERROR(RESUMEN_7°!F44,"")) | E57: =IF(C57="","",IFERROR(RESUMEN_7°!R44,"")) | F57: =IF(C57="","",IFERROR('Asistencia (7°)'!BI42,"")) -> 0 | G57: =IF(AND(RESUMEN_7°!B44=""),"",IF(OR(IFERROR(RESUMEN_7°!F44,0)<3,IFERROR(RESUMEN_7°!R44,0)<3),"⚠ REVISAR","OK")) -> OK
A58: 8° | B58: =RESUMEN_8°!A5 -> 1 | C58: =RESUMEN_8°!B5 -> 0 | D58: =IF(C58="","",IFERROR(RESUMEN_8°!F5,"")) | E58: =IF(C58="","",IFERROR(RESUMEN_8°!R5,"")) | F58: =IF(C58="","",IFERROR('Asistencia (8°)'!BI3,"")) -> 0 | G58: =IF(AND(RESUMEN_8°!B5=""),"",IF(OR(IFERROR(RESUMEN_8°!F5,0)<3,IFERROR(RESUMEN_8°!R5,0)<3),"⚠ REVISAR","OK")) -> OK
A59: 8° | B59: =RESUMEN_8°!A6 -> 2 | C59: =RESUMEN_8°!B6 -> 0 | D59: =IF(C59="","",IFERROR(RESUMEN_8°!F6,"")) | E59: =IF(C59="","",IFERROR(RESUMEN_8°!R6,"")) | F59: =IF(C59="","",IFERROR('Asistencia (8°)'!BI4,"")) -> 0 | G59: =IF(AND(RESUMEN_8°!B6=""),"",IF(OR(IFERROR(RESUMEN_8°!F6,0)<3,IFERROR(RESUMEN_8°!R6,0)<3),"⚠ REVISAR","OK")) -> OK
A60: 8° | B60: =RESUMEN_8°!A7 -> 3 | C60: =RESUMEN_8°!B7 -> 0 | D60: =IF(C60="","",IFERROR(RESUMEN_8°!F7,"")) | E60: =IF(C60="","",IFERROR(RESUMEN_8°!R7,"")) | F60: =IF(C60="","",IFERROR('Asistencia (8°)'!BI5,"")) -> 0 | G60: =IF(AND(RESUMEN_8°!B7=""),"",IF(OR(IFERROR(RESUMEN_8°!F7,0)<3,IFERROR(RESUMEN_8°!R7,0)<3),"⚠ REVISAR","OK")) -> OK
A61: 8° | B61: =RESUMEN_8°!A8 -> 4 | C61: =RESUMEN_8°!B8 -> 0 | D61: =IF(C61="","",IFERROR(RESUMEN_8°!F8,"")) | E61: =IF(C61="","",IFERROR(RESUMEN_8°!R8,"")) | F61: =IF(C61="","",IFERROR('Asistencia (8°)'!BI6,"")) -> 0 | G61: =IF(AND(RESUMEN_8°!B8=""),"",IF(OR(IFERROR(RESUMEN_8°!F8,0)<3,IFERROR(RESUMEN_8°!R8,0)<3),"⚠ REVISAR","OK")) -> OK
A62: 8° | B62: =RESUMEN_8°!A9 -> 5 | C62: =RESUMEN_8°!B9 -> 0 | D62: =IF(C62="","",IFERROR(RESUMEN_8°!F9,"")) | E62: =IF(C62="","",IFERROR(RESUMEN_8°!R9,"")) | F62: =IF(C62="","",IFERROR('Asistencia (8°)'!BI7,"")) -> 0 | G62: =IF(AND(RESUMEN_8°!B9=""),"",IF(OR(IFERROR(RESUMEN_8°!F9,0)<3,IFERROR(RESUMEN_8°!R9,0)<3),"⚠ REVISAR","OK")) -> OK
A63: 8° | B63: =RESUMEN_8°!A10 -> 6 | C63: =RESUMEN_8°!B10 -> 0 | D63: =IF(C63="","",IFERROR(RESUMEN_8°!F10,"")) | E63: =IF(C63="","",IFERROR(RESUMEN_8°!R10,"")) | F63: =IF(C63="","",IFERROR('Asistencia (8°)'!BI8,"")) -> 0 | G63: =IF(AND(RESUMEN_8°!B10=""),"",IF(OR(IFERROR(RESUMEN_8°!F10,0)<3,IFERROR(RESUMEN_8°!R10,0)<3),"⚠ REVISAR","OK")) -> OK
A64: 8° | B64: =RESUMEN_8°!A11 -> 7 | C64: =RESUMEN_8°!B11 -> 0 | D64: =IF(C64="","",IFERROR(RESUMEN_8°!F11,"")) | E64: =IF(C64="","",IFERROR(RESUMEN_8°!R11,"")) | F64: =IF(C64="","",IFERROR('Asistencia (8°)'!BI9,"")) -> 0 | G64: =IF(AND(RESUMEN_8°!B11=""),"",IF(OR(IFERROR(RESUMEN_8°!F11,0)<3,IFERROR(RESUMEN_8°!R11,0)<3),"⚠ REVISAR","OK")) -> OK
A65: 8° | B65: =RESUMEN_8°!A12 -> 8 | C65: =RESUMEN_8°!B12 -> 0 | D65: =IF(C65="","",IFERROR(RESUMEN_8°!F12,"")) | E65: =IF(C65="","",IFERROR(RESUMEN_8°!R12,"")) | F65: =IF(C65="","",IFERROR('Asistencia (8°)'!BI10,"")) -> 0 | G65: =IF(AND(RESUMEN_8°!B12=""),"",IF(OR(IFERROR(RESUMEN_8°!F12,0)<3,IFERROR(RESUMEN_8°!R12,0)<3),"⚠ REVISAR","OK")) -> OK
A66: 8° | B66: =RESUMEN_8°!A13 -> 9 | C66: =RESUMEN_8°!B13 -> 0 | D66: =IF(C66="","",IFERROR(RESUMEN_8°!F13,"")) | E66: =IF(C66="","",IFERROR(RESUMEN_8°!R13,"")) | F66: =IF(C66="","",IFERROR('Asistencia (8°)'!BI11,"")) -> 0 | G66: =IF(AND(RESUMEN_8°!B13=""),"",IF(OR(IFERROR(RESUMEN_8°!F13,0)<3,IFERROR(RESUMEN_8°!R13,0)<3),"⚠ REVISAR","OK")) -> OK
A67: 8° | B67: =RESUMEN_8°!A14 -> 10 | C67: =RESUMEN_8°!B14 -> 0 | D67: =IF(C67="","",IFERROR(RESUMEN_8°!F14,"")) | E67: =IF(C67="","",IFERROR(RESUMEN_8°!R14,"")) | F67: =IF(C67="","",IFERROR('Asistencia (8°)'!BI12,"")) -> 0 | G67: =IF(AND(RESUMEN_8°!B14=""),"",IF(OR(IFERROR(RESUMEN_8°!F14,0)<3,IFERROR(RESUMEN_8°!R14,0)<3),"⚠ REVISAR","OK")) -> OK
A68: 8° | B68: =RESUMEN_8°!A15 -> 11 | C68: =RESUMEN_8°!B15 -> 0 | D68: =IF(C68="","",IFERROR(RESUMEN_8°!F15,"")) | E68: =IF(C68="","",IFERROR(RESUMEN_8°!R15,"")) | F68: =IF(C68="","",IFERROR('Asistencia (8°)'!BI13,"")) -> 0 | G68: =IF(AND(RESUMEN_8°!B15=""),"",IF(OR(IFERROR(RESUMEN_8°!F15,0)<3,IFERROR(RESUMEN_8°!R15,0)<3),"⚠ REVISAR","OK")) -> OK
A69: 8° | B69: =RESUMEN_8°!A16 -> 12 | C69: =RESUMEN_8°!B16 -> 0 | D69: =IF(C69="","",IFERROR(RESUMEN_8°!F16,"")) | E69: =IF(C69="","",IFERROR(RESUMEN_8°!R16,"")) | F69: =IF(C69="","",IFERROR('Asistencia (8°)'!BI14,"")) -> 0 | G69: =IF(AND(RESUMEN_8°!B16=""),"",IF(OR(IFERROR(RESUMEN_8°!F16,0)<3,IFERROR(RESUMEN_8°!R16,0)<3),"⚠ REVISAR","OK")) -> OK
...

Sheet RESUMEN_7°
A1: CUADRO DE NOTAS FINALES — 7° GRADO · ESCUELA CERRO CACICÓN 2026
A2: Nota: Las calificaciones se obtienen automáticamente de las hojas PROM de cada materia
A3: No. | B3: APELLIDO, NOMBRE | C3: INGLÉS | G3: AGROPECUARIA | K3: HOGAR Y DESARROLLO | O3: TECNOLOGÍA | S3: ESTADO
C4: T1 | D4: T2 | E4: T3 | F4: FINAL | G4: T1 | H4: T2 | I4: T3 | J4: FINAL | K4: T1 | L4: T2 | M4: T3 | N4: FINAL | O4: T1 | P4: T2 | Q4: T3 | R4: FINAL
A5: 1 | B5: =MAESTRO!B5 -> 0 | C5: =IF(MAESTRO!B5="","",IFERROR('PROM (Ingles 7°)'!AE5,"")) | D5: =IF(MAESTRO!B5="","",IFERROR('PROM (Ingles 7°)'!BM5,"")) | E5: =IF(MAESTRO!B5="","",IFERROR('PROM (Ingles 7°)'!CU5,"")) | F5: =IF(MAESTRO!B5="","",IFERROR(TRUNC(AVERAGE(C5,D5,E5),1),"")) | G5: =IF(MAESTRO!B5="","",IFERROR('PROM (Agropecuaria 7°)'!AE5,"")) | H5: =IF(MAESTRO!B5="","",IFERROR('PROM (Agropecuaria 7°)'!BM5,"")) | I5: =IF(MAESTRO!B5="","",IFERROR('PROM (Agropecuaria 7°)'!CU5,"")) | J5: =IF(MAESTRO!B5="","",IFERROR(TRUNC(AVERAGE(G5,H5,I5),1),"")) | K5: =IF(MAESTRO!B5="","",IFERROR('PROM (Hogar y Desarrollo 7°)'!AE5,"")) | L5: =IF(MAESTRO!B5="","",IFERROR('PROM (Hogar y Desarrollo 7°)'!BM5,"")) | M5: =IF(MAESTRO!B5="","",IFERROR('PROM (Hogar y Desarrollo 7°)'!CU5,"")) | N5: =IF(MAESTRO!B5="","",IFERROR(TRUNC(AVERAGE(K5,L5,M5),1),"")) | O5: =IF(MAESTRO!B5="","",IFERROR(AVERAGE(G5,K5),"")) | P5: =IF(MAESTRO!B5="","",IFERROR(AVERAGE(H5,L5),"")) | Q5: =IF(MAESTRO!B5="","",IFERROR(AVERAGE(I5,M5),"")) | R5: =IF(MAESTRO!B5="","",IFERROR(TRUNC(AVERAGE(O5,P5,Q5),1),"")) | S5: =IF(MAESTRO!B5="","",IF(AND(F5="",J5="",N5="",R5=""),"",IF(Y(OR(F5="",F5>=3),OR(J5="",J5>=3),OR(N5="",N5>=3),OR(R5="",R5>=3)),"✓ APROBADO","✗ REPROBADO")))
A6: 2 | B6: =MAESTRO!B6 -> 0 | C6: =IF(MAESTRO!B6="","",IFERROR('PROM (Ingles 7°)'!AE6,"")) | D6: =IF(MAESTRO!B6="","",IFERROR('PROM (Ingles 7°)'!BM6,"")) | E6: =IF(MAESTRO!B6="","",IFERROR('PROM (Ingles 7°)'!CU6,"")) | F6: =IF(MAESTRO!B6="","",IFERROR(TRUNC(AVERAGE(C6,D6,E6),1),"")) | G6: =IF(MAESTRO!B6="","",IFERROR('PROM (Agropecuaria 7°)'!AE6,"")) | H6: =IF(MAESTRO!B6="","",IFERROR('PROM (Agropecuaria 7°)'!BM6,"")) | I6: =IF(MAESTRO!B6="","",IFERROR('PROM (Agropecuaria 7°)'!CU6,"")) | J6: =IF(MAESTRO!B6="","",IFERROR(TRUNC(AVERAGE(G6,H6,I6),1),"")) | K6: =IF(MAESTRO!B6="","",IFERROR('PROM (Hogar y Desarrollo 7°)'!AE6,"")) | L6: =IF(MAESTRO!B6="","",IFERROR('PROM (Hogar y Desarrollo 7°)'!BM6,"")) | M6: =IF(MAESTRO!B6="","",IFERROR('PROM (Hogar y Desarrollo 7°)'!CU6,"")) | N6: =IF(MAESTRO!B6="","",IFERROR(TRUNC(AVERAGE(K6,L6,M6),1),"")) | O6: =IF(MAESTRO!B6="","",IFERROR(AVERAGE(G6,K6),"")) | P6: =IF(MAESTRO!B6="","",IFERROR(AVERAGE(H6,L6),"")) | Q6: =IF(MAESTRO!B6="","",IFERROR(AVERAGE(I6,M6),"")) | R6: =IF(MAESTRO!B6="","",IFERROR(TRUNC(AVERAGE(O6,P6,Q6),1),"")) | S6: =IF(MAESTRO!B6="","",IF(AND(F6="",J6="",N6="",R6=""),"",IF(Y(OR(F6="",F6>=3),OR(J6="",J6>=3),OR(N6="",N6>=3),OR(R6="",R6>=3)),"✓ APROBADO","✗ REPROBADO")))
A7: 3 | B7: =MAESTRO!B7 -> 0 | C7: =IF(MAESTRO!B7="","",IFERROR('PROM (Ingles 7°)'!AE7,"")) | D7: =IF(MAESTRO!B7="","",IFERROR('PROM (Ingles 7°)'!BM7,"")) | E7: =IF(MAESTRO!B7="","",IFERROR('PROM (Ingles 7°)'!CU7,"")) | F7: =IF(MAESTRO!B7="","",IFERROR(TRUNC(AVERAGE(C7,D7,E7),1),"")) | G7: =IF(MAESTRO!B7="","",IFERROR('PROM (Agropecuaria 7°)'!AE7,"")) | H7: =IF(MAESTRO!B7="","",IFERROR('PROM (Agropecuaria 7°)'!BM7,"")) | I7: =IF(MAESTRO!B7="","",IFERROR('PROM (Agropecuaria 7°)'!CU7,"")) | J7: =IF(MAESTRO!B7="","",IFERROR(TRUNC(AVERAGE(G7,H7,I7),1),"")) | K7: =IF(MAESTRO!B7="","",IFERROR('PROM (Hogar y Desarrollo 7°)'!AE7,"")) | L7: =IF(MAESTRO!B7="","",IFERROR('PROM (Hogar y Desarrollo 7°)'!BM7,"")) | M7: =IF(MAESTRO!B7="","",IFERROR('PROM (Hogar y Desarrollo 7°)'!CU7,"")) | N7: =IF(MAESTRO!B7="","",IFERROR(TRUNC(AVERAGE(K7,L7,M7),1),"")) | O7: =IF(MAESTRO!B7="","",IFERROR(AVERAGE(G7,K7),"")) | P7: =IF(MAESTRO!B7="","",IFERROR(AVERAGE(H7,L7),"")) | Q7: =IF(MAESTRO!B7="","",IFERROR(AVERAGE(I7,M7),"")) | R7: =IF(MAESTRO!B7="","",IFERROR(TRUNC(AVERAGE(O7,P7,Q7),1),"")) | S7: =IF(MAESTRO!B7="","",IF(AND(F7="",J7="",N7="",R7=""),"",IF(Y(OR(F7="",F7>=3),OR(J7="",J7>=3),OR(N7="",N7>=3),OR(R7="",R7>=3)),"✓ APROBADO","✗ REPROBADO")))
A8: 4 | B8: =MAESTRO!B8 -> 0 | C8: =IF(MAESTRO!B8="","",IFERROR('PROM (Ingles 7°)'!AE8,"")) | D8: =IF(MAESTRO!B8="","",IFERROR('PROM (Ingles 7°)'!BM8,"")) | E8: =IF(MAESTRO!B8="","",IFERROR('PROM (Ingles 7°)'!CU8,"")) | F8: =IF(MAESTRO!B8="","",IFERROR(TRUNC(AVERAGE(C8,D8,E8),1),"")) | G8: =IF(MAESTRO!B8="","",IFERROR('PROM (Agropecuaria 7°)'!AE8,"")) | H8: =IF(MAESTRO!B8="","",IFERROR('PROM (Agropecuaria 7°)'!BM8,"")) | I8: =IF(MAESTRO!B8="","",IFERROR('PROM (Agropecuaria 7°)'!CU8,"")) | J8: =IF(MAESTRO!B8="","",IFERROR(TRUNC(AVERAGE(G8,H8,I8),1),"")) | K8: =IF(MAESTRO!B8="","",IFERROR('PROM (Hogar y Desarrollo 7°)'!AE8,"")) | L8: =IF(MAESTRO!B8="","",IFERROR('PROM (Hogar y Desarrollo 7°)'!BM8,"")) | M8: =IF(MAESTRO!B8="","",IFERROR('PROM (Hogar y Desarrollo 7°)'!CU8,"")) | N8: =IF(MAESTRO!B8="","",IFERROR(TRUNC(AVERAGE(K8,L8,M8),1),"")) | O8: =IF(MAESTRO!B8="","",IFERROR(AVERAGE(G8,K8),"")) | P8: =IF(MAESTRO!B8="","",IFERROR(AVERAGE(H8,L8),"")) | Q8: =IF(MAESTRO!B8="","",IFERROR(AVERAGE(I8,M8),"")) | R8: =IF(MAESTRO!B8="","",IFERROR(TRUNC(AVERAGE(O8,P8,Q8),1),"")) | S8: =IF(MAESTRO!B8="","",IF(AND(F8="",J8="",N8="",R8=""),"",IF(Y(OR(F8="",F8>=3),OR(J8="",J8>=3),OR(N8="",N8>=3),OR(R8="",R8>=3)),"✓ APROBADO","✗ REPROBADO")))
A9: 5 | B9: =MAESTRO!B9 -> 0 | C9: =IF(MAESTRO!B9="","",IFERROR('PROM (Ingles 7°)'!AE9,"")) | D9: =IF(MAESTRO!B9="","",IFERROR('PROM (Ingles 7°)'!BM9,"")) | E9: =IF(MAESTRO!B9="","",IFERROR('PROM (Ingles 7°)'!CU9,"")) | F9: =IF(MAESTRO!B9="","",IFERROR(TRUNC(AVERAGE(C9,D9,E9),1),"")) | G9: =IF(MAESTRO!B9="","",IFERROR('PROM (Agropecuaria 7°)'!AE9,"")) | H9: =IF(MAESTRO!B9="","",IFERROR('PROM (Agropecuaria 7°)'!BM9,"")) | I9: =IF(MAESTRO!B9="","",IFERROR('PROM (Agropecuaria 7°)'!CU9,"")) | J9: =IF(MAESTRO!B9="","",IFERROR(TRUNC(AVERAGE(G9,H9,I9),1),"")) | K9: =IF(MAESTRO!B9="","",IFERROR('PROM (Hogar y Desarrollo 7°)'!AE9,"")) | L9: =IF(MAESTRO!B9="","",IFERROR('PROM (Hogar y Desarrollo 7°)'!BM9,"")) | M9: =IF(MAESTRO!B9="","",IFERROR('PROM (Hogar y Desarrollo 7°)'!CU9,"")) | N9: =IF(MAESTRO!B9="","",IFERROR(TRUNC(AVERAGE(K9,L9,M9),1),"")) | O9: =IF(MAESTRO!B9="","",IFERROR(AVERAGE(G9,K9),"")) | P9: =IF(MAESTRO!B9="","",IFERROR(AVERAGE(H9,L9),"")) | Q9: =IF(MAESTRO!B9="","",IFERROR(AVERAGE(I9,M9),"")) | R9: =IF(MAESTRO!B9="","",IFERROR(TRUNC(AVERAGE(O9,P9,Q9),1),"")) | S9: =IF(MAESTRO!B9="","",IF(AND(F9="",J9="",N9="",R9=""),"",IF(Y(OR(F9="",F9>=3),OR(J9="",J9>=3),OR(N9="",N9>=3),OR(R9="",R9>=3)),"✓ APROBADO","✗ REPROBADO")))
A10: 6 | B10: =MAESTRO!B10 -> 0 | C10: =IF(MAESTRO!B10="","",IFERROR('PROM (Ingles 7°)'!AE10,"")) | D10: =IF(MAESTRO!B10="","",IFERROR('PROM (Ingles 7°)'!BM10,"")) | E10: =IF(MAESTRO!B10="","",IFERROR('PROM (Ingles 7°)'!CU10,"")) | F10: =IF(MAESTRO!B10="","",IFERROR(TRUNC(AVERAGE(C10,D10,E10),1),"")) | G10: =IF(MAESTRO!B10="","",IFERROR('PROM (Agropecuaria 7°)'!AE10,"")) | H10: =IF(MAESTRO!B10="","",IFERROR('PROM (Agropecuaria 7°)'!BM10,"")) | I10: =IF(MAESTRO!B10="","",IFERROR('PROM (Agropecuaria 7°)'!CU10,"")) | J10: =IF(MAESTRO!B10="","",IFERROR(TRUNC(AVERAGE(G10,H10,I10),1),"")) | K10: =IF(MAESTRO!B10="","",IFERROR('PROM (Hogar y Desarrollo 7°)'!AE10,"")) | L10: =IF(MAESTRO!B10="","",IFERROR('PROM (Hogar y Desarrollo 7°)'!BM10,"")) | M10: =IF(MAESTRO!B10="","",IFERROR('PROM (Hogar y Desarrollo 7°)'!CU10,"")) | N10: =IF(MAESTRO!B10="","",IFERROR(TRUNC(AVERAGE(K10,L10,M10),1),"")) | O10: =IF(MAESTRO!B10="","",IFERROR(AVERAGE(G10,K10),"")) | P10: =IF(MAESTRO!B10="","",IFERROR(AVERAGE(H10,L10),"")) | Q10: =IF(MAESTRO!B10="","",IFERROR(AVERAGE(I10,M10),"")) | R10: =IF(MAESTRO!B10="","",IFERROR(TRUNC(AVERAGE(O10,P10,Q10),1),"")) | S10: =IF(MAESTRO!B10="","",IF(AND(F10="",J10="",N10="",R10=""),"",IF(Y(OR(F10="",F10>=3),OR(J10="",J10>=3),OR(N10="",N10>=3),OR(R10="",R10>=3)),"✓ APROBADO","✗ REPROBADO")))
A11: 7 | B11: =MAESTRO!B11 -> 0 | C11: =IF(MAESTRO!B11="","",IFERROR('PROM (Ingles 7°)'!AE11,"")) | D11: =IF(MAESTRO!B11="","",IFERROR('PROM (Ingles 7°)'!BM11,"")) | E11: =IF(MAESTRO!B11="","",IFERROR('PROM (Ingles 7°)'!CU11,"")) | F11: =IF(MAESTRO!B11="","",IFERROR(TRUNC(AVERAGE(C11,D11,E11),1),"")) | G11: =IF(MAESTRO!B11="","",IFERROR('PROM (Agropecuaria 7°)'!AE11,"")) | H11: =IF(MAESTRO!B11="","",IFERROR('PROM (Agropecuaria 7°)'!BM11,"")) | I11: =IF(MAESTRO!B11="","",IFERROR('PROM (Agropecuaria 7°)'!CU11,"")) | J11: =IF(MAESTRO!B11="","",IFERROR(TRUNC(AVERAGE(G11,H11,I11),1),"")) | K11: =IF(MAESTRO!B11="","",IFERROR('PROM (Hogar y Desarrollo 7°)'!AE11,"")) | L11: =IF(MAESTRO!B11="","",IFERROR('PROM (Hogar y Desarrollo 7°)'!BM11,"")) | M11: =IF(MAESTRO!B11="","",IFERROR('PROM (Hogar y Desarrollo 7°)'!CU11,"")) | N11: =IF(MAESTRO!B11="","",IFERROR(TRUNC(AVERAGE(K11,L11,M11),1),"")) | O11: =IF(MAESTRO!B11="","",IFERROR(AVERAGE(G11,K11),"")) | P11: =IF(MAESTRO!B11="","",IFERROR(AVERAGE(H11,L11),"")) | Q11: =IF(MAESTRO!B11="","",IFERROR(AVERAGE(I11,M11),"")) | R11: =IF(MAESTRO!B11="","",IFERROR(TRUNC(AVERAGE(O11,P11,Q11),1),"")) | S11: =IF(MAESTRO!B11="","",IF(AND(F11="",J11="",N11="",R11=""),"",IF(Y(OR(F11="",F11>=3),OR(J11="",J11>=3),OR(N11="",N11>=3),OR(R11="",R11>=3)),"✓ APROBADO","✗ REPROBADO")))
A12: 8 | B12: =MAESTRO!B12 -> 0 | C12: =IF(MAESTRO!B12="","",IFERROR('PROM (Ingles 7°)'!AE12,"")) | D12: =IF(MAESTRO!B12="","",IFERROR('PROM (Ingles 7°)'!BM12,"")) | E12: =IF(MAESTRO!B12="","",IFERROR('PROM (Ingles 7°)'!CU12,"")) | F12: =IF(MAESTRO!B12="","",IFERROR(TRUNC(AVERAGE(C12,D12,E12),1),"")) | G12: =IF(MAESTRO!B12="","",IFERROR('PROM (Agropecuaria 7°)'!AE12,"")) | H12: =IF(MAESTRO!B12="","",IFERROR('PROM (Agropecuaria 7°)'!BM12,"")) | I12: =IF(MAESTRO!B12="","",IFERROR('PROM (Agropecuaria 7°)'!CU12,"")) | J12: =IF(MAESTRO!B12="","",IFERROR(TRUNC(AVERAGE(G12,H12,I12),1),"")) | K12: =IF(MAESTRO!B12="","",IFERROR('PROM (Hogar y Desarrollo 7°)'!AE12,"")) | L12: =IF(MAESTRO!B12="","",IFERROR('PROM (Hogar y Desarrollo 7°)'!BM12,"")) | M12: =IF(MAESTRO!B12="","",IFERROR('PROM (Hogar y Desarrollo 7°)'!CU12,"")) | N12: =IF(MAESTRO!B12="","",IFERROR(TRUNC(AVERAGE(K12,L12,M12),1),"")) | O12: =IF(MAESTRO!B12="","",IFERROR(AVERAGE(G12,K12),"")) | P12: =IF(MAESTRO!B12="","",IFERROR(AVERAGE(H12,L12),"")) | Q12: =IF(MAESTRO!B12="","",IFERROR(AVERAGE(I12,M12),"")) | R12: =IF(MAESTRO!B12="","",IFERROR(TRUNC(AVERAGE(O12,P12,Q12),1),"")) | S12: =IF(MAESTRO!B12="","",IF(AND(F12="",J12="",N12="",R12=""),"",IF(Y(OR(F12="",F12>=3),OR(J12="",J12>=3),OR(N12="",N12>=3),OR(R12="",R12>=3)),"✓ APROBADO","✗ REPROBADO")))
A13: 9 | B13: =MAESTRO!B13 -> 0 | C13: =IF(MAESTRO!B13="","",IFERROR('PROM (Ingles 7°)'!AE13,"")) | D13: =IF(MAESTRO!B13="","",IFERROR('PROM (Ingles 7°)'!BM13,"")) | E13: =IF(MAESTRO!B13="","",IFERROR('PROM (Ingles 7°)'!CU13,"")) | F13: =IF(MAESTRO!B13="","",IFERROR(TRUNC(AVERAGE(C13,D13,E13),1),"")) | G13: =IF(MAESTRO!B13="","",IFERROR('PROM (Agropecuaria 7°)'!AE13,"")) | H13: =IF(MAESTRO!B13="","",IFERROR('PROM (Agropecuaria 7°)'!BM13,"")) | I13: =IF(MAESTRO!B13="","",IFERROR('PROM (Agropecuaria 7°)'!CU13,"")) | J13: =IF(MAESTRO!B13="","",IFERROR(TRUNC(AVERAGE(G13,H13,I13),1),"")) | K13: =IF(MAESTRO!B13="","",IFERROR('PROM (Hogar y Desarrollo 7°)'!AE13,"")) | L13: =IF(MAESTRO!B13="","",IFERROR('PROM (Hogar y Desarrollo 7°)'!BM13,"")) | M13: =IF(MAESTRO!B13="","",IFERROR('PROM (Hogar y Desarrollo 7°)'!CU13,"")) | N13: =IF(MAESTRO!B13="","",IFERROR(TRUNC(AVERAGE(K13,L13,M13),1),"")) | O13: =IF(MAESTRO!B13="","",IFERROR(AVERAGE(G13,K13),"")) | P13: =IF(MAESTRO!B13="","",IFERROR(AVERAGE(H13,L13),"")) | Q13: =IF(MAESTRO!B13="","",IFERROR(AVERAGE(I13,M13),"")) | R13: =IF(MAESTRO!B13="","",IFERROR(TRUNC(AVERAGE(O13,P13,Q13),1),"")) | S13: =IF(MAESTRO!B13="","",IF(AND(F13="",J13="",N13="",R13=""),"",IF(Y(OR(F13="",F13>=3),OR(J13="",J13>=3),OR(N13="",N13>=3),OR(R13="",R13>=3)),"✓ APROBADO","✗ REPROBADO")))
A14: 10 | B14: =MAESTRO!B14 -> 0 | C14: =IF(MAESTRO!B14="","",IFERROR('PROM (Ingles 7°)'!AE14,"")) | D14: =IF(MAESTRO!B14="","",IFERROR('PROM (Ingles 7°)'!BM14,"")) | E14: =IF(MAESTRO!B14="","",IFERROR('PROM (Ingles 7°)'!CU14,"")) | F14: =IF(MAESTRO!B14="","",IFERROR(TRUNC(AVERAGE(C14,D14,E14),1),"")) | G14: =IF(MAESTRO!B14="","",IFERROR('PROM (Agropecuaria 7°)'!AE14,"")) | H14: =IF(MAESTRO!B14="","",IFERROR('PROM (Agropecuaria 7°)'!BM14,"")) | I14: =IF(MAESTRO!B14="","",IFERROR('PROM (Agropecuaria 7°)'!CU14,"")) | J14: =IF(MAESTRO!B14="","",IFERROR(TRUNC(AVERAGE(G14,H14,I14),1),"")) | K14: =IF(MAESTRO!B14="","",IFERROR('PROM (Hogar y Desarrollo 7°)'!AE14,"")) | L14: =IF(MAESTRO!B14="","",IFERROR('PROM (Hogar y Desarrollo 7°)'!BM14,"")) | M14: =IF(MAESTRO!B14="","",IFERROR('PROM (Hogar y Desarrollo 7°)'!CU14,"")) | N14: =IF(MAESTRO!B14="","",IFERROR(TRUNC(AVERAGE(K14,L14,M14),1),"")) | O14: =IF(MAESTRO!B14="","",IFERROR(AVERAGE(G14,K14),"")) | P14: =IF(MAESTRO!B14="","",IFERROR(AVERAGE(H14,L14),"")) | Q14: =IF(MAESTRO!B14="","",IFERROR(AVERAGE(I14,M14),"")) | R14: =IF(MAESTRO!B14="","",IFERROR(TRUNC(AVERAGE(O14,P14,Q14),1),"")) | S14: =IF(MAESTRO!B14="","",IF(AND(F14="",J14="",N14="",R14=""),"",IF(Y(OR(F14="",F14>=3),OR(J14="",J14>=3),OR(N14="",N14>=3),OR(R14="",R14>=3)),"✓ APROBADO","✗ REPROBADO")))
A15: 11 | B15: =MAESTRO!B15 -> 0 | C15: =IF(MAESTRO!B15="","",IFERROR('PROM (Ingles 7°)'!AE15,"")) | D15: =IF(MAESTRO!B15="","",IFERROR('PROM (Ingles 7°)'!BM15,"")) | E15: =IF(MAESTRO!B15="","",IFERROR('PROM (Ingles 7°)'!CU15,"")) | F15: =IF(MAESTRO!B15="","",IFERROR(TRUNC(AVERAGE(C15,D15,E15),1),"")) | G15: =IF(MAESTRO!B15="","",IFERROR('PROM (Agropecuaria 7°)'!AE15,"")) | H15: =IF(MAESTRO!B15="","",IFERROR('PROM (Agropecuaria 7°)'!BM15,"")) | I15: =IF(MAESTRO!B15="","",IFERROR('PROM (Agropecuaria 7°)'!CU15,"")) | J15: =IF(MAESTRO!B15="","",IFERROR(TRUNC(AVERAGE(G15,H15,I15),1),"")) | K15: =IF(MAESTRO!B15="","",IFERROR('PROM (Hogar y Desarrollo 7°)'!AE15,"")) | L15: =IF(MAESTRO!B15="","",IFERROR('PROM (Hogar y Desarrollo 7°)'!BM15,"")) | M15: =IF(MAESTRO!B15="","",IFERROR('PROM (Hogar y Desarrollo 7°)'!CU15,"")) | N15: =IF(MAESTRO!B15="","",IFERROR(TRUNC(AVERAGE(K15,L15,M15),1),"")) | O15: =IF(MAESTRO!B15="","",IFERROR(AVERAGE(G15,K15),"")) | P15: =IF(MAESTRO!B15="","",IFERROR(AVERAGE(H15,L15),"")) | Q15: =IF(MAESTRO!B15="","",IFERROR(AVERAGE(I15,M15),"")) | R15: =IF(MAESTRO!B15="","",IFERROR(TRUNC(AVERAGE(O15,P15,Q15),1),"")) | S15: =IF(MAESTRO!B15="","",IF(AND(F15="",J15="",N15="",R15=""),"",IF(Y(OR(F15="",F15>=3),OR(J15="",J15>=3),OR(N15="",N15>=3),OR(R15="",R15>=3)),"✓ APROBADO","✗ REPROBADO")))
A16: 12 | B16: =MAESTRO!B16 -> 0 | C16: =IF(MAESTRO!B16="","",IFERROR('PROM (Ingles 7°)'!AE16,"")) | D16: =IF(MAESTRO!B16="","",IFERROR('PROM (Ingles 7°)'!BM16,"")) | E16: =IF(MAESTRO!B16="","",IFERROR('PROM (Ingles 7°)'!CU16,"")) | F16: =IF(MAESTRO!B16="","",IFERROR(TRUNC(AVERAGE(C16,D16,E16),1),"")) | G16: =IF(MAESTRO!B16="","",IFERROR('PROM (Agropecuaria 7°)'!AE16,"")) | H16: =IF(MAESTRO!B16="","",IFERROR('PROM (Agropecuaria 7°)'!BM16,"")) | I16: =IF(MAESTRO!B16="","",IFERROR('PROM (Agropecuaria 7°)'!CU16,"")) | J16: =IF(MAESTRO!B16="","",IFERROR(TRUNC(AVERAGE(G16,H16,I16),1),"")) | K16: =IF(MAESTRO!B16="","",IFERROR('PROM (Hogar y Desarrollo 7°)'!AE16,"")) | L16: =IF(MAESTRO!B16="","",IFERROR('PROM (Hogar y Desarrollo 7°)'!BM16,"")) | M16: =IF(MAESTRO!B16="","",IFERROR('PROM (Hogar y Desarrollo 7°)'!CU16,"")) | N16: =IF(MAESTRO!B16="","",IFERROR(TRUNC(AVERAGE(K16,L16,M16),1),"")) | O16: =IF(MAESTRO!B16="","",IFERROR(AVERAGE(G16,K16),"")) | P16: =IF(MAESTRO!B16="","",IFERROR(AVERAGE(H16,L16),"")) | Q16: =IF(MAESTRO!B16="","",IFERROR(AVERAGE(I16,M16),"")) | R16: =IF(MAESTRO!B16="","",IFERROR(TRUNC(AVERAGE(O16,P16,Q16),1),"")) | S16: =IF(MAESTRO!B16="","",IF(AND(F16="",J16="",N16="",R16=""),"",IF(Y(OR(F16="",F16>=3),OR(J16="",J16>=3),OR(N16="",N16>=3),OR(R16="",R16>=3)),"✓ APROBADO","✗ REPROBADO")))
... A44: 40 | B44: =MAESTRO!B44 -> 0 | C44: =IF(MAESTRO!B44="","",IFERROR('PROM (Ingles 7°)'!AE44,"")) | D44: =IF(MAESTRO!B44="","",IFERROR('PROM (Ingles 7°)'!BM44,"")) | E44: =IF(MAESTRO!B44="","",IFERROR('PROM (Ingles 7°)'!CU44,"")) | F44: =IF(MAESTRO!B44="","",IFERROR(TRUNC(AVERAGE(C44,D44,E44),1),"")) | G44: =IF(MAESTRO!B44="","",IFERROR('PROM (Agropecuaria 7°)'!AE44,"")) | H44: =IF(MAESTRO!B44="","",IFERROR('PROM (Agropecuaria 7°)'!BM44,"")) | I44: =IF(MAESTRO!B44="","",IFERROR('PROM (Agropecuaria 7°)'!CU44,"")) | J44: =IF(MAESTRO!B44="","",IFERROR(TRUNC(AVERAGE(G44,H44,I44),1),"")) | K44: =IF(MAESTRO!B44="","",IFERROR('PROM (Hogar y Desarrollo 7°)'!AE44,"")) | L44: =IF(MAESTRO!B44="","",IFERROR('PROM (Hogar y Desarrollo 7°)'!BM44,"")) | M44: =IF(MAESTRO!B44="","",IFERROR('PROM (Hogar y Desarrollo 7°)'!CU44,"")) | N44: =IF(MAESTRO!B44="","",IFERROR(TRUNC(AVERAGE(K44,L44,M44),1),"")) | O44: =IF(MAESTRO!B44="","",IFERROR(AVERAGE(G44,K44),"")) | P44: =IF(MAESTRO!B44="","",IFERROR(AVERAGE(H44,L44),"")) | Q44: =IF(MAESTRO!B44="","",IFERROR(AVERAGE(I44,M44),"")) | R44: =IF(MAESTRO!B44="","",IFERROR(TRUNC(AVERAGE(O44,P44,Q44),1),"")) | S44: =IF(MAESTRO!B44="","",IF(AND(F44="",J44="",N44="",R44=""),"",IF(Y(OR(F44="",F44>=3),OR(J44="",J44>=3),OR(N44="",N44>=3),OR(R44="",R44>=3)),"✓ APROBADO","✗ REPROBADO")))
A46: PROMEDIO DEL GRUPO | C46: =IFERROR(ROUND(AVERAGEIF(C5:C44,"<>"&""),1),"") | D46: =IFERROR(ROUND(AVERAGEIF(D5:D44,"<>"&""),1),"") | E46: =IFERROR(ROUND(AVERAGEIF(E5:E44,"<>"&""),1),"") | F46: =IFERROR(ROUND(AVERAGEIF(F5:F44,"<>"&""),1),"") | G46: =IFERROR(ROUND(AVERAGEIF(G5:G44,"<>"&""),1),"") | H46: =IFERROR(ROUND(AVERAGEIF(H5:H44,"<>"&""),1),"") | I46: =IFERROR(ROUND(AVERAGEIF(I5:I44,"<>"&""),1),"") | J46: =IFERROR(ROUND(AVERAGEIF(J5:J44,"<>"&""),1),"") | ... R46: =IFERROR(ROUND(AVERAGEIF(R5:R44,"<>"&""),1),"")

Sheet RESUMEN_8°
A1: CUADRO DE NOTAS FINALES — 8° GRADO · ESCUELA CERRO CACICÓN 2026
A2: Nota: Las calificaciones se obtienen automáticamente de las hojas PROM de cada materia
A3: No. | B3: APELLIDO, NOMBRE | C3: INGLÉS | G3: AGROPECUARIA | K3: COMERCIO | O3: TECNOLOGÍA | S3: ESTADO
C4: T1 | D4: T2 | E4: T3 | F4: FINAL | G4: T1 | H4: T2 | I4: T3 | J4: FINAL | K4: T1 | L4: T2 | M4: T3 | N4: FINAL | O4: T1 | P4: T2 | Q4: T3 | R4: FINAL
A5: 1 | B5: =MAESTRO!D5 -> 0 | C5: =IF(MAESTRO!D5="","",IFERROR('PROM (Ingles 8°)'!AE5,"")) | D5: =IF(MAESTRO!D5="","",IFERROR('PROM (Ingles 8°)'!BM5,"")) | E5: =IF(MAESTRO!D5="","",IFERROR('PROM (Ingles 8°)'!CU5,"")) | F5: =IF(MAESTRO!D5="","",IFERROR(TRUNC(AVERAGE(C5,D5,E5),1),"")) | G5: =IF(MAESTRO!D5="","",IFERROR('PROM (Agropecuaria 8°)'!AE5,"")) | H5: =IF(MAESTRO!D5="","",IFERROR('PROM (Agropecuaria 8°)'!BM5,"")) | I5: =IF(MAESTRO!D5="","",IFERROR('PROM (Agropecuaria 8°)'!CU5,"")) | J5: =IF(MAESTRO!D5="","",IFERROR(TRUNC(AVERAGE(G5,H5,I5),1),"")) | K5: =IF(MAESTRO!D5="","",IFERROR('PROM (Comercio 8°)'!AE5,"")) | L5: =IF(MAESTRO!D5="","",IFERROR('PROM (Comercio 8°)'!BM5,"")) | M5: =IF(MAESTRO!D5="","",IFERROR('PROM (Comercio 8°)'!CU5,"")) | N5: =IF(MAESTRO!D5="","",IFERROR(TRUNC(AVERAGE(K5,L5,M5),1),"")) | O5: =IF(MAESTRO!D5="","",IFERROR(AVERAGE(G5,K5),"")) | P5: =IF(MAESTRO!D5="","",IFERROR(AVERAGE(H5,L5),"")) | Q5: =IF(MAESTRO!D5="","",IFERROR(AVERAGE(I5,M5),"")) | R5: =IF(MAESTRO!D5="","",IFERROR(TRUNC(AVERAGE(O5,P5,Q5),1),"")) | S5: =IF(MAESTRO!D5="","",IF(AND(F5="",J5="",N5="",R5=""),"",IF(Y(OR(F5="",F5>=3),OR(J5="",J5>=3),OR(N5="",N5>=3),OR(R5="",R5>=3)),"✓ APROBADO","✗ REPROBADO")))
A6: 2 | B6: =MAESTRO!D6 -> 0 | C6: =IF(MAESTRO!D6="","",IFERROR('PROM (Ingles 8°)'!AE6,"")) | D6: =IF(MAESTRO!D6="","",IFERROR('PROM (Ingles 8°)'!BM6,"")) | E6: =IF(MAESTRO!D6="","",IFERROR('PROM (Ingles 8°)'!CU6,"")) | F6: =IF(MAESTRO!D6="","",IFERROR(TRUNC(AVERAGE(C6,D6,E6),1),"")) | G6: =IF(MAESTRO!D6="","",IFERROR('PROM (Agropecuaria 8°)'!AE6,"")) | H6: =IF(MAESTRO!D6="","",IFERROR('PROM (Agropecuaria 8°)'!BM6,"")) | I6: =IF(MAESTRO!D6="","",IFERROR('PROM (Agropecuaria 8°)'!CU6,"")) | J6: =IF(MAESTRO!D6="","",IFERROR(TRUNC(AVERAGE(G6,H6,I6),1),"")) | K6: =IF(MAESTRO!D6="","",IFERROR('PROM (Comercio 8°)'!AE6,"")) | L6: =IF(MAESTRO!D6="","",IFERROR('PROM (Comercio 8°)'!BM6,"")) | M6: =IF(MAESTRO!D6="","",IFERROR('PROM (Comercio 8°)'!CU6,"")) | N6: =IF(MAESTRO!D6="","",IFERROR(TRUNC(AVERAGE(K6,L6,M6),1),"")) | O6: =IF(MAESTRO!D6="","",IFERROR(AVERAGE(G6,K6),"")) | P6: =IF(MAESTRO!D6="","",IFERROR(AVERAGE(H6,L6),"")) | Q6: =IF(MAESTRO!D6="","",IFERROR(AVERAGE(I6,M6),"")) | R6: =IF(MAESTRO!D6="","",IFERROR(TRUNC(AVERAGE(O6,P6,Q6),1),"")) | S6: =IF(MAESTRO!D6="","",IF(AND(F6="",J6="",N6="",R6=""),"",IF(Y(OR(F6="",F6>=3),OR(J6="",J6>=3),OR(N6="",N6>=3),OR(R6="",R6>=3)),"✓ APROBADO","✗ REPROBADO")))
A7: 3 | B7: =MAESTRO!D7 -> 0 | C7: =IF(MAESTRO!D7="","",IFERROR('PROM (Ingles 8°)'!AE7,"")) | D7: =IF(MAESTRO!D7="","",IFERROR('PROM (Ingles 8°)'!BM7,"")) | E7: =IF(MAESTRO!D7="","",IFERROR('PROM (Ingles 8°)'!CU7,"")) | F7: =IF(MAESTRO!D7="","",IFERROR(TRUNC(AVERAGE(C7,D7,E7),1),"")) | G7: =IF(MAESTRO!D7="","",IFERROR('PROM (Agropecuaria 8°)'!AE7,"")) | H7: =IF(MAESTRO!D7="","",IFERROR('PROM (Agropecuaria 8°)'!BM7,"")) | I7: =IF(MAESTRO!D7="","",IFERROR('PROM (Agropecuaria 8°)'!CU7,"")) | J7: =IF(MAESTRO!D7="","",IFERROR(TRUNC(AVERAGE(G7,H7,I7),1),"")) | K7: =IF(MAESTRO!D7="","",IFERROR('PROM (Comercio 8°)'!AE7,"")) | L7: =IF(MAESTRO!D7="","",IFERROR('PROM (Comercio 8°)'!BM7,"")) | M7: =IF(MAESTRO!D7="","",IFERROR('PROM (Comercio 8°)'!CU7,"")) | N7: =IF(MAESTRO!D7="","",IFERROR(TRUNC(AVERAGE(K7,L7,M7),1),"")) | O7: =IF(MAESTRO!D7="","",IFERROR(AVERAGE(G7,K7),"")) | P7: =IF(MAESTRO!D7="","",IFERROR(AVERAGE(H7,L7),"")) | Q7: =IF(MAESTRO!D7="","",IFERROR(AVERAGE(I7,M7),"")) | R7: =IF(MAESTRO!D7="","",IFERROR(TRUNC(AVERAGE(O7,P7,Q7),1),"")) | S7: =IF(MAESTRO!D7="","",IF(AND(F7="",J7="",N7="",R7=""),"",IF(Y(OR(F7="",F7>=3),OR(J7="",J7>=3),OR(N7="",N7>=3),OR(R7="",R7>=3)),"✓ APROBADO","✗ REPROBADO")))
A8: 4 | B8: =MAESTRO!D8 -> 0 | C8: =IF(MAESTRO!D8="","",IFERROR('PROM (Ingles 8°)'!AE8,"")) | D8: =IF(MAESTRO!D8="","",IFERROR('PROM (Ingles 8°)'!BM8,"")) | E8: =IF(MAESTRO!D8="","",IFERROR('PROM (Ingles 8°)'!CU8,"")) | F8: =IF(MAESTRO!D8="","",IFERROR(TRUNC(AVERAGE(C8,D8,E8),1),"")) | G8: =IF(MAESTRO!D8="","",IFERROR('PROM (Agropecuaria 8°)'!AE8,"")) | H8: =IF(MAESTRO!D8="","",IFERROR('PROM (Agropecuaria 8°)'!BM8,"")) | I8: =IF(MAESTRO!D8="","",IFERROR('PROM (Agropecuaria 8°)'!CU8,"")) | J8: =IF(MAESTRO!D8="","",IFERROR(TRUNC(AVERAGE(G8,H8,I8),1),"")) | K8: =IF(MAESTRO!D8="","",IFERROR('PROM (Comercio 8°)'!AE8,"")) | L8: =IF(MAESTRO!D8="","",IFERROR('PROM (Comercio 8°)'!BM8,"")) | M8: =IF(MAESTRO!D8="","",IFERROR('PROM (Comercio 8°)'!CU8,"")) | N8: =IF(MAESTRO!D8="","",IFERROR(TRUNC(AVERAGE(K8,L8,M8),1),"")) | O8: =IF(MAESTRO!D8="","",IFERROR(AVERAGE(G8,K8),"")) | P8: =IF(MAESTRO!D8="","",IFERROR(AVERAGE(H8,L8),"")) | Q8: =IF(MAESTRO!D8="","",IFERROR(AVERAGE(I8,M8),"")) | R8: =IF(MAESTRO!D8="","",IFERROR(TRUNC(AVERAGE(O8,P8,Q8),1),"")) | S8: =IF(MAESTRO!D8="","",IF(AND(F8="",J8="",N8="",R8=""),"",IF(Y(OR(F8="",F8>=3),OR(J8="",J8>=3),OR(N8="",N8>=3),OR(R8="",R8>=3)),"✓ APROBADO","✗ REPROBADO")))
A9: 5 | B9: =MAESTRO!D9 -> 0 | C9: =IF(MAESTRO!D9="","",IFERROR('PROM (Ingles 8°)'!AE9,"")) | D9: =IF(MAESTRO!D9="","",IFERROR('PROM (Ingles 8°)'!BM9,"")) | E9: =IF(MAESTRO!D9="","",IFERROR('PROM (Ingles 8°)'!CU9,"")) | F9: =IF(MAESTRO!D9="","",IFERROR(TRUNC(AVERAGE(C9,D9,E9),1),"")) | G9: =IF(MAESTRO!D9="","",IFERROR('PROM (Agropecuaria 8°)'!AE9,"")) | H9: =IF(MAESTRO!D9="","",IFERROR('PROM (Agropecuaria 8°)'!BM9,"")) | I9: =IF(MAESTRO!D9="","",IFERROR('PROM (Agropecuaria 8°)'!CU9,"")) | J9: =IF(MAESTRO!D9="","",IFERROR(TRUNC(AVERAGE(G9,H9,I9),1),"")) | K9: =IF(MAESTRO!D9="","",IFERROR('PROM (Comercio 8°)'!AE9,"")) | L9: =IF(MAESTRO!D9="","",IFERROR('PROM (Comercio 8°)'!BM9,"")) | M9: =IF(MAESTRO!D9="","",IFERROR('PROM (Comercio 8°)'!CU9,"")) | N9: =IF(MAESTRO!D9="","",IFERROR(TRUNC(AVERAGE(K9,L9,M9),1),"")) | O9: =IF(MAESTRO!D9="","",IFERROR(AVERAGE(G9,K9),"")) | P9: =IF(MAESTRO!D9="","",IFERROR(AVERAGE(H9,L9),"")) | Q9: =IF(MAESTRO!D9="","",IFERROR(AVERAGE(I9,M9),"")) | R9: =IF(MAESTRO!D9="","",IFERROR(TRUNC(AVERAGE(O9,P9,Q9),1),"")) | S9: =IF(MAESTRO!D9="","",IF(AND(F9="",J9="",N9="",R9=""),"",IF(Y(OR(F9="",F9>=3),OR(J9="",J9>=3),OR(N9="",N9>=3),OR(R9="",R9>=3)),"✓ APROBADO","✗ REPROBADO")))
A10: 6 | B10: =MAESTRO!D10 -> 0 | C10: =IF(MAESTRO!D10="","",IFERROR('PROM (Ingles 8°)'!AE10,"")) | D10: =IF(MAESTRO!D10="","",IFERROR('PROM (Ingles 8°)'!BM10,"")) | E10: =IF(MAESTRO!D10="","",IFERROR('PROM (Ingles 8°)'!CU10,"")) | F10: =IF(MAESTRO!D10="","",IFERROR(TRUNC(AVERAGE(C10,D10,E10),1),"")) | G10: =IF(MAESTRO!D10="","",IFERROR('PROM (Agropecuaria 8°)'!AE10,"")) | H10: =IF(MAESTRO!D10="","",IFERROR('PROM (Agropecuaria 8°)'!BM10,"")) | I10: =IF(MAESTRO!D10="","",IFERROR('PROM (Agropecuaria 8°)'!CU10,"")) | J10: =IF(MAESTRO!D10="","",IFERROR(TRUNC(AVERAGE(G10,H10,I10),1),"")) | K10: =IF(MAESTRO!D10="","",IFERROR('PROM (Comercio 8°)'!AE10,"")) | L10: =IF(MAESTRO!D10="","",IFERROR('PROM (Comercio 8°)'!BM10,"")) | M10: =IF(MAESTRO!D10="","",IFERROR('PROM (Comercio 8°)'!CU10,"")) | N10: =IF(MAESTRO!D10="","",IFERROR(TRUNC(AVERAGE(K10,L10,M10),1),"")) | O10: =IF(MAESTRO!D10="","",IFERROR(AVERAGE(G10,K10),"")) | P10: =IF(MAESTRO!D10="","",IFERROR(AVERAGE(H10,L10),"")) | Q10: =IF(MAESTRO!D10="","",IFERROR(AVERAGE(I10,M10),"")) | R10: =IF(MAESTRO!D10="","",IFERROR(TRUNC(AVERAGE(O10,P10,Q10),1),"")) | S10: =IF(MAESTRO!D10="","",IF(AND(F10="",J10="",N10="",R10=""),"",IF(Y(OR(F10="",F10>=3),OR(J10="",J10>=3),OR(N10="",N10>=3),OR(R10="",R10>=3)),"✓ APROBADO","✗ REPROBADO")))
A11: 7 | B11: =MAESTRO!D11 -> 0 | C11: =IF(MAESTRO!D11="","",IFERROR('PROM (Ingles 8°)'!AE11,"")) | D11: =IF(MAESTRO!D11="","",IFERROR('PROM (Ingles 8°)'!BM11,"")) | E11: =IF(MAESTRO!D11="","",IFERROR('PROM (Ingles 8°)'!CU11,"")) | F11: =IF(MAESTRO!D11="","",IFERROR(TRUNC(AVERAGE(C11,D11,E11),1),"")) | G11: =IF(MAESTRO!D11="","",IFERROR('PROM (Agropecuaria 8°)'!AE11,"")) | H11: =IF(MAESTRO!D11="","",IFERROR('PROM (Agropecuaria 8°)'!BM11,"")) | I11: =IF(MAESTRO!D11="","",IFERROR('PROM (Agropecuaria 8°)'!CU11,"")) | J11: =IF(MAESTRO!D11="","",IFERROR(TRUNC(AVERAGE(G11,H11,I11),1),"")) | K11: =IF(MAESTRO!D11="","",IFERROR('PROM (Comercio 8°)'!AE11,"")) | L11: =IF(MAESTRO!D11="","",IFERROR('PROM (Comercio 8°)'!BM11,"")) | M11: =IF(MAESTRO!D11="","",IFERROR('PROM (Comercio 8°)'!CU11,"")) | N11: =IF(MAESTRO!D11="","",IFERROR(TRUNC(AVERAGE(K11,L11,M11),1),"")) | O11: =IF(MAESTRO!D11="","",IFERROR(AVERAGE(G11,K11),"")) | P11: =IF(MAESTRO!D11="","",IFERROR(AVERAGE(H11,L11),"")) | Q11: =IF(MAESTRO!D11="","",IFERROR(AVERAGE(I11,M11),"")) | R11: =IF(MAESTRO!D11="","",IFERROR(TRUNC(AVERAGE(O11,P11,Q11),1),"")) | S11: =IF(MAESTRO!D11="","",IF(AND(F11="",J11="",N11="",R11=""),"",IF(Y(OR(F11="",F11>=3),OR(J11="",J11>=3),OR(N11="",N11>=3),OR(R11="",R11>=3)),"✓ APROBADO","✗ REPROBADO")))
A12: 8 | B12: =MAESTRO!D12 -> 0 | C12: =IF(MAESTRO!D12="","",IFERROR('PROM (Ingles 8°)'!AE12,"")) | D12: =IF(MAESTRO!D12="","",IFERROR('PROM (Ingles 8°)'!BM12,"")) | E12: =IF(MAESTRO!D12="","",IFERROR('PROM (Ingles 8°)'!CU12,"")) | F12: =IF(MAESTRO!D12="","",IFERROR(TRUNC(AVERAGE(C12,D12,E12),1),"")) | G12: =IF(MAESTRO!D12="","",IFERROR('PROM (Agropecuaria 8°)'!AE12,"")) | H12: =IF(MAESTRO!D12="","",IFERROR('PROM (Agropecuaria 8°)'!BM12,"")) | I12: =IF(MAESTRO!D12="","",IFERROR('PROM (Agropecuaria 8°)'!CU12,"")) | J12: =IF(MAESTRO!D12="","",IFERROR(TRUNC(AVERAGE(G12,H12,I12),1),"")) | K12: =IF(MAESTRO!D12="","",IFERROR('PROM (Comercio 8°)'!AE12,"")) | L12: =IF(MAESTRO!D12="","",IFERROR('PROM (Comercio 8°)'!BM12,"")) | M12: =IF(MAESTRO!D12="","",IFERROR('PROM (Comercio 8°)'!CU12,"")) | N12: =IF(MAESTRO!D12="","",IFERROR(TRUNC(AVERAGE(K12,L12,M12),1),"")) | O12: =IF(MAESTRO!D12="","",IFERROR(AVERAGE(G12,K12),"")) | P12: =IF(MAESTRO!D12="","",IFERROR(AVERAGE(H12,L12),"")) | Q12: =IF(MAESTRO!D12="","",IFERROR(AVERAGE(I12,M12),"")) | R12: =IF(MAESTRO!D12="","",IFERROR(TRUNC(AVERAGE(O12,P12,Q12),1),"")) | S12: =IF(MAESTRO!D12="","",IF(AND(F12="",J12="",N12="",R12=""),"",IF(Y(OR(F12="",F12>=3),OR(J12="",J12>=3),OR(N12="",N12>=3),OR(R12="",R12>=3)),"✓ APROBADO","✗ REPROBADO")))
A13: 9 | B13: =MAESTRO!D13 -> 0 | C13: =IF(MAESTRO!D13="","",IFERROR('PROM (Ingles 8°)'!AE13,"")) | D13: =IF(MAESTRO!D13="","",IFERROR('PROM (Ingles 8°)'!BM13,"")) | E13: =IF(MAESTRO!D13="","",IFERROR('PROM (Ingles 8°)'!CU13,"")) | F13: =IF(MAESTRO!D13="","",IFERROR(TRUNC(AVERAGE(C13,D13,E13),1),"")) | G13: =IF(MAESTRO!D13="","",IFERROR('PROM (Agropecuaria 8°)'!AE13,"")) | H13: =IF(MAESTRO!D13="","",IFERROR('PROM (Agropecuaria 8°)'!BM13,"")) | I13: =IF(MAESTRO!D13="","",IFERROR('PROM (Agropecuaria 8°)'!CU13,"")) | J13: =IF(MAESTRO!D13="","",IFERROR(TRUNC(AVERAGE(G13,H13,I13),1),"")) | K13: =IF(MAESTRO!D13="","",IFERROR('PROM (Comercio 8°)'!AE13,"")) | L13: =IF(MAESTRO!D13="","",IFERROR('PROM (Comercio 8°)'!BM13,"")) | M13: =IF(MAESTRO!D13="","",IFERROR('PROM (Comercio 8°)'!CU13,"")) | N13: =IF(MAESTRO!D13="","",IFERROR(TRUNC(AVERAGE(K13,L13,M13),1),"")) | O13: =IF(MAESTRO!D13="","",IFERROR(AVERAGE(G13,K13),"")) | P13: =IF(MAESTRO!D13="","",IFERROR(AVERAGE(H13,L13),"")) | Q13: =IF(MAESTRO!D13="","",IFERROR(AVERAGE(I13,M13),"")) | R13: =IF(MAESTRO!D13="","",IFERROR(TRUNC(AVERAGE(O13,P13,Q13),1),"")) | S13: =IF(MAESTRO!D13="","",IF(AND(F13="",J13="",N13="",R13=""),"",IF(Y(OR(F13="",F13>=3),OR(J13="",J13>=3),OR(N13="",N13>=3),OR(R13="",R13>=3)),"✓ APROBADO","✗ REPROBADO")))
A14: 10 | B14: =MAESTRO!D14 -> 0 | C14: =IF(MAESTRO!D14="","",IFERROR('PROM (Ingles 8°)'!AE14,"")) | D14: =IF(MAESTRO!D14="","",IFERROR('PROM (Ingles 8°)'!BM14,"")) | E14: =IF(MAESTRO!D14="","",IFERROR('PROM (Ingles 8°)'!CU14,"")) | F14: =IF(MAESTRO!D14="","",IFERROR(TRUNC(AVERAGE(C14,D14,E14),1),"")) | G14: =IF(MAESTRO!D14="","",IFERROR('PROM (Agropecuaria 8°)'!AE14,"")) | H14: =IF(MAESTRO!D14="","",IFERROR('PROM (Agropecuaria 8°)'!BM14,"")) | I14: =IF(MAESTRO!D14="","",IFERROR('PROM (Agropecuaria 8°)'!CU14,"")) | J14: =IF(MAESTRO!D14="","",IFERROR(TRUNC(AVERAGE(G14,H14,I14),1),"")) | K14: =IF(MAESTRO!D14="","",IFERROR('PROM (Comercio 8°)'!AE14,"")) | L14: =IF(MAESTRO!D14="","",IFERROR('PROM (Comercio 8°)'!BM14,"")) | M14: =IF(MAESTRO!D14="","",IFERROR('PROM (Comercio 8°)'!CU14,"")) | N14: =IF(MAESTRO!D14="","",IFERROR(TRUNC(AVERAGE(K14,L14,M14),1),"")) | O14: =IF(MAESTRO!D14="","",IFERROR(AVERAGE(G14,K14),"")) | P14: =IF(MAESTRO!D14="","",IFERROR(AVERAGE(H14,L14),"")) | Q14: =IF(MAESTRO!D14="","",IFERROR(AVERAGE(I14,M14),"")) | R14: =IF(MAESTRO!D14="","",IFERROR(TRUNC(AVERAGE(O14,P14,Q14),1),"")) | S14: =IF(MAESTRO!D14="","",IF(AND(F14="",J14="",N14="",R14=""),"",IF(Y(OR(F14="",F14>=3),OR(J14="",J14>=3),OR(N14="",N14>=3),OR(R14="",R14>=3)),"✓ APROBADO","✗ REPROBADO")))
A15: 11 | B15: =MAESTRO!D15 -> 0 | C15: =IF(MAESTRO!D15="","",IFERROR('PROM (Ingles 8°)'!AE15,"")) | D15: =IF(MAESTRO!D15="","",IFERROR('PROM (Ingles 8°)'!BM15,"")) | E15: =IF(MAESTRO!D15="","",IFERROR('PROM (Ingles 8°)'!CU15,"")) | F15: =IF(MAESTRO!D15="","",IFERROR(TRUNC(AVERAGE(C15,D15,E15),1),"")) | G15: =IF(MAESTRO!D15="","",IFERROR('PROM (Agropecuaria 8°)'!AE15,"")) | H15: =IF(MAESTRO!D15="","",IFERROR('PROM (Agropecuaria 8°)'!BM15,"")) | I15: =IF(MAESTRO!D15="","",IFERROR('PROM (Agropecuaria 8°)'!CU15,"")) | J15: =IF(MAESTRO!D15="","",IFERROR(TRUNC(AVERAGE(G15,H15,I15),1),"")) | K15: =IF(MAESTRO!D15="","",IFERROR('PROM (Comercio 8°)'!AE15,"")) | L15: =IF(MAESTRO!D15="","",IFERROR('PROM (Comercio 8°)'!BM15,"")) | M15: =IF(MAESTRO!D15="","",IFERROR('PROM (Comercio 8°)'!CU15,"")) | N15: =IF(MAESTRO!D15="","",IFERROR(TRUNC(AVERAGE(K15,L15,M15),1),"")) | O15: =IF(MAESTRO!D15="","",IFERROR(AVERAGE(G15,K15),"")) | P15: =IF(MAESTRO!D15="","",IFERROR(AVERAGE(H15,L15),"")) | Q15: =IF(MAESTRO!D15="","",IFERROR(AVERAGE(I15,M15),"")) | R15: =IF(MAESTRO!D15="","",IFERROR(TRUNC(AVERAGE(O15,P15,Q15),1),"")) | S15: =IF(MAESTRO!D15="","",IF(AND(F15="",J15="",N15="",R15=""),"",IF(Y(OR(F15="",F15>=3),OR(J15="",J15>=3),OR(N15="",N15>=3),OR(R15="",R15>=3)),"✓ APROBADO","✗ REPROBADO")))
A16: 12 | B16: =MAESTRO!D16 -> 0 | C16: =IF(MAESTRO!D16="","",IFERROR('PROM (Ingles 8°)'!AE16,"")) | D16: =IF(MAESTRO!D16="","",IFERROR('PROM (Ingles 8°)'!BM16,"")) | E16: =IF(MAESTRO!D16="","",IFERROR('PROM (Ingles 8°)'!CU16,"")) | F16: =IF(MAESTRO!D16="","",IFERROR(TRUNC(AVERAGE(C16,D16,E16),1),"")) | G16: =IF(MAESTRO!D16="","",IFERROR('PROM (Agropecuaria 8°)'!AE16,"")) | H16: =IF(MAESTRO!D16="","",IFERROR('PROM (Agropecuaria 8°)'!BM16,"")) | I16: =IF(MAESTRO!D16="","",IFERROR('PROM (Agropecuaria 8°)'!CU16,"")) | J16: =IF(MAESTRO!D16="","",IFERROR(TRUNC(AVERAGE(G16,H16,I16),1),"")) | K16: =IF(MAESTRO!D16="","",IFERROR('PROM (Comercio 8°)'!AE16,"")) | L16: =IF(MAESTRO!D16="","",IFERROR('PROM (Comercio 8°)'!BM16,"")) | M16: =IF(MAESTRO!D16="","",IFERROR('PROM (Comercio 8°)'!CU16,"")) | N16: =IF(MAESTRO!D16="","",IFERROR(TRUNC(AVERAGE(K16,L16,M16),1),"")) | O16: =IF(MAESTRO!D16="","",IFERROR(AVERAGE(G16,K16),"")) | P16: =IF(MAESTRO!D16="","",IFERROR(AVERAGE(H16,L16),"")) | Q16: =IF(MAESTRO!D16="","",IFERROR(AVERAGE(I16,M16),"")) | R16: =IF(MAESTRO!D16="","",IFERROR(TRUNC(AVERAGE(O16,P16,Q16),1),"")) | S16: =IF(MAESTRO!D16="","",IF(AND(F16="",J16="",N16="",R16=""),"",IF(Y(OR(F16="",F16>=3),OR(J16="",J16>=3),OR(N16="",N16>=3),OR(R16="",R16>=3)),"✓ APROBADO","✗ REPROBADO")))
... A44: 40 | B44: =MAESTRO!D44 -> 0 | C44: =IF(MAESTRO!D44="","",IFERROR('PROM (Ingles 8°)'!AE44,"")) | D44: =IF(MAESTRO!D44="","",IFERROR('PROM (Ingles 8°)'!BM44,"")) | E44: =IF(MAESTRO!D44="","",IFERROR('PROM (Ingles 8°)'!CU44,"")) | F44: =IF(MAESTRO!D44="","",IFERROR(TRUNC(AVERAGE(C44,D44,E44),1),"")) | G44: =IF(MAESTRO!D44="","",IFERROR('PROM (Agropecuaria 8°)'!AE44,"")) | H44: =IF(MAESTRO!D44="","",IFERROR('PROM (Agropecuaria 8°)'!BM44,"")) | I44: =IF(MAESTRO!D44="","",IFERROR('PROM (Agropecuaria 8°)'!CU44,"")) | J44: =IF(MAESTRO!D44="","",IFERROR(TRUNC(AVERAGE(G44,H44,I44),1),"")) | K44: =IF(MAESTRO!D44="","",IFERROR('PROM (Comercio 8°)'!AE44,"")) | L44: =IF(MAESTRO!D44="","",IFERROR('PROM (Comercio 8°)'!BM44,"")) | M44: =IF(MAESTRO!D44="","",IFERROR('PROM (Comercio 8°)'!CU44,"")) | N44: =IF(MAESTRO!D44="","",IFERROR(TRUNC(AVERAGE(K44,L44,M44),1),"")) | O44: =IF(MAESTRO!D44="","",IFERROR(AVERAGE(G44,K44),"")) | P44: =IF(MAESTRO!D44="","",IFERROR(AVERAGE(H44,L44),"")) | Q44: =IF(MAESTRO!D44="","",IFERROR(AVERAGE(I44,M44),"")) | R44: =IF(MAESTRO!D44="","",IFERROR(TRUNC(AVERAGE(O44,P44,Q44),1),"")) | S44: =IF(MAESTRO!D44="","",IF(AND(F44="",J44="",N44="",R44=""),"",IF(Y(OR(F44="",F44>=3),OR(J44="",J44>=3),OR(N44="",N44>=3),OR(R44="",R44>=3)),"✓ APROBADO","✗ REPROBADO")))
A46: PROMEDIO DEL GRUPO | C46: =IFERROR(ROUND(AVERAGEIF(C5:C44,"<>"&""),1),"") | D46: =IFERROR(ROUND(AVERAGEIF(D5:D44,"<>"&""),1),"") | E46: =IFERROR(ROUND(AVERAGEIF(E5:E44,"<>"&""),1),"") | F46: =IFERROR(ROUND(AVERAGEIF(F5:F44,"<>"&""),1),"") | G46: =IFERROR(ROUND(AVERAGEIF(G5:G44,"<>"&""),1),"") | H46: =IFERROR(ROUND(AVERAGEIF(H5:H44,"<>"&""),1),"") | I46: =IFERROR(ROUND(AVERAGEIF(I5:I44,"<>"&""),1),"") | J46: =IFERROR(ROUND(AVERAGEIF(J5:J44,"<>"&""),1),"") | ... R46: =IFERROR(ROUND(AVERAGEIF(R5:R44,"<>"&""),1),"")

Sheet RESUMEN_9°
A1: CUADRO DE NOTAS FINALES — 9° GRADO · ESCUELA CERRO CACICÓN 2026
A2: Nota: Las calificaciones se obtienen automáticamente de las hojas PROM de cada materia
A3: No. | B3: APELLIDO, NOMBRE | C3: INGLÉS | G3: AGROPECUARIA | K3: COMERCIO | O3: TECNOLOGÍA | S3: ED. ARTÍSTICA | W3: ESTADO
C4: T1 | D4: T2 | E4: T3 | F4: FINAL | G4: T1 | H4: T2 | I4: T3 | J4: FINAL | K4: T1 | L4: T2 | M4: T3 | N4: FINAL | O4: T1 | P4: T2 | Q4: T3 | R4: FINAL | S4: T1 | T4: T2 | U4: T3 | V4: FINAL
A5: 1 | B5: =MAESTRO!F5 -> 0 | C5: =IF(MAESTRO!F5="","",IFERROR('PROM (Ingles 9°)'!AE5,"")) | D5: =IF(MAESTRO!F5="","",IFERROR('PROM (Ingles 9°)'!BM5,"")) | E5: =IF(MAESTRO!F5="","",IFERROR('PROM (Ingles 9°)'!CU5,"")) | F5: =IF(MAESTRO!F5="","",IFERROR(TRUNC(AVERAGE(C5,D5,E5),1),"")) | G5: =IF(MAESTRO!F5="","",IFERROR('PROM (Agropecuaria 9°)'!AE5,"")) | H5: =IF(MAESTRO!F5="","",IFERROR('PROM (Agropecuaria 9°)'!BM5,"")) | I5: =IF(MAESTRO!F5="","",IFERROR('PROM (Agropecuaria 9°)'!CU5,"")) | J5: =IF(MAESTRO!F5="","",IFERROR(TRUNC(AVERAGE(G5,H5,I5),1),"")) | K5: =IF(MAESTRO!F5="","",IFERROR('PROM (Comercio 9°)'!AE5,"")) | L5: =IF(MAESTRO!F5="","",IFERROR('PROM (Comercio 9°)'!BM5,"")) | M5: =IF(MAESTRO!F5="","",IFERROR('PROM (Comercio 9°)'!CU5,"")) | N5: =IF(MAESTRO!F5="","",IFERROR(TRUNC(AVERAGE(K5,L5,M5),1),"")) | O5: =IF(MAESTRO!F5="","",IFERROR(AVERAGE(G5,K5),"")) | P5: =IF(MAESTRO!F5="","",IFERROR(AVERAGE(H5,L5),"")) | Q5: =IF(MAESTRO!F5="","",IFERROR(AVERAGE(I5,M5),"")) | R5: =IF(MAESTRO!F5="","",IFERROR(TRUNC(AVERAGE(O5,P5,Q5),1),"")) | S5: =IF(MAESTRO!F5="","",IFERROR('PROM (Artistica 9°)'!AE5,"")) | T5: =IF(MAESTRO!F5="","",IFERROR('PROM (Artistica 9°)'!BM5,"")) | U5: =IF(MAESTRO!F5="","",IFERROR('PROM (Artistica 9°)'!CU5,"")) | V5: =IF(MAESTRO!F5="","",IFERROR(TRUNC(AVERAGE(S5,T5,U5),1),"")) | W5: =IF(MAESTRO!F5="","",IF(AND(F5="",J5="",N5="",R5="",V5=""),"",IF(Y(OR(F5="",F5>=3),OR(J5="",J5>=3),OR(N5="",N5>=3),OR(R5="",R5>=3),OR(V5="",V5>=3)),"✓ APROBADO","✗ REPROBADO")))
A6: 2 | B6: =MAESTRO!F6 -> 0 | C6: =IF(MAESTRO!F6="","",IFERROR('PROM (Ingles 9°)'!AE6,"")) | D6: =IF(MAESTRO!F6="","",IFERROR('PROM (Ingles 9°)'!BM6,"")) | E6: =IF(MAESTRO!F6="","",IFERROR('PROM (Ingles 9°)'!CU6,"")) | F6: =IF(MAESTRO!F6="","",IFERROR(TRUNC(AVERAGE(C6,D6,E6),1),"")) | G6: =IF(MAESTRO!F6="","",IFERROR('PROM (Agropecuaria 9°)'!AE6,"")) | H6: =IF(MAESTRO!F6="","",IFERROR('PROM (Agropecuaria 9°)'!BM6,"")) | I6: =IF(MAESTRO!F6="","",IFERROR('PROM (Agropecuaria 9°)'!CU6,"")) | J6: =IF(MAESTRO!F6="","",IFERROR(TRUNC(AVERAGE(G6,H6,I6),1),"")) | K6: =IF(MAESTRO!F6="","",IFERROR('PROM (Comercio 9°)'!AE6,"")) | L6: =IF(MAESTRO!F6="","",IFERROR('PROM (Comercio 9°)'!BM6,"")) | M6: =IF(MAESTRO!F6="","",IFERROR('PROM (Comercio 9°)'!CU6,"")) | N6: =IF(MAESTRO!F6="","",IFERROR(TRUNC(AVERAGE(K6,L6,M6),1),"")) | O6: =IF(MAESTRO!F6="","",IFERROR(AVERAGE(G6,K6),"")) | P6: =IF(MAESTRO!F6="","",IFERROR(AVERAGE(H6,L6),"")) | Q6: =IF(MAESTRO!F6="","",IFERROR(AVERAGE(I6,M6),"")) | R6: =IF(MAESTRO!F6="","",IFERROR(TRUNC(AVERAGE(O6,P6,Q6),1),"")) | S6: =IF(MAESTRO!F6="","",IFERROR('PROM (Artistica 9°)'!AE6,"")) | T6: =IF(MAESTRO!F6="","",IFERROR('PROM (Artistica 9°)'!BM6,"")) | U6: =IF(MAESTRO!F6="","",IFERROR('PROM (Artistica 9°)'!CU6,"")) | V6: =IF(MAESTRO!F6="","",IFERROR(TRUNC(AVERAGE(S6,T6,U6),1),"")) | W6: =IF(MAESTRO!F6="","",IF(AND(F6="",J6="",N6="",R6="",V6=""),"",IF(Y(OR(F6="",F6>=3),OR(J6="",J6>=3),OR(N6="",N6>=3),OR(R6="",R6>=3),OR(V6="",V6>=3)),"✓ APROBADO","✗ REPROBADO")))
A7: 3 | B7: =MAESTRO!F7 -> 0 | C7: =IF(MAESTRO!F7="","",IFERROR('PROM (Ingles 9°)'!AE7,"")) | D7: =IF(MAESTRO!F7="","",IFERROR('PROM (Ingles 9°)'!BM7,"")) | E7: =IF(MAESTRO!F7="","",IFERROR('PROM (Ingles 9°)'!CU7,"")) | F7: =IF(MAESTRO!F7="","",IFERROR(TRUNC(AVERAGE(C7,D7,E7),1),"")) | G7: =IF(MAESTRO!F7="","",IFERROR('PROM (Agropecuaria 9°)'!AE7,"")) | H7: =IF(MAESTRO!F7="","",IFERROR('PROM (Agropecuaria 9°)'!BM7,"")) | I7: =IF(MAESTRO!F7="","",IFERROR('PROM (Agropecuaria 9°)'!CU7,"")) | J7: =IF(MAESTRO!F7="","",IFERROR(TRUNC(AVERAGE(G7,H7,I7),1),"")) | K7: =IF(MAESTRO!F7="","",IFERROR('PROM (Comercio 9°)'!AE7,"")) | L7: =IF(MAESTRO!F7="","",IFERROR('PROM (Comercio 9°)'!BM7,"")) | M7: =IF(MAESTRO!F7="","",IFERROR('PROM (Comercio 9°)'!CU7,"")) | N7: =IF(MAESTRO!F7="","",IFERROR(TRUNC(AVERAGE(K7,L7,M7),1),"")) | O7: =IF(MAESTRO!F7="","",IFERROR(AVERAGE(G7,K7),"")) | P7: =IF(MAESTRO!F7="","",IFERROR(AVERAGE(H7,L7),"")) | Q7: =IF(MAESTRO!F7="","",IFERROR(AVERAGE(I7,M7),"")) | R7: =IF(MAESTRO!F7="","",IFERROR(TRUNC(AVERAGE(O7,P7,Q7),1),"")) | S7: =IF(MAESTRO!F7="","",IFERROR('PROM (Artistica 9°)'!AE7,"")) | T7: =IF(MAESTRO!F7="","",IFERROR('PROM (Artistica 9°)'!BM7,"")) | U7: =IF(MAESTRO!F7="","",IFERROR('PROM (Artistica 9°)'!CU7,"")) | V7: =IF(MAESTRO!F7="","",IFERROR(TRUNC(AVERAGE(S7,T7,U7),1),"")) | W7: =IF(MAESTRO!F7="","",IF(AND(F7="",J7="",N7="",R7="",V7=""),"",IF(Y(OR(F7="",F7>=3),OR(J7="",J7>=3),OR(N7="",N7>=3),OR(R7="",R7>=3),OR(V7="",V7>=3)),"✓ APROBADO","✗ REPROBADO")))
A8: 4 | B8: =MAESTRO!F8 -> 0 | C8: =IF(MAESTRO!F8="","",IFERROR('PROM (Ingles 9°)'!AE8,"")) | D8: =IF(MAESTRO!F8="","",IFERROR('PROM (Ingles 9°)'!BM8,"")) | E8: =IF(MAESTRO!F8="","",IFERROR('PROM (Ingles 9°)'!CU8,"")) | F8: =IF(MAESTRO!F8="","",IFERROR(TRUNC(AVERAGE(C8,D8,E8),1),"")) | G8: =IF(MAESTRO!F8="","",IFERROR('PROM (Agropecuaria 9°)'!AE8,"")) | H8: =IF(MAESTRO!F8="","",IFERROR('PROM (Agropecuaria 9°)'!BM8,"")) | I8: =IF(MAESTRO!F8="","",IFERROR('PROM (Agropecuaria 9°)'!CU8,"")) | J8: =IF(MAESTRO!F8="","",IFERROR(TRUNC(AVERAGE(G8,H8,I8),1),"")) | K8: =IF(MAESTRO!F8="","",IFERROR('PROM (Comercio 9°)'!AE8,"")) | L8: =IF(MAESTRO!F8="","",IFERROR('PROM (Comercio 9°)'!BM8,"")) | M8: =IF(MAESTRO!F8="","",IFERROR('PROM (Comercio 9°)'!CU8,"")) | N8: =IF(MAESTRO!F8="","",IFERROR(TRUNC(AVERAGE(K8,L8,M8),1),"")) | O8: =IF(MAESTRO!F8="","",IFERROR(AVERAGE(G8,K8),"")) | P8: =IF(MAESTRO!F8="","",IFERROR(AVERAGE(H8,L8),"")) | Q8: =IF(MAESTRO!F8="","",IFERROR(AVERAGE(I8,M8),"")) | R8: =IF(MAESTRO!F8="","",IFERROR(TRUNC(AVERAGE(O8,P8,Q8),1),"")) | S8: =IF(MAESTRO!F8="","",IFERROR('PROM (Artistica 9°)'!AE8,"")) | T8: =IF(MAESTRO!F8="","",IFERROR('PROM (Artistica 9°)'!BM8,"")) | U8: =IF(MAESTRO!F8="","",IFERROR('PROM (Artistica 9°)'!CU8,"")) | V8: =IF(MAESTRO!F8="","",IFERROR(TRUNC(AVERAGE(S8,T8,U8),1),"")) | W8: =IF(MAESTRO!F8="","",IF(AND(F8="",J8="",N8="",R8="",V8=""),"",IF(Y(OR(F8="",F8>=3),OR(J8="",J8>=3),OR(N8="",N8>=3),OR(R8="",R8>=3),OR(V8="",V8>=3)),"✓ APROBADO","✗ REPROBADO")))
A9: 5 | B9: =MAESTRO!F9 -> 0 | C9: =IF(MAESTRO!F9="","",IFERROR('PROM (Ingles 9°)'!AE9,"")) | D9: =IF(MAESTRO!F9="","",IFERROR('PROM (Ingles 9°)'!BM9,"")) | E9: =IF(MAESTRO!F9="","",IFERROR('PROM (Ingles 9°)'!CU9,"")) | F9: =IF(MAESTRO!F9="","",IFERROR(TRUNC(AVERAGE(C9,D9,E9),1),"")) | G9: =IF(MAESTRO!F9="","",IFERROR('PROM (Agropecuaria 9°)'!AE9,"")) | H9: =IF(MAESTRO!F9="","",IFERROR('PROM (Agropecuaria 9°)'!BM9,"")) | I9: =IF(MAESTRO!F9="","",IFERROR('PROM (Agropecuaria 9°)'!CU9,"")) | J9: =IF(MAESTRO!F9="","",IFERROR(TRUNC(AVERAGE(G9,H9,I9),1),"")) | K9: =IF(MAESTRO!F9="","",IFERROR('PROM (Comercio 9°)'!AE9,"")) | L9: =IF(MAESTRO!F9="","",IFERROR('PROM (Comercio 9°)'!BM9,"")) | M9: =IF(MAESTRO!F9="","",IFERROR('PROM (Comercio 9°)'!CU9,"")) | N9: =IF(MAESTRO!F9="","",IFERROR(TRUNC(AVERAGE(K9,L9,M9),1),"")) | O9: =IF(MAESTRO!F9="","",IFERROR(AVERAGE(G9,K9),"")) | P9: =IF(MAESTRO!F9="","",IFERROR(AVERAGE(H9,L9),"")) | Q9: =IF(MAESTRO!F9="","",IFERROR(AVERAGE(I9,M9),"")) | R9: =IF(MAESTRO!F9="","",IFERROR(TRUNC(AVERAGE(O9,P9,Q9),1),"")) | S9: =IF(MAESTRO!F9="","",IFERROR('PROM (Artistica 9°)'!AE9,"")) | T9: =IF(MAESTRO!F9="","",IFERROR('PROM (Artistica 9°)'!BM9,"")) | U9: =IF(MAESTRO!F9="","",IFERROR('PROM (Artistica 9°)'!CU9,"")) | V9: =IF(MAESTRO!F9="","",IFERROR(TRUNC(AVERAGE(S9,T9,U9),1),"")) | W9: =IF(MAESTRO!F9="","",IF(AND(F9="",J9="",N9="",R9="",V9=""),"",IF(Y(OR(F9="",F9>=3),OR(J9="",J9>=3),OR(N9="",N9>=3),OR(R9="",R9>=3),OR(V9="",V9>=3)),"✓ APROBADO","✗ REPROBADO")))
A10: 6 | B10: =MAESTRO!F10 -> 0 | C10: =IF(MAESTRO!F10="","",IFERROR('PROM (Ingles 9°)'!AE10,"")) | D10: =IF(MAESTRO!F10="","",IFERROR('PROM (Ingles 9°)'!BM10,"")) | E10: =IF(MAESTRO!F10="","",IFERROR('PROM (Ingles 9°)'!CU10,"")) | F10: =IF(MAESTRO!F10="","",IFERROR(TRUNC(AVERAGE(C10,D10,E10),1),"")) | G10: =IF(MAESTRO!F10="","",IFERROR('PROM (Agropecuaria 9°)'!AE10,"")) | H10: =IF(MAESTRO!F10="","",IFERROR('PROM (Agropecuaria 9°)'!BM10,"")) | I10: =IF(MAESTRO!F10="","",IFERROR('PROM (Agropecuaria 9°)'!CU10,"")) | J10: =IF(MAESTRO!F10="","",IFERROR(TRUNC(AVERAGE(G10,H10,I10),1),"")) | K10: =IF(MAESTRO!F10="","",IFERROR('PROM (Comercio 9°)'!AE10,"")) | L10: =IF(MAESTRO!F10="","",IFERROR('PROM (Comercio 9°)'!BM10,"")) | M10: =IF(MAESTRO!F10="","",IFERROR('PROM (Comercio 9°)'!CU10,"")) | N10: =IF(MAESTRO!F10="","",IFERROR(TRUNC(AVERAGE(K10,L10,M10),1),"")) | O10: =IF(MAESTRO!F10="","",IFERROR(AVERAGE(G10,K10),"")) | P10: =IF(MAESTRO!F10="","",IFERROR(AVERAGE(H10,L10),"")) | Q10: =IF(MAESTRO!F10="","",IFERROR(AVERAGE(I10,M10),"")) | R10: =IF(MAESTRO!F10="","",IFERROR(TRUNC(AVERAGE(O10,P10,Q10),1),"")) | S10: =IF(MAESTRO!F10="","",IFERROR('PROM (Artistica 9°)'!AE10,"")) | T10: =IF(MAESTRO!F10="","",IFERROR('PROM (Artistica 9°)'!BM10,"")) | U10: =IF(MAESTRO!F10="","",IFERROR('PROM (Artistica 9°)'!CU10,"")) | V10: =IF(MAESTRO!F10="","",IFERROR(TRUNC(AVERAGE(S10,T10,U10),1),"")) | W10: =IF(MAESTRO!F10="","",IF(AND(F10="",J10="",N10="",R10="",V10=""),"",IF(Y(OR(F10="",F10>=3),OR(J10="",J10>=3),OR(N10="",N10>=3),OR(R10="",R10>=3),OR(V10="",V10>=3)),"✓ APROBADO","✗ REPROBADO")))
A11: 7 | B11: =MAESTRO!F11 -> 0 | C11: =IF(MAESTRO!F11="","",IFERROR('PROM (Ingles 9°)'!AE11,"")) | D11: =IF(MAESTRO!F11="","",IFERROR('PROM (Ingles 9°)'!BM11,"")) | E11: =IF(MAESTRO!F11="","",IFERROR('PROM (Ingles 9°)'!CU11,"")) | F11: =IF(MAESTRO!F11="","",IFERROR(TRUNC(AVERAGE(C11,D11,E11),1),"")) | G11: =IF(MAESTRO!F11="","",IFERROR('PROM (Agropecuaria 9°)'!AE11,"")) | H11: =IF(MAESTRO!F11="","",IFERROR('PROM (Agropecuaria 9°)'!BM11,"")) | I11: =IF(MAESTRO!F11="","",IFERROR('PROM (Agropecuaria 9°)'!CU11,"")) | J11: =IF(MAESTRO!F11="","",IFERROR(TRUNC(AVERAGE(G11,H11,I11),1),"")) | K11: =IF(MAESTRO!F11="","",IFERROR('PROM (Comercio 9°)'!AE11,"")) | L11: =IF(MAESTRO!F11="","",IFERROR('PROM (Comercio 9°)'!BM11,"")) | M11: =IF(MAESTRO!F11="","",IFERROR('PROM (Comercio 9°)'!CU11,"")) | N11: =IF(MAESTRO!F11="","",IFERROR(TRUNC(AVERAGE(K11,L11,M11),1),"")) | O11: =IF(MAESTRO!F11="","",IFERROR(AVERAGE(G11,K11),"")) | P11: =IF(MAESTRO!F11="","",IFERROR(AVERAGE(H11,L11),"")) | Q11: =IF(MAESTRO!F11="","",IFERROR(AVERAGE(I11,M11),"")) | R11: =IF(MAESTRO!F11="","",IFERROR(TRUNC(AVERAGE(O11,P11,Q11),1),"")) | S11: =IF(MAESTRO!F11="","",IFERROR('PROM (Artistica 9°)'!AE11,"")) | T11: =IF(MAESTRO!F11="","",IFERROR('PROM (Artistica 9°)'!BM11,"")) | U11: =IF(MAESTRO!F11="","",IFERROR('PROM (Artistica 9°)'!CU11,"")) | V11: =IF(MAESTRO!F11="","",IFERROR(TRUNC(AVERAGE(S11,T11,U11),1),"")) | W11: =IF(MAESTRO!F11="","",IF(AND(F11="",J11="",N11="",R11="",V11=""),"",IF(Y(OR(F11="",F11>=3),OR(J11="",J11>=3),OR(N11="",N11>=3),OR(R11="",R11>=3),OR(V11="",V11>=3)),"✓ APROBADO","✗ REPROBADO")))
A12: 8 | B12: =MAESTRO!F12 -> 0 | C12: =IF(MAESTRO!F12="","",IFERROR('PROM (Ingles 9°)'!AE12,"")) | D12: =IF(MAESTRO!F12="","",IFERROR('PROM (Ingles 9°)'!BM12,"")) | E12: =IF(MAESTRO!F12="","",IFERROR('PROM (Ingles 9°)'!CU12,"")) | F12: =IF(MAESTRO!F12="","",IFERROR(TRUNC(AVERAGE(C12,D12,E12),1),"")) | G12: =IF(MAESTRO!F12="","",IFERROR('PROM (Agropecuaria 9°)'!AE12,"")) | H12: =IF(MAESTRO!F12="","",IFERROR('PROM (Agropecuaria 9°)'!BM12,"")) | I12: =IF(MAESTRO!F12="","",IFERROR('PROM (Agropecuaria 9°)'!CU12,"")) | J12: =IF(MAESTRO!F12="","",IFERROR(TRUNC(AVERAGE(G12,H12,I12),1),"")) | K12: =IF(MAESTRO!F12="","",IFERROR('PROM (Comercio 9°)'!AE12,"")) | L12: =IF(MAESTRO!F12="","",IFERROR('PROM (Comercio 9°)'!BM12,"")) | M12: =IF(MAESTRO!F12="","",IFERROR('PROM (Comercio 9°)'!CU12,"")) | N12: =IF(MAESTRO!F12="","",IFERROR(TRUNC(AVERAGE(K12,L12,M12),1),"")) | O12: =IF(MAESTRO!F12="","",IFERROR(AVERAGE(G12,K12),"")) | P12: =IF(MAESTRO!F12="","",IFERROR(AVERAGE(H12,L12),"")) | Q12: =IF(MAESTRO!F12="","",IFERROR(AVERAGE(I12,M12),"")) | R12: =IF(MAESTRO!F12="","",IFERROR(TRUNC(AVERAGE(O12,P12,Q12),1),"")) | S12: =IF(MAESTRO!F12="","",IFERROR('PROM (Artistica 9°)'!AE12,"")) | T12: =IF(MAESTRO!F12="","",IFERROR('PROM (Artistica 9°)'!BM12,"")) | U12: =IF(MAESTRO!F12="","",IFERROR('PROM (Artistica 9°)'!CU12,"")) | V12: =IF(MAESTRO!F12="","",IFERROR(TRUNC(AVERAGE(S12,T12,U12),1),"")) | W12: =IF(MAESTRO!F12="","",IF(AND(F12="",J12="",N12="",R12="",V12=""),"",IF(Y(OR(F12="",F12>=3),OR(J12="",J12>=3),OR(N12="",N12>=3),OR(R12="",R12>=3),OR(V12="",V12>=3)),"✓ APROBADO","✗ REPROBADO")))
